<?xml version="1.0" ?>
<robot name="assembly_1">
  <link name="Motor_Weight_Mount">
    <visual name="Motor_Weight_Mount_visual">
      <origin xyz="0 0 0" rpy="0 0 0"/>
      <geometry name="Motor_Weight_Mount_geometry">
        <mesh filename="meshes/Motor_Weight_Mount.stl"/>
      </geometry>
      <material name="Motor_Weight_Mount_material">
        <color rgba="0.97254902 0.52941176 0.0039215686 1"/>
      </material>
    </visual>
    <collision name="Motor_Weight_Mount.collision">
      <origin xyz="0 0 0" rpy="0 0 0"/>
      <geometry name="Motor_Weight_Mount_collision_geometry">
        <mesh filename="meshes/Motor_Weight_Mount.stl"/>
      </geometry>
    </collision>
    <inertial name="Motor_Weight_Mount_inertial">
      <mass value="0.108"/>
      <inertia ixx="0.00025671209072946754" iyy="0.00023024378013468234" izz="4.3574052217014776e-05" ixy="-3.684877512045158e-10" ixz="1.745026328443468e-09" iyz="-3.44376938106893e-05"/>
      <origin xyz="4.1164608888888893e-07 0.00048755811111111117 -0.0023089010089316323" rpy="0 0 0"/>
    </inertial>
  </link>
  <joint name="fix_imu_front_side" type="fixed">
    <origin xyz="7.4096296e-06 -0.029723954 -0.041560218" rpy="1.5707963 1.5707963 0"/>
    <parent link="Motor_Weight_Mount"/>
    <child link="imu"/>
  </joint>
  <link name="imu">
    <visual name="imu_visual">
      <origin xyz="0 0 0" rpy="0 0 0"/>
      <geometry name="imu_geometry">
        <mesh filename="meshes/imu.stl"/>
      </geometry>
      <material name="imu_material">
        <color rgba="0.61568627 0.81176471 0.92941176 1"/>
      </material>
    </visual>
    <collision name="imu.collision">
      <origin xyz="0 0 0" rpy="0 0 0"/>
      <geometry name="imu_collision_geometry">
        <mesh filename="meshes/imu.stl"/>
      </geometry>
    </collision>
    <inertial name="imu_inertial">
      <mass value="0.0057"/>
      <inertia ixx="1e-06" iyy="1.1684421e-06" izz="1.5348873e-06" ixy="0" ixz="0" iyz="0"/>
      <origin xyz="-0.0030124468 0 0.0032493417" rpy="0 0 0"/>
    </inertial>
  </link>
  <joint name="fix_imu_right_side" type="fixed">
    <origin xyz="0.02000741 -0.0032239537 -0.023810218" rpy="0 1.5707963 0"/>
    <parent link="Motor_Weight_Mount"/>
    <child link="imu_2"/>
  </joint>
  <link name="imu_2">
    <visual name="imu_visual_2">
      <origin xyz="0 0 0" rpy="0 0 0"/>
      <geometry name="imu_geometry_2">
        <mesh filename="meshes/imu_2.stl"/>
      </geometry>
      <material name="imu_material_2">
        <color rgba="0.61568627 0.81176471 0.92941176 1"/>
      </material>
    </visual>
    <collision name="imu.collision_2">
      <origin xyz="0 0 0" rpy="0 0 0"/>
      <geometry name="imu_collision_geometry_2">
        <mesh filename="meshes/imu_2.stl"/>
      </geometry>
    </collision>
    <inertial name="imu_inertial_2">
      <mass value="0.0057"/>
      <inertia ixx="1e-06" iyy="1.1684421e-06" izz="1.5348873e-06" ixy="0" ixz="0" iyz="0"/>
      <origin xyz="0.014737553 -0.012 0.0029993417" rpy="0 0 0"/>
    </inertial>
  </link>
  <joint name="fix_imu_bottom" type="fixed">
    <origin xyz="0.017731837 -0.0032239537 -0.067899562" rpy="3.1415927 0 3.1415927"/>
    <parent link="Motor_Weight_Mount"/>
    <child link="imu_3"/>
  </joint>
  <link name="imu_3">
    <visual name="imu_visual_3">
      <origin xyz="0 0 0" rpy="0 0 0"/>
      <geometry name="imu_geometry_3">
        <mesh filename="meshes/imu_3.stl"/>
      </geometry>
      <material name="imu_material_3">
        <color rgba="0.61568627 0.81176471 0.92941176 1"/>
      </material>
    </visual>
    <collision name="imu.collision_3">
      <origin xyz="0 0 0" rpy="0 0 0"/>
      <geometry name="imu_collision_geometry_3">
        <mesh filename="meshes/imu_3.stl"/>
      </geometry>
    </collision>
    <inertial name="imu_inertial_3">
      <mass value="0.0057"/>
      <inertia ixx="1e-06" iyy="1.1684421e-06" izz="1.5348873e-06" ixy="0" ixz="0" iyz="0"/>
      <origin xyz="0.014737553 -0.012 0.0029993417" rpy="0 0 0"/>
    </inertial>
  </link>
  <joint name="dof_servo_out" type="revolute">
    <origin xyz="7.4096296e-06 -0.010298954 0.088439782" rpy="-1.5707963 0 0"/>
    <parent link="Motor_Weight_Mount"/>
    <child link="STS3215"/>
    <limit effort="5" velocity="6.28" lower="-1.5707963" upper="1.5707963"/>
    <axis xyz="0 0 -1"/>
  </joint>
  <link name="STS3215">
    <visual name="STS3215_visual">
      <origin xyz="0 0 0" rpy="0 0 0"/>
      <geometry name="STS3215_geometry">
        <mesh filename="meshes/STS3215.stl"/>
      </geometry>
      <material name="STS3215_material">
        <color rgba="1 0 0 1"/>
      </material>
    </visual>
    <collision name="STS3215.collision">
      <origin xyz="0 0 0" rpy="0 0 0"/>
      <geometry name="STS3215_collision_geometry">
        <mesh filename="meshes/STS3215.stl"/>
      </geometry>
    </collision>
    <inertial name="STS3215_inertial">
      <mass value="0.34112575"/>
      <inertia ixx="0.0007991976665541033" iyy="0.0009078084262351327" izz="0.0002757100497095613" ixy="2.4760137196551268e-08" ixz="-4.7333634687073423e-08" iyz="0.00012843866280498235"/>
      <origin xyz="-2.789990960259091e-06 -0.03792701956340436 0.06687174290207863" rpy="0 0 0"/>
    </inertial>
  </link>
</robot>
