<?xml version="1.0" ?>
<robot name="assembly_1">
  <link name="floating_base_link">
    <visual name="floating_base_link_visual">
      <geometry name="floating_base_link_geometry">
        <sphere radius="0.01"/>
      </geometry>
      <material name="floating_base_link_material">
        <color rgba="1 0 0 1"/>
      </material>
      <origin xyz="0 0 0" rpy="0.00 -1.57 0.00"/>
    </visual>
    <inertial name="floating_base_link_inertial">
      <mass value="0.001"/>
      <inertia ixx="0.000001" iyy="0.000001" izz="0.000002" ixy="0" ixz="0" iyz="0"/>
      <origin xyz="0 0 0" rpy="0.00 -1.57 0.00"/>
    </inertial>
  </link>
  <joint name="floating_base_joint" type="fixed">
    <parent link="floating_base_link"/>
    <child link="STS3215"/>
    <origin xyz="0 0 0" rpy="0.00 -1.57 0.00"/>
  </joint>
  <joint name="servo_out" type="revolute">
    <origin xyz="-0.011909 -0.000014 -0.020256" rpy="3.141593 0 0"/>
    <parent link="STS3215"/>
    <child link="Motor_Weight_Mount"/>
    <limit effort="5" velocity="6.28" lower="-1.570796" upper="1.570796"/>
    <axis xyz="0 0 -1"/>
  </joint>
  <joint name="imu_front_side" type="fixed">
    <origin xyz="-0.130000 0 -0.057375" rpy="3.141593 0 3.141593"/>
    <parent link="Motor_Weight_Mount"/>
    <child link="imu"/>
  </joint>
  <joint name="imu_right_side" type="fixed">
    <origin xyz="-0.130000 0.020000 -0.042875" rpy="1.570796 0 3.141593"/>
    <parent link="Motor_Weight_Mount"/>
    <child link="imu_2"/>
  </joint>
  <joint name="imu_bottom" type="fixed">
    <origin xyz="-0.156339 0 -0.042875" rpy="1.570796 0 -1.570796"/>
    <parent link="Motor_Weight_Mount"/>
    <child link="imu_3"/>
  </joint>
  <link name="STS3215">
    <visual name="STS3215_visual">
      <origin xyz="0 0 0" rpy="0 0 0"/>
      <geometry name="STS3215_geometry">
        <mesh filename="meshes/STS3215.stl"/>
      </geometry>
      <material name="STS3215_material">
        <color rgba="1 0 0 1"/>
      </material>
    </visual>
    <collision name="STS3215.collision">
      <origin xyz="0 0 0" rpy="0 0 0"/>
      <geometry name="STS3215_collision_geometry">
        <mesh filename="meshes/STS3215.collision.stl"/>
      </geometry>
    </collision>
    <inertial name="STS3215_inertial">
      <mass value="0.270643"/>
      <inertia ixx="0.000724" iyy="0.000658" izz="0.000225" ixy="0" ixz="0.000118" iyz="0"/>
      <origin xyz="0.024245 -0.000010 -0.046618" rpy="0 0 0"/>
    </inertial>
  </link>
  <link name="Motor_Weight_Mount">
    <visual name="Motor_Weight_Mount_visual">
      <origin xyz="0 0 0" rpy="0 0 0"/>
      <geometry name="Motor_Weight_Mount_geometry">
        <mesh filename="meshes/Motor_Weight_Mount.stl"/>
      </geometry>
      <material name="Motor_Weight_Mount_material">
        <color rgba="0.972549 0.529412 0.003922 1"/>
      </material>
    </visual>
    <collision name="Motor_Weight_Mount.collision">
      <origin xyz="0 0 0" rpy="0 0 0"/>
      <geometry name="Motor_Weight_Mount_collision_geometry">
        <mesh filename="meshes/Motor_Weight_Mount.collision.stl"/>
      </geometry>
    </collision>
    <inertial name="Motor_Weight_Mount_inertial">
      <mass value="0.092000"/>
      <inertia ixx="0.000037" iyy="0.000218" izz="0.000196" ixy="0" ixz="-0.000029" iyz="0"/>
      <origin xyz="-0.091150 -0.000007 -0.027111" rpy="0 0 0"/>
    </inertial>
  </link>
  <link name="imu">
    <visual name="imu_visual">
      <origin xyz="0 0 0" rpy="0 0 0"/>
      <geometry name="imu_geometry">
        <mesh filename="meshes/imu.stl"/>
      </geometry>
      <material name="imu_material">
        <color rgba="0.615686 0.811765 0.929412 1"/>
      </material>
    </visual>
    <collision name="imu.collision">
      <origin xyz="0 0 0" rpy="0 0 0"/>
      <geometry name="imu_collision_geometry">
        <mesh filename="meshes/imu.collision.stl"/>
      </geometry>
    </collision>
    <inertial name="imu_inertial">
      <mass value="0.005700"/>
      <inertia ixx="0.000001" iyy="0.000001" izz="0.000002" ixy="0" ixz="0" iyz="0"/>
      <origin xyz="-0.003012 0 0.002999" rpy="0 0 0"/>
    </inertial>
  </link>
  <link name="imu_2">
    <visual name="imu_visual_2">
      <origin xyz="0 0 0" rpy="0 0 0"/>
      <geometry name="imu_geometry_2">
        <mesh filename="meshes/imu_2.stl"/>
      </geometry>
      <material name="imu_material_2">
        <color rgba="0.615686 0.811765 0.929412 1"/>
      </material>
    </visual>
    <collision name="imu.collision_2">
      <origin xyz="0 0 0" rpy="0 0 0"/>
      <geometry name="imu_collision_geometry_2">
        <mesh filename="meshes/imu_2.collision.stl"/>
      </geometry>
    </collision>
    <inertial name="imu_inertial_2">
      <mass value="0.005700"/>
      <inertia ixx="0.000001" iyy="0.000001" izz="0.000002" ixy="0" ixz="0" iyz="0"/>
      <origin xyz="-0.003012 0 0.002999" rpy="0 0 0"/>
    </inertial>
  </link>
  <link name="imu_3">
    <visual name="imu_visual_3">
      <origin xyz="0 0 0" rpy="0 0 0"/>
      <geometry name="imu_geometry_3">
        <mesh filename="meshes/imu_3.stl"/>
      </geometry>
      <material name="imu_material_3">
        <color rgba="0.615686 0.811765 0.929412 1"/>
      </material>
    </visual>
    <collision name="imu.collision_3">
      <origin xyz="0 0 0" rpy="0 0 0"/>
      <geometry name="imu_collision_geometry_3">
        <mesh filename="meshes/imu_3.collision.stl"/>
      </geometry>
    </collision>
    <inertial name="imu_inertial_3">
      <mass value="0.005700"/>
      <inertia ixx="0.000001" iyy="0.000001" izz="0.000002" ixy="0" ixz="0" iyz="0"/>
      <origin xyz="-0.003012 0 0.002999" rpy="0 0 0"/>
    </inertial>
  </link>
</robot>
