<mujoco model="assembly_1">
  <default>
    <default class="robot">
      <default class="motor">
        <joint />
        <motor />
      </default>
      <default class="visual">
        <geom material="visualgeom" contype="0" conaffinity="0" group="2" />
      </default>
      <default class="collision">
        <geom condim="6" friction="0.8 0.02 0.01" group="3" />
      </default>
    </default>
    <mesh maxhullvert="64" />
    <default class="floor">
      <geom contype="1" conaffinity="1" group="1" friction="0.8 0.02 0.01" condim="6" type="plane" size="100 100 0.1" />
    </default>
  </default>

  <compiler angle="radian" />

  <asset>
    <material name="floating_base_link_material" rgba="1 0 0 1" />
    <material name="Motor_Weight_Mount_material" rgba="0.972549 0.529412 0.003922 1" />
    <material name="imu_material" rgba="0.615686 0.811765 0.929412 1" />
    <material name="default_material" rgba="0.7 0.7 0.7 1" />
    <mesh name="Motor_Weight_Mount.collision.stl" file="meshes/Motor_Weight_Mount.collision.stl" />
    <mesh name="Motor_Weight_Mount.stl" file="meshes/Motor_Weight_Mount.stl" />
    <mesh name="imu.collision.stl" file="meshes/imu.collision.stl" />
    <mesh name="imu.stl" file="meshes/imu.stl" />
    <mesh name="imu_2.collision.stl" file="meshes/imu_2.collision.stl" />
    <mesh name="imu_2.stl" file="meshes/imu_2.stl" />
    <mesh name="imu_3.collision.stl" file="meshes/imu_3.collision.stl" />
    <mesh name="imu_3.stl" file="meshes/imu_3.stl" />
    <mesh name="STS3215.collision.stl" file="meshes/STS3215.collision.stl" />
    <mesh name="STS3215.stl" file="meshes/STS3215.stl" />
  </asset>

  <worldbody>
    <body name="floating_base_link" pos="0.00000000 0.00000000 0.06790000" quat="1 0 0 0" childclass="robot">
      <geom name="floating_base_link_visual" pos="0 0 0" quat="1.0 0.0 0.0 0.0" material="floating_base_link_material" type="sphere" size="0.01" class="visual" />
      <body name="Motor_Weight_Mount" pos="0 0 0" quat="1.0 0.0 0.0 0.0">
        <inertial pos="0 0.000488 -0.002309" quat="1.0 0.0 0.0 0.0" mass="0.108000" diaginertia="0.000257 0.00023 4.4e-05" />
        <geom name="Motor_Weight_Mount_collision" pos="0 0 0" quat="1.0 0.0 0.0 0.0" type="mesh" mesh="Motor_Weight_Mount.collision.stl" class="collision" />
        <geom name="Motor_Weight_Mount_visual" pos="0 0 0" quat="1.0 0.0 0.0 0.0" material="Motor_Weight_Mount_material" type="mesh" mesh="Motor_Weight_Mount.stl" class="visual" />
        <body name="imu" pos="0.000007 -0.029724 -0.041560" quat="0.5000001633974483 0.4999999999999733 0.4999999999999733 -0.49999983660255165">
          <inertial pos="-0.003012 0 0.003249" quat="1.0 0.0 0.0 0.0" mass="0.005700" diaginertia="1e-06 1e-06 2e-06" />
          <geom name="imu_collision" pos="0 0 0" quat="1.0 0.0 0.0 0.0" type="mesh" mesh="imu.collision.stl" class="collision" />
          <geom name="imu_visual" pos="0 0 0" quat="1.0 0.0 0.0 0.0" material="imu_material" type="mesh" mesh="imu.stl" class="visual" />
          <site name="imu_site" quat="1.0 0.0 0.0 0.0" pos="0.0 0.0 0.0" />
        </body>
        <body name="imu_2" pos="0.020007 -0.003224 -0.023810" quat="0.7071068967259818 0.0 0.7071066656470943 0.0">
          <inertial pos="0.014738 -0.012000 0.002999" quat="1.0 0.0 0.0 0.0" mass="0.005700" diaginertia="1e-06 1e-06 2e-06" />
          <geom name="imu_2_collision" pos="0 0 0" quat="1.0 0.0 0.0 0.0" type="mesh" mesh="imu_2.collision.stl" class="collision" />
          <geom name="imu_2_visual" pos="0 0 0" quat="1.0 0.0 0.0 0.0" material="imu_material" type="mesh" mesh="imu_2.stl" class="visual" />
          <site name="imu_2_site" quat="1.0 0.0 0.0 0.0" pos="0.0 0.0 0.0" />
        </body>
        <body name="imu_3" pos="0.017732 -0.003224 -0.067900" quat="3.000000781252362e-14 -1.7320510330969674e-07 0.99999999999997 -1.7320510330969674e-07">
          <inertial pos="0.014738 -0.012000 0.002999" quat="1.0 0.0 0.0 0.0" mass="0.005700" diaginertia="1e-06 1e-06 2e-06" />
          <geom name="imu_3_collision" pos="0 0 0" quat="1.0 0.0 0.0 0.0" type="mesh" mesh="imu_3.collision.stl" class="collision" />
          <geom name="imu_3_visual" pos="0 0 0" quat="1.0 0.0 0.0 0.0" material="imu_material" type="mesh" mesh="imu_3.stl" class="visual" />
          <site name="imu_3_site" quat="1.0 0.0 0.0 0.0" pos="0.0 0.0 0.0" />
        </body>
        <body name="STS3215" pos="0.000007 -0.010299 0.088440" quat="0.7071068967259818 -0.7071066656470943 0.0 0.0">
          <joint name="dof_servo_out" type="hinge" ref="0.0" class="motor" range="-1.570796 1.570796" axis="0 0 -1" />
          <inertial pos="-0.000003 -0.037927 0.066872" quat="1.0 0.0 0.0 0.0" mass="0.341126" diaginertia="0.000799 0.000908 0.000276" />
          <geom name="STS3215_collision" pos="0 0 0" quat="1.0 0.0 0.0 0.0" type="mesh" mesh="STS3215.collision.stl" class="collision" />
          <geom name="STS3215_visual" pos="0 0 0" quat="1.0 0.0 0.0 0.0" material="floating_base_link_material" type="mesh" mesh="STS3215.stl" class="visual" />
        </body>
      </body>
      <site name="floating_base_link_site" pos="0 0 0" quat="1 0 0 0" />
      <camera name="front_camera" mode="track" fovy="90.0" quat="4.329780281177467e-17 4.329780281177466e-17 0.7071067811865475 0.7071067811865476" pos="0.0 2.0 0.5" />
      <camera name="side_camera" mode="track" fovy="90.0" quat="-0.5 -0.4999999999999999 0.5 0.5000000000000001" pos="-2.0 0.0 0.5" />
    </body>
  </worldbody>

  <actuator>
    <motor name="dof_servo_out_ctrl" joint="dof_servo_out" class="motor" />
  </actuator>

  <contact>
    <exclude body1="Motor_Weight_Mount" body2="imu" />
    <exclude body1="Motor_Weight_Mount" body2="imu_2" />
    <exclude body1="Motor_Weight_Mount" body2="imu_3" />
    <exclude body1="Motor_Weight_Mount" body2="STS3215" />
  </contact>

  <sensor>
    <accelerometer name="imu_acc" site="imu_site" noise="0.01" />
    <gyro name="imu_gyro" site="imu_site" noise="0.01" />
    <magnetometer name="imu_mag" site="imu_site" noise="0.05" />
    <framepos name="base_link_pos" objtype="site" objname="imu_site" />
    <framequat name="base_link_quat" objtype="site" objname="imu_site" />
    <framelinvel name="base_link_vel" objtype="site" objname="imu_site" />
    <frameangvel name="base_link_ang_vel" objtype="site" objname="imu_site" />
    <accelerometer name="imu_2_acc" site="imu_2_site" noise="0.01" />
    <gyro name="imu_2_gyro" site="imu_2_site" noise="0.01" />
    <magnetometer name="imu_2_mag" site="imu_2_site" noise="0.05" />
    <!-- <framepos name="base_link_pos" objtype="site" objname="imu_2_site" />
    <framequat name="base_link_quat" objtype="site" objname="imu_2_site" />
    <framelinvel name="base_link_vel" objtype="site" objname="imu_2_site" />
    <frameangvel name="base_link_ang_vel" objtype="site" objname="imu_2_site" /> -->
    <accelerometer name="imu_3_acc" site="imu_3_site" noise="0.01" />
    <gyro name="imu_3_gyro" site="imu_3_site" noise="0.01" />
    <magnetometer name="imu_3_mag" site="imu_3_site" noise="0.05" />
    <!-- <framepos name="base_link_pos" objtype="site" objname="imu_3_site" />
    <framequat name="base_link_quat" objtype="site" objname="imu_3_site" />
    <framelinvel name="base_link_vel" objtype="site" objname="imu_3_site" />
    <frameangvel name="base_link_ang_vel" objtype="site" objname="imu_3_site" /> -->
  </sensor>
</mujoco>