<?xml version="1.0" ?>
<robot name="k-bot_sim">
  <link name="link:Torso_Naked_(1):body1-part_(4)">
    <visual name="link:Torso_Naked_(1):body1-part_(4)_visual">
      <origin xyz="0 0 0" rpy="0 0 0"/>
      <geometry name="link:Torso_Naked_(1):body1-part_(4)_geometry">
        <mesh filename="meshes/Torso_Naked_(1):body1-part_(4).stl"/>
      </geometry>
      <material name="link:Torso_Naked_(1):body1-part_(4)_material">
        <color rgba="1 1 1 1"/>
      </material>
    </visual>
    <collision name="link:Torso_Naked_(1):body1-part_(4).collision">
      <origin xyz="0 0 0" rpy="0 0 0"/>
      <geometry name="link:Torso_Naked_(1):body1-part_(4)_collision_geometry">
        <mesh filename="meshes/Torso_Naked_(1):body1-part_(4).stl"/>
      </geometry>
    </collision>
    <inertial name="link:Torso_Naked_(1):body1-part_(4)_inertial">
      <mass value="1.2310126"/>
      <inertia ixx="0.027487958" iyy="0.021833906" izz="0.0076034713" ixy="-1.9582105e-05" ixz="0" iyz="0"/>
      <origin xyz="0 0 0" rpy="0 0 0"/>
    </inertial>
  </link>
  <joint name="joint:imu_link" type="fixed">
    <origin xyz="0.039989396 -0.12691044 0" rpy="-1.5707963 0 0"/>
    <parent link="link:Torso_Naked_(1):body1-part_(4)"/>
    <child link="link:imu_(1)"/>
  </joint>
  <link name="link:imu_(1)">
    <visual name="link:imu_(1)_visual">
      <origin xyz="0 0 0" rpy="0 0 0"/>
      <geometry name="link:imu_(1)_geometry">
        <mesh filename="meshes/imu_(1).stl"/>
      </geometry>
      <material name="link:imu_(1)_material">
        <color rgba="0.61568627 0.81176471 0.92941176 1"/>
      </material>
    </visual>
    <collision name="link:imu_(1).collision">
      <origin xyz="0 0 0" rpy="0 0 0"/>
      <geometry name="link:imu_(1)_collision_geometry">
        <mesh filename="meshes/imu_(1).stl"/>
      </geometry>
    </collision>
    <inertial name="link:imu_(1)_inertial">
      <mass value="0.01"/>
      <inertia ixx="1.1408333e-06" iyy="1.1408333e-06" izz="2.0416667e-06" ixy="0" ixz="0" iyz="0"/>
      <origin xyz="-0.0075 0 0.006" rpy="0 0 0"/>
    </inertial>
  </link>
  <joint name="joint:Torso_Naked_(1):Fastened_16" type="fixed">
    <origin xyz="-1.0603759e-05 0.018089564 0.14549981" rpy="3.1415927 0 0"/>
    <parent link="link:Torso_Naked_(1):body1-part_(4)"/>
    <child link="link:Torso_Naked_(1):body1-part_(10)"/>
  </joint>
  <link name="link:Torso_Naked_(1):body1-part_(10)">
    <visual name="link:Torso_Naked_(1):body1-part_(10)_visual">
      <origin xyz="0 0 0" rpy="0 0 0"/>
      <geometry name="link:Torso_Naked_(1):body1-part_(10)_geometry">
        <mesh filename="meshes/Torso_Naked_(1):body1-part_(10).stl"/>
      </geometry>
      <material name="link:Torso_Naked_(1):body1-part_(10)_material">
        <color rgba="1 1 1 1"/>
      </material>
    </visual>
    <collision name="link:Torso_Naked_(1):body1-part_(10).collision">
      <origin xyz="0 0 0" rpy="0 0 0"/>
      <geometry name="link:Torso_Naked_(1):body1-part_(10)_collision_geometry">
        <mesh filename="meshes/Torso_Naked_(1):body1-part_(10).stl"/>
      </geometry>
    </collision>
    <inertial name="link:Torso_Naked_(1):body1-part_(10)_inertial">
      <mass value="0.9"/>
      <inertia ixx="0.00067098171" iyy="0.00067098171" izz="0.00090724844" ixy="0" ixz="0" iyz="0"/>
      <origin xyz="0 0 -0.014732068" rpy="0 0 0"/>
    </inertial>
  </link>
  <joint name="joint:Torso_Naked_(1):Fastened_17" type="fixed">
    <origin xyz="-1.0603759e-05 0.018089564 -0.14550019" rpy="0 0 0"/>
    <parent link="link:Torso_Naked_(1):body1-part_(4)"/>
    <child link="link:Torso_Naked_(1):body1-part_(9)"/>
  </joint>
  <link name="link:Torso_Naked_(1):body1-part_(9)">
    <visual name="link:Torso_Naked_(1):body1-part_(9)_visual">
      <origin xyz="0 0 0" rpy="0 0 0"/>
      <geometry name="link:Torso_Naked_(1):body1-part_(9)_geometry">
        <mesh filename="meshes/Torso_Naked_(1):body1-part_(9).stl"/>
      </geometry>
      <material name="link:Torso_Naked_(1):body1-part_(9)_material">
        <color rgba="1 1 1 1"/>
      </material>
    </visual>
    <collision name="link:Torso_Naked_(1):body1-part_(9).collision">
      <origin xyz="0 0 0" rpy="0 0 0"/>
      <geometry name="link:Torso_Naked_(1):body1-part_(9)_collision_geometry">
        <mesh filename="meshes/Torso_Naked_(1):body1-part_(9).stl"/>
      </geometry>
    </collision>
    <inertial name="link:Torso_Naked_(1):body1-part_(9)_inertial">
      <mass value="0.9"/>
      <inertia ixx="0.00067098171" iyy="0.00067098171" izz="0.00090724844" ixy="0" ixz="0" iyz="0"/>
      <origin xyz="0 0 -0.014732068" rpy="0 0 0"/>
    </inertial>
  </link>
  <joint name="joint:Torso_Naked_(1):Fastened_8" type="fixed">
    <origin xyz="-1.0603691e-05 -0.12991044 0" rpy="1.5707963 0 0"/>
    <parent link="link:Torso_Naked_(1):body1-part_(4)"/>
    <child link="link:Torso_Naked_(1):body1-part_(5)"/>
  </joint>
  <link name="link:Torso_Naked_(1):body1-part_(5)">
    <visual name="link:Torso_Naked_(1):body1-part_(5)_visual">
      <origin xyz="0 0 0" rpy="0 0 0"/>
      <geometry name="link:Torso_Naked_(1):body1-part_(5)_geometry">
        <mesh filename="meshes/Torso_Naked_(1):body1-part_(5).stl"/>
      </geometry>
      <material name="link:Torso_Naked_(1):body1-part_(5)_material">
        <color rgba="1 1 1 1"/>
      </material>
    </visual>
    <collision name="link:Torso_Naked_(1):body1-part_(5).collision">
      <origin xyz="0 0 0" rpy="0 0 0"/>
      <geometry name="link:Torso_Naked_(1):body1-part_(5)_collision_geometry">
        <mesh filename="meshes/Torso_Naked_(1):body1-part_(5).stl"/>
      </geometry>
    </collision>
    <inertial name="link:Torso_Naked_(1):body1-part_(5)_inertial">
      <mass value="0.68030096"/>
      <inertia ixx="0.0086891579" iyy="0.006933761" izz="0.002608882" ixy="8.7755602e-06" ixz="-0.00015085389" iyz="3.1228871e-05"/>
      <origin xyz="-0.0071262559 0.00039370917 0.13888879" rpy="0 0 0"/>
    </inertial>
  </link>
  <joint name="joint:left_shoulder_pitch_03" type="revolute">
    <origin xyz="0 0 -0.042" rpy="0 0 3.1415927"/>
    <parent link="link:Torso_Naked_(1):body1-part_(10)"/>
    <child link="link:arm0_(1):shoulder_(4)"/>
    <limit effort="60" velocity="6.283" lower="0" upper="3.1415927"/>
    <axis xyz="0 0 1"/>
  </joint>
  <link name="link:arm0_(1):shoulder_(4)">
    <visual name="link:arm0_(1):shoulder_(4)_visual">
      <origin xyz="0 0 0" rpy="0 0 0"/>
      <geometry name="link:arm0_(1):shoulder_(4)_geometry">
        <mesh filename="meshes/arm0_(1):shoulder_(4).stl"/>
      </geometry>
      <material name="link:arm0_(1):shoulder_(4)_material">
        <color rgba="1 1 1 1"/>
      </material>
    </visual>
    <collision name="link:arm0_(1):shoulder_(4).collision">
      <origin xyz="0 0 0" rpy="0 0 0"/>
      <geometry name="link:arm0_(1):shoulder_(4)_collision_geometry">
        <mesh filename="meshes/arm0_(1):shoulder_(4).stl"/>
      </geometry>
    </collision>
    <inertial name="link:arm0_(1):shoulder_(4)_inertial">
      <mass value="0.20735569"/>
      <inertia ixx="0.00056829087" iyy="0.00033049536" izz="0.00028215546" ixy="0" ixz="9.6860776e-06" iyz="0"/>
      <origin xyz="0.0091931637 4.9355922e-05 -0.062070257" rpy="0 0 0"/>
    </inertial>
  </link>
  <joint name="joint:Torso_Naked_(1):Fastened_5" type="fixed">
    <origin xyz="0 0 -0.0395" rpy="0 0 0"/>
    <parent link="link:Torso_Naked_(1):body1-part_(10)"/>
    <child link="link:Torso_Naked_(1):body1-part_(11)"/>
  </joint>
  <link name="link:Torso_Naked_(1):body1-part_(11)">
    <visual name="link:Torso_Naked_(1):body1-part_(11)_visual">
      <origin xyz="0 0 0" rpy="0 0 0"/>
      <geometry name="link:Torso_Naked_(1):body1-part_(11)_geometry">
        <mesh filename="meshes/Torso_Naked_(1):body1-part_(11).stl"/>
      </geometry>
      <material name="link:Torso_Naked_(1):body1-part_(11)_material">
        <color rgba="1 1 1 1"/>
      </material>
    </visual>
    <collision name="link:Torso_Naked_(1):body1-part_(11).collision">
      <origin xyz="0 0 0" rpy="0 0 0"/>
      <geometry name="link:Torso_Naked_(1):body1-part_(11)_collision_geometry">
        <mesh filename="meshes/Torso_Naked_(1):body1-part_(11).stl"/>
      </geometry>
    </collision>
    <inertial name="link:Torso_Naked_(1):body1-part_(11)_inertial">
      <mass value="0.075924533"/>
      <inertia ixx="9.3806565e-06" iyy="4.1635546e-05" izz="4.730836e-05" ixy="0" ixz="0" iyz="0"/>
      <origin xyz="0 -0.03633484 -0.007761698" rpy="0 0 0"/>
    </inertial>
  </link>
  <joint name="joint:right_shoulder_pitch_03" type="revolute">
    <origin xyz="0 0 -0.042" rpy="0 0 3.1415927"/>
    <parent link="link:Torso_Naked_(1):body1-part_(9)"/>
    <child link="link:arm0_(1):shoulder_(6)"/>
    <limit effort="60" velocity="6.283" lower="-3.1415927" upper="0"/>
    <axis xyz="0 0 1"/>
  </joint>
  <link name="link:arm0_(1):shoulder_(6)">
    <visual name="link:arm0_(1):shoulder_(6)_visual">
      <origin xyz="0 0 0" rpy="0 0 0"/>
      <geometry name="link:arm0_(1):shoulder_(6)_geometry">
        <mesh filename="meshes/arm0_(1):shoulder_(6).stl"/>
      </geometry>
      <material name="link:arm0_(1):shoulder_(6)_material">
        <color rgba="1 1 1 1"/>
      </material>
    </visual>
    <collision name="link:arm0_(1):shoulder_(6).collision">
      <origin xyz="0 0 0" rpy="0 0 0"/>
      <geometry name="link:arm0_(1):shoulder_(6)_collision_geometry">
        <mesh filename="meshes/arm0_(1):shoulder_(6).stl"/>
      </geometry>
    </collision>
    <inertial name="link:arm0_(1):shoulder_(6)_inertial">
      <mass value="0.20735447"/>
      <inertia ixx="0.00056828887" iyy="0.00033049431" izz="0.00028215474" ixy="0" ixz="9.6857228e-06" iyz="0"/>
      <origin xyz="0.0091932565 -4.9379497e-05 -0.062070419" rpy="0 0 0"/>
    </inertial>
  </link>
  <joint name="joint:Torso_Naked_(1):Fastened_4" type="fixed">
    <origin xyz="0 0 -0.0395" rpy="0 0 0"/>
    <parent link="link:Torso_Naked_(1):body1-part_(9)"/>
    <child link="link:Torso_Naked_(1):body1-part_(14)"/>
  </joint>
  <link name="link:Torso_Naked_(1):body1-part_(14)">
    <visual name="link:Torso_Naked_(1):body1-part_(14)_visual">
      <origin xyz="0 0 0" rpy="0 0 0"/>
      <geometry name="link:Torso_Naked_(1):body1-part_(14)_geometry">
        <mesh filename="meshes/Torso_Naked_(1):body1-part_(14).stl"/>
      </geometry>
      <material name="link:Torso_Naked_(1):body1-part_(14)_material">
        <color rgba="1 1 1 1"/>
      </material>
    </visual>
    <collision name="link:Torso_Naked_(1):body1-part_(14).collision">
      <origin xyz="0 0 0" rpy="0 0 0"/>
      <geometry name="link:Torso_Naked_(1):body1-part_(14)_collision_geometry">
        <mesh filename="meshes/Torso_Naked_(1):body1-part_(14).stl"/>
      </geometry>
    </collision>
    <inertial name="link:Torso_Naked_(1):body1-part_(14)_inertial">
      <mass value="0.075924533"/>
      <inertia ixx="9.3806565e-06" iyy="4.1635546e-05" izz="4.730836e-05" ixy="0" ixz="0" iyz="0"/>
      <origin xyz="0 0.03633484 -0.007761698" rpy="0 0 0"/>
    </inertial>
  </link>
  <joint name="joint:Torso_Naked_(1):Fastened_1" type="fixed">
    <origin xyz="0.0375 -0.016 0.2911" rpy="3.1415927 0 3.1415927"/>
    <parent link="link:Torso_Naked_(1):body1-part_(5)"/>
    <child link="link:Torso_Naked_(1):body1-part_(6)"/>
  </joint>
  <link name="link:Torso_Naked_(1):body1-part_(6)">
    <visual name="link:Torso_Naked_(1):body1-part_(6)_visual">
      <origin xyz="0 0 0" rpy="0 0 0"/>
      <geometry name="link:Torso_Naked_(1):body1-part_(6)_geometry">
        <mesh filename="meshes/Torso_Naked_(1):body1-part_(6).stl"/>
      </geometry>
      <material name="link:Torso_Naked_(1):body1-part_(6)_material">
        <color rgba="1 1 1 1"/>
      </material>
    </visual>
    <collision name="link:Torso_Naked_(1):body1-part_(6).collision">
      <origin xyz="0 0 0" rpy="0 0 0"/>
      <geometry name="link:Torso_Naked_(1):body1-part_(6)_collision_geometry">
        <mesh filename="meshes/Torso_Naked_(1):body1-part_(6).stl"/>
      </geometry>
    </collision>
    <inertial name="link:Torso_Naked_(1):body1-part_(6)_inertial">
      <mass value="0.55223125"/>
      <inertia ixx="0.0024507681" iyy="0.0015647521" izz="0.0023032522" ixy="0" ixz="0" iyz="0"/>
      <origin xyz="0.037500005 0.01601865 -0.0017942193" rpy="0 0 0"/>
    </inertial>
  </link>
  <joint name="joint:Torso_Naked_(1):Fastened_9" type="fixed">
    <origin xyz="-0.035 -0.0648 0.012925" rpy="0 0 3.1415927"/>
    <parent link="link:Torso_Naked_(1):body1-part_(5)"/>
    <child link="link:Torso_Naked_(1):body1-part_(3)"/>
  </joint>
  <link name="link:Torso_Naked_(1):body1-part_(3)">
    <visual name="link:Torso_Naked_(1):body1-part_(3)_visual">
      <origin xyz="0 0 0" rpy="0 0 0"/>
      <geometry name="link:Torso_Naked_(1):body1-part_(3)_geometry">
        <mesh filename="meshes/Torso_Naked_(1):body1-part_(3).stl"/>
      </geometry>
      <material name="link:Torso_Naked_(1):body1-part_(3)_material">
        <color rgba="1 1 1 1"/>
      </material>
    </visual>
    <collision name="link:Torso_Naked_(1):body1-part_(3).collision">
      <origin xyz="0 0 0" rpy="0 0 0"/>
      <geometry name="link:Torso_Naked_(1):body1-part_(3)_collision_geometry">
        <mesh filename="meshes/Torso_Naked_(1):body1-part_(3).stl"/>
      </geometry>
    </collision>
    <inertial name="link:Torso_Naked_(1):body1-part_(3)_inertial">
      <mass value="0.2184791"/>
      <inertia ixx="0.0018812453" iyy="0.0014172355" izz="0.00053438067" ixy="-3.9835645e-06" ixz="-1.3418689e-05" iyz="-2.5774755e-05"/>
      <origin xyz="-0.012867514 -0.065706145 0.10424425" rpy="0 0 0"/>
    </inertial>
  </link>
  <joint name="joint:arm0_(1):Fastened_2" type="fixed">
    <origin xyz="0.020011964 5.6278452e-05 -0.0675" rpy="1.5707963 0 1.5707963"/>
    <parent link="link:arm0_(1):shoulder_(4)"/>
    <child link="link:arm0_(1):shoulder_(3)"/>
  </joint>
  <link name="link:arm0_(1):shoulder_(3)">
    <visual name="link:arm0_(1):shoulder_(3)_visual">
      <origin xyz="0 0 0" rpy="0 0 0"/>
      <geometry name="link:arm0_(1):shoulder_(3)_geometry">
        <mesh filename="meshes/arm0_(1):shoulder_(3).stl"/>
      </geometry>
      <material name="link:arm0_(1):shoulder_(3)_material">
        <color rgba="1 1 1 1"/>
      </material>
    </visual>
    <collision name="link:arm0_(1):shoulder_(3).collision">
      <origin xyz="0 0 0" rpy="0 0 0"/>
      <geometry name="link:arm0_(1):shoulder_(3)_collision_geometry">
        <mesh filename="meshes/arm0_(1):shoulder_(3).stl"/>
      </geometry>
    </collision>
    <inertial name="link:arm0_(1):shoulder_(3)_inertial">
      <mass value="0.9"/>
      <inertia ixx="0.00067098171" iyy="0.00067098171" izz="0.00090724844" ixy="0" ixz="0" iyz="0"/>
      <origin xyz="0 0 -0.024767932" rpy="0 0 0"/>
    </inertial>
  </link>
  <joint name="joint:arm0_(1):Fastened_1" type="fixed">
    <origin xyz="0.020011964 -5.6278452e-05 -0.0675" rpy="-1.5707963 0 -1.5707963"/>
    <parent link="link:arm0_(1):shoulder_(6)"/>
    <child link="link:arm0_(1):shoulder_(5)"/>
  </joint>
  <link name="link:arm0_(1):shoulder_(5)">
    <visual name="link:arm0_(1):shoulder_(5)_visual">
      <origin xyz="0 0 0" rpy="0 0 0"/>
      <geometry name="link:arm0_(1):shoulder_(5)_geometry">
        <mesh filename="meshes/arm0_(1):shoulder_(5).stl"/>
      </geometry>
      <material name="link:arm0_(1):shoulder_(5)_material">
        <color rgba="1 1 1 1"/>
      </material>
    </visual>
    <collision name="link:arm0_(1):shoulder_(5).collision">
      <origin xyz="0 0 0" rpy="0 0 0"/>
      <geometry name="link:arm0_(1):shoulder_(5)_collision_geometry">
        <mesh filename="meshes/arm0_(1):shoulder_(5).stl"/>
      </geometry>
    </collision>
    <inertial name="link:arm0_(1):shoulder_(5)_inertial">
      <mass value="0.9"/>
      <inertia ixx="0.00067098171" iyy="0.00067098171" izz="0.00090724844" ixy="0" ixz="0" iyz="0"/>
      <origin xyz="0 0 -0.024767932" rpy="0 0 0"/>
    </inertial>
  </link>
  <joint name="joint:Torso_Naked_(1):Fastened_2" type="fixed">
    <origin xyz="0.0375 0.0647 -0.011" rpy="-1.5707963 0 0"/>
    <parent link="link:Torso_Naked_(1):body1-part_(6)"/>
    <child link="link:Torso_Naked_(1):body1-part_(8)"/>
  </joint>
  <link name="link:Torso_Naked_(1):body1-part_(8)">
    <visual name="link:Torso_Naked_(1):body1-part_(8)_visual">
      <origin xyz="0 0 0" rpy="0 0 0"/>
      <geometry name="link:Torso_Naked_(1):body1-part_(8)_geometry">
        <mesh filename="meshes/Torso_Naked_(1):body1-part_(8).stl"/>
      </geometry>
      <material name="link:Torso_Naked_(1):body1-part_(8)_material">
        <color rgba="1 1 1 1"/>
      </material>
    </visual>
    <collision name="link:Torso_Naked_(1):body1-part_(8).collision">
      <origin xyz="0 0 0" rpy="0 0 0"/>
      <geometry name="link:Torso_Naked_(1):body1-part_(8)_collision_geometry">
        <mesh filename="meshes/Torso_Naked_(1):body1-part_(8).stl"/>
      </geometry>
    </collision>
    <inertial name="link:Torso_Naked_(1):body1-part_(8)_inertial">
      <mass value="0.9"/>
      <inertia ixx="0.00092667619" iyy="0.00094476194" izz="0.0015093945" ixy="0" ixz="0" iyz="0"/>
      <origin xyz="0 0 0.015265182" rpy="0 0 0"/>
    </inertial>
  </link>
  <joint name="joint:Torso_Naked_(1):Fastened_3" type="fixed">
    <origin xyz="0.0375 -0.0332 -0.011" rpy="-1.5707963 0 0"/>
    <parent link="link:Torso_Naked_(1):body1-part_(6)"/>
    <child link="link:Torso_Naked_(1):body1-part_(7)"/>
  </joint>
  <link name="link:Torso_Naked_(1):body1-part_(7)">
    <visual name="link:Torso_Naked_(1):body1-part_(7)_visual">
      <origin xyz="0 0 0" rpy="0 0 0"/>
      <geometry name="link:Torso_Naked_(1):body1-part_(7)_geometry">
        <mesh filename="meshes/Torso_Naked_(1):body1-part_(7).stl"/>
      </geometry>
      <material name="link:Torso_Naked_(1):body1-part_(7)_material">
        <color rgba="1 1 1 1"/>
      </material>
    </visual>
    <collision name="link:Torso_Naked_(1):body1-part_(7).collision">
      <origin xyz="0 0 0" rpy="0 0 0"/>
      <geometry name="link:Torso_Naked_(1):body1-part_(7)_collision_geometry">
        <mesh filename="meshes/Torso_Naked_(1):body1-part_(7).stl"/>
      </geometry>
    </collision>
    <inertial name="link:Torso_Naked_(1):body1-part_(7)_inertial">
      <mass value="0.9"/>
      <inertia ixx="0.00092667619" iyy="0.00094476194" izz="0.0015093945" ixy="0" ixz="0" iyz="0"/>
      <origin xyz="0 0 -0.015265182" rpy="0 0 0"/>
    </inertial>
  </link>
  <joint name="joint:Torso_Naked_(1):Fastened_6" type="fixed">
    <origin xyz="-0.003 -0.0645 0.1218" rpy="0 1.5707963 0"/>
    <parent link="link:Torso_Naked_(1):body1-part_(3)"/>
    <child link="link:Torso_Naked_(1):body1-part_(1)"/>
  </joint>
  <link name="link:Torso_Naked_(1):body1-part_(1)">
    <visual name="link:Torso_Naked_(1):body1-part_(1)_visual">
      <origin xyz="0 0 0" rpy="0 0 0"/>
      <geometry name="link:Torso_Naked_(1):body1-part_(1)_geometry">
        <mesh filename="meshes/Torso_Naked_(1):body1-part_(1).stl"/>
      </geometry>
      <material name="link:Torso_Naked_(1):body1-part_(1)_material">
        <color rgba="1 1 1 1"/>
      </material>
    </visual>
    <collision name="link:Torso_Naked_(1):body1-part_(1).collision">
      <origin xyz="0 0 0" rpy="0 0 0"/>
      <geometry name="link:Torso_Naked_(1):body1-part_(1)_collision_geometry">
        <mesh filename="meshes/Torso_Naked_(1):body1-part_(1).stl"/>
      </geometry>
    </collision>
    <inertial name="link:Torso_Naked_(1):body1-part_(1)_inertial">
      <mass value="2.65"/>
      <inertia ixx="0.0045809667" iyy="0.0076119042" izz="0.010495104" ixy="0" ixz="0" iyz="0"/>
      <origin xyz="0 0 -0.031" rpy="0 0 0"/>
    </inertial>
  </link>
  <joint name="joint:Torso_Naked_(1):Fastened_7" type="fixed">
    <origin xyz="-0.04 0.008 0.05865" rpy="0 1.5707963 0"/>
    <parent link="link:Torso_Naked_(1):body1-part_(3)"/>
    <child link="link:Torso_Naked_(1):body1-part_(2)"/>
  </joint>
  <link name="link:Torso_Naked_(1):body1-part_(2)">
    <visual name="link:Torso_Naked_(1):body1-part_(2)_visual">
      <origin xyz="0 0 0" rpy="0 0 0"/>
      <geometry name="link:Torso_Naked_(1):body1-part_(2)_geometry">
        <mesh filename="meshes/Torso_Naked_(1):body1-part_(2).stl"/>
      </geometry>
      <material name="link:Torso_Naked_(1):body1-part_(2)_material">
        <color rgba="1 1 1 1"/>
      </material>
    </visual>
    <collision name="link:Torso_Naked_(1):body1-part_(2).collision">
      <origin xyz="0 0 0" rpy="0 0 0"/>
      <geometry name="link:Torso_Naked_(1):body1-part_(2)_collision_geometry">
        <mesh filename="meshes/Torso_Naked_(1):body1-part_(2).stl"/>
      </geometry>
    </collision>
    <inertial name="link:Torso_Naked_(1):body1-part_(2)_inertial">
      <mass value="0.19664803"/>
      <inertia ixx="0.00048017886" iyy="0.0011617696" izz="0.0016065057" ixy="-2.1892502e-06" ixz="1.2826178e-06" iyz="0"/>
      <origin xyz="-0.049405081 -0.07235961 -0.021136733" rpy="0 0 0"/>
    </inertial>
  </link>
  <joint name="joint:left_shoulder_roll_03" type="revolute">
    <origin xyz="0 0 0.0025" rpy="0 0 0"/>
    <parent link="link:arm0_(1):shoulder_(3)"/>
    <child link="link:arm1_(1):arm1_top_(1)"/>
    <limit effort="60" velocity="6.283" lower="-3.6302848" upper="0.47996554"/>
    <axis xyz="0 0 -1"/>
  </joint>
  <link name="link:arm1_(1):arm1_top_(1)">
    <visual name="link:arm1_(1):arm1_top_(1)_visual">
      <origin xyz="0 0 0" rpy="0 0 0"/>
      <geometry name="link:arm1_(1):arm1_top_(1)_geometry">
        <mesh filename="meshes/arm1_(1):arm1_top_(1).stl"/>
      </geometry>
      <material name="link:arm1_(1):arm1_top_(1)_material">
        <color rgba="0.89803922 0.91764706 0.92941176 1"/>
      </material>
    </visual>
    <collision name="link:arm1_(1):arm1_top_(1).collision">
      <origin xyz="0 0 0" rpy="0 0 0"/>
      <geometry name="link:arm1_(1):arm1_top_(1)_collision_geometry">
        <mesh filename="meshes/arm1_(1):arm1_top_(1).stl"/>
      </geometry>
    </collision>
    <inertial name="link:arm1_(1):arm1_top_(1)_inertial">
      <mass value="0.17273239"/>
      <inertia ixx="0.00014277081" iyy="0.00032836929" izz="0.00031367502" ixy="0" ixz="-7.7657011e-05" iyz="0"/>
      <origin xyz="-0.052942145 -3.8550161e-06 -0.0088528025" rpy="0 0 0"/>
    </inertial>
  </link>
  <joint name="joint:right_shoulder_roll_03" type="revolute">
    <origin xyz="0 0 0.0025" rpy="3.1415927 0 0"/>
    <parent link="link:arm0_(1):shoulder_(5)"/>
    <child link="link:arm1_(1):arm1_top_2_(2)"/>
    <limit effort="60" velocity="6.283" lower="-0.47996554" upper="3.6302848"/>
    <axis xyz="0 0 1"/>
  </joint>
  <link name="link:arm1_(1):arm1_top_2_(2)">
    <visual name="link:arm1_(1):arm1_top_2_(2)_visual">
      <origin xyz="0 0 0" rpy="0 0 0"/>
      <geometry name="link:arm1_(1):arm1_top_2_(2)_geometry">
        <mesh filename="meshes/arm1_(1):arm1_top_2_(2).stl"/>
      </geometry>
      <material name="link:arm1_(1):arm1_top_2_(2)_material">
        <color rgba="0.89803922 0.91764706 0.92941176 1"/>
      </material>
    </visual>
    <collision name="link:arm1_(1):arm1_top_2_(2).collision">
      <origin xyz="0 0 0" rpy="0 0 0"/>
      <geometry name="link:arm1_(1):arm1_top_2_(2)_collision_geometry">
        <mesh filename="meshes/arm1_(1):arm1_top_2_(2).stl"/>
      </geometry>
    </collision>
    <inertial name="link:arm1_(1):arm1_top_2_(2)_inertial">
      <mass value="0.17273186"/>
      <inertia ixx="0.00014276994" iyy="0.00032836833" izz="0.00031367483" ixy="0" ixz="7.7656754e-05" iyz="0"/>
      <origin xyz="-0.052942107 -3.5991896e-06 0.0078526534" rpy="0 0 0"/>
    </inertial>
  </link>
  <joint name="joint:left_hip_pitch_04" type="revolute">
    <origin xyz="0 0 0.039" rpy="3.1415927 0 0"/>
    <parent link="link:Torso_Naked_(1):body1-part_(8)"/>
    <child link="link:leg0_(1):leg0_shell_(1)"/>
    <limit effort="120" velocity="6.283" lower="-1.5707963" upper="1.5707963"/>
    <axis xyz="0 0 1"/>
  </joint>
  <link name="link:leg0_(1):leg0_shell_(1)">
    <visual name="link:leg0_(1):leg0_shell_(1)_visual">
      <origin xyz="0 0 0" rpy="0 0 0"/>
      <geometry name="link:leg0_(1):leg0_shell_(1)_geometry">
        <mesh filename="meshes/leg0_(1):leg0_shell_(1).stl"/>
      </geometry>
      <material name="link:leg0_(1):leg0_shell_(1)_material">
        <color rgba="0.89803922 0.91764706 0.92941176 1"/>
      </material>
    </visual>
    <collision name="link:leg0_(1):leg0_shell_(1).collision">
      <origin xyz="0 0 0" rpy="0 0 0"/>
      <geometry name="link:leg0_(1):leg0_shell_(1)_collision_geometry">
        <mesh filename="meshes/leg0_(1):leg0_shell_(1).stl"/>
      </geometry>
    </collision>
    <inertial name="link:leg0_(1):leg0_shell_(1)_inertial">
      <mass value="0.37018127"/>
      <inertia ixx="0.00093621354" iyy="0.00065646916" izz="0.00053778412" ixy="0" ixz="2.8249641e-06" iyz="0"/>
      <origin xyz="-0.0060442347 0 -0.064584622" rpy="0 0 0"/>
    </inertial>
  </link>
  <joint name="joint:Torso_Naked_(1):Fastened_11" type="fixed">
    <origin xyz="0 0 0.039" rpy="3.1415927 0 0"/>
    <parent link="link:Torso_Naked_(1):body1-part_(8)"/>
    <child link="link:Torso_Naked_(1):body1-part_(12)"/>
  </joint>
  <link name="link:Torso_Naked_(1):body1-part_(12)">
    <visual name="link:Torso_Naked_(1):body1-part_(12)_visual">
      <origin xyz="0 0 0" rpy="0 0 0"/>
      <geometry name="link:Torso_Naked_(1):body1-part_(12)_geometry">
        <mesh filename="meshes/Torso_Naked_(1):body1-part_(12).stl"/>
      </geometry>
      <material name="link:Torso_Naked_(1):body1-part_(12)_material">
        <color rgba="1 1 1 1"/>
      </material>
    </visual>
    <collision name="link:Torso_Naked_(1):body1-part_(12).collision">
      <origin xyz="0 0 0" rpy="0 0 0"/>
      <geometry name="link:Torso_Naked_(1):body1-part_(12)_collision_geometry">
        <mesh filename="meshes/Torso_Naked_(1):body1-part_(12).stl"/>
      </geometry>
    </collision>
    <inertial name="link:Torso_Naked_(1):body1-part_(12)_inertial">
      <mass value="0.067658274"/>
      <inertia ixx="3.3775869e-05" iyy="6.8844667e-06" izz="3.7372327e-05" ixy="0" ixz="0" iyz="0"/>
      <origin xyz="-0.043191859 0 -0.0082396077" rpy="0 0 0"/>
    </inertial>
  </link>
  <joint name="joint:right_hip_pitch_04" type="revolute">
    <origin xyz="0 0 -0.039" rpy="0 0 0"/>
    <parent link="link:Torso_Naked_(1):body1-part_(7)"/>
    <child link="link:leg0_(2):leg0_shell_(1)"/>
    <limit effort="120" velocity="6.283" lower="-1.5707963" upper="1.5707963"/>
    <axis xyz="0 0 1"/>
  </joint>
  <link name="link:leg0_(2):leg0_shell_(1)">
    <visual name="link:leg0_(2):leg0_shell_(1)_visual">
      <origin xyz="0 0 0" rpy="0 0 0"/>
      <geometry name="link:leg0_(2):leg0_shell_(1)_geometry">
        <mesh filename="meshes/leg0_(2):leg0_shell_(1).stl"/>
      </geometry>
      <material name="link:leg0_(2):leg0_shell_(1)_material">
        <color rgba="0.89803922 0.91764706 0.92941176 1"/>
      </material>
    </visual>
    <collision name="link:leg0_(2):leg0_shell_(1).collision">
      <origin xyz="0 0 0" rpy="0 0 0"/>
      <geometry name="link:leg0_(2):leg0_shell_(1)_collision_geometry">
        <mesh filename="meshes/leg0_(2):leg0_shell_(1).stl"/>
      </geometry>
    </collision>
    <inertial name="link:leg0_(2):leg0_shell_(1)_inertial">
      <mass value="0.37018127"/>
      <inertia ixx="0.00093621354" iyy="0.00065646916" izz="0.00053778412" ixy="0" ixz="2.8249641e-06" iyz="0"/>
      <origin xyz="-0.0060442347 0 -0.064084622" rpy="0 0 0"/>
    </inertial>
  </link>
  <joint name="joint:Torso_Naked_(1):Fastened_10" type="fixed">
    <origin xyz="0 0 -0.039" rpy="0 0 0"/>
    <parent link="link:Torso_Naked_(1):body1-part_(7)"/>
    <child link="link:Torso_Naked_(1):body1-part_(13)"/>
  </joint>
  <link name="link:Torso_Naked_(1):body1-part_(13)">
    <visual name="link:Torso_Naked_(1):body1-part_(13)_visual">
      <origin xyz="0 0 0" rpy="0 0 0"/>
      <geometry name="link:Torso_Naked_(1):body1-part_(13)_geometry">
        <mesh filename="meshes/Torso_Naked_(1):body1-part_(13).stl"/>
      </geometry>
      <material name="link:Torso_Naked_(1):body1-part_(13)_material">
        <color rgba="1 1 1 1"/>
      </material>
    </visual>
    <collision name="link:Torso_Naked_(1):body1-part_(13).collision">
      <origin xyz="0 0 0" rpy="0 0 0"/>
      <geometry name="link:Torso_Naked_(1):body1-part_(13)_collision_geometry">
        <mesh filename="meshes/Torso_Naked_(1):body1-part_(13).stl"/>
      </geometry>
    </collision>
    <inertial name="link:Torso_Naked_(1):body1-part_(13)_inertial">
      <mass value="0.067658274"/>
      <inertia ixx="3.3775869e-05" iyy="6.8844667e-06" izz="3.7372327e-05" ixy="0" ixz="0" iyz="0"/>
      <origin xyz="-0.043191859 0 -0.0082396077" rpy="0 0 0"/>
    </inertial>
  </link>
  <joint name="joint:arm1_(1):Fastened_2" type="fixed">
    <origin xyz="-0.108 0 -0.0235" rpy="3.1415927 -1.5707963 0"/>
    <parent link="link:arm1_(1):arm1_top_(1)"/>
    <child link="link:arm1_(1):arm-actuator_(1)"/>
  </joint>
  <link name="link:arm1_(1):arm-actuator_(1)">
    <visual name="link:arm1_(1):arm-actuator_(1)_visual">
      <origin xyz="0 0 0" rpy="0 0 0"/>
      <geometry name="link:arm1_(1):arm-actuator_(1)_geometry">
        <mesh filename="meshes/arm1_(1):arm-actuator_(1).stl"/>
      </geometry>
      <material name="link:arm1_(1):arm-actuator_(1)_material">
        <color rgba="0.79215686 0.81960784 0.93333333 1"/>
      </material>
    </visual>
    <collision name="link:arm1_(1):arm-actuator_(1).collision">
      <origin xyz="0 0 0" rpy="0 0 0"/>
      <geometry name="link:arm1_(1):arm-actuator_(1)_collision_geometry">
        <mesh filename="meshes/arm1_(1):arm-actuator_(1).stl"/>
      </geometry>
    </collision>
    <inertial name="link:arm1_(1):arm-actuator_(1)_inertial">
      <mass value="0.4"/>
      <inertia ixx="0.00018548163" iyy="0.00018548163" izz="0.00028416296" ixy="0" ixz="0" iyz="0"/>
      <origin xyz="0 0 -0.011585135" rpy="0 0 0"/>
    </inertial>
  </link>
  <joint name="joint:arm1_(1):Fastened_1" type="fixed">
    <origin xyz="-0.108 0 0.0225" rpy="0 1.5707963 0"/>
    <parent link="link:arm1_(1):arm1_top_2_(2)"/>
    <child link="link:arm1_(1):arm-actuator_(2)"/>
  </joint>
  <link name="link:arm1_(1):arm-actuator_(2)">
    <visual name="link:arm1_(1):arm-actuator_(2)_visual">
      <origin xyz="0 0 0" rpy="0 0 0"/>
      <geometry name="link:arm1_(1):arm-actuator_(2)_geometry">
        <mesh filename="meshes/arm1_(1):arm-actuator_(2).stl"/>
      </geometry>
      <material name="link:arm1_(1):arm-actuator_(2)_material">
        <color rgba="0.79215686 0.81960784 0.93333333 1"/>
      </material>
    </visual>
    <collision name="link:arm1_(1):arm-actuator_(2).collision">
      <origin xyz="0 0 0" rpy="0 0 0"/>
      <geometry name="link:arm1_(1):arm-actuator_(2)_collision_geometry">
        <mesh filename="meshes/arm1_(1):arm-actuator_(2).stl"/>
      </geometry>
    </collision>
    <inertial name="link:arm1_(1):arm-actuator_(2)_inertial">
      <mass value="0.4"/>
      <inertia ixx="0.00018548163" iyy="0.00018548163" izz="0.00028416296" ixy="0" ixz="0" iyz="0"/>
      <origin xyz="0 0 -0.011585135" rpy="0 0 0"/>
    </inertial>
  </link>
  <joint name="joint:leg0_(1):Fastened_1" type="fixed">
    <origin xyz="-0.0301 0 -0.0695" rpy="-1.5707963 0 1.5707963"/>
    <parent link="link:leg0_(1):leg0_shell_(1)"/>
    <child link="link:leg0_(1):leg0_actuator_(1)"/>
  </joint>
  <link name="link:leg0_(1):leg0_actuator_(1)">
    <visual name="link:leg0_(1):leg0_actuator_(1)_visual">
      <origin xyz="0 0 0" rpy="0 0 0"/>
      <geometry name="link:leg0_(1):leg0_actuator_(1)_geometry">
        <mesh filename="meshes/leg0_(1):leg0_actuator_(1).stl"/>
      </geometry>
      <material name="link:leg0_(1):leg0_actuator_(1)_material">
        <color rgba="0.79215686 0.81960784 0.93333333 1"/>
      </material>
    </visual>
    <collision name="link:leg0_(1):leg0_actuator_(1).collision">
      <origin xyz="0 0 0" rpy="0 0 0"/>
      <geometry name="link:leg0_(1):leg0_actuator_(1)_collision_geometry">
        <mesh filename="meshes/leg0_(1):leg0_actuator_(1).stl"/>
      </geometry>
    </collision>
    <inertial name="link:leg0_(1):leg0_actuator_(1)_inertial">
      <mass value="0.9"/>
      <inertia ixx="0.00067098171" iyy="0.00067098171" izz="0.00090724844" ixy="0" ixz="0" iyz="0"/>
      <origin xyz="0 0 -0.029332068" rpy="0 0 0"/>
    </inertial>
  </link>
  <joint name="joint:leg0_(1):Fastened_2" type="fixed">
    <origin xyz="-0.0346 0 -0.0695" rpy="1.5707963 0 1.5707963"/>
    <parent link="link:leg0_(1):leg0_shell_(1)"/>
    <child link="link:leg0_(1):leg0_bearing_(1)"/>
  </joint>
  <link name="link:leg0_(1):leg0_bearing_(1)">
    <visual name="link:leg0_(1):leg0_bearing_(1)_visual">
      <origin xyz="0 0 0" rpy="0 0 0"/>
      <geometry name="link:leg0_(1):leg0_bearing_(1)_geometry">
        <mesh filename="meshes/leg0_(1):leg0_bearing_(1).stl"/>
      </geometry>
      <material name="link:leg0_(1):leg0_bearing_(1)_material">
        <color rgba="0.89803922 0.91764706 0.92941176 1"/>
      </material>
    </visual>
    <collision name="link:leg0_(1):leg0_bearing_(1).collision">
      <origin xyz="0 0 0" rpy="0 0 0"/>
      <geometry name="link:leg0_(1):leg0_bearing_(1)_collision_geometry">
        <mesh filename="meshes/leg0_(1):leg0_bearing_(1).stl"/>
      </geometry>
    </collision>
    <inertial name="link:leg0_(1):leg0_bearing_(1)_inertial">
      <mass value="0.053266787"/>
      <inertia ixx="1.8136502e-05" iyy="1.8136502e-05" izz="3.5913995e-05" ixy="0" ixz="0" iyz="0"/>
      <origin xyz="0 0 -0.0035" rpy="0 0 0"/>
    </inertial>
  </link>
  <joint name="joint:leg0_(2):Fastened_1" type="fixed">
    <origin xyz="-0.0301 0 -0.069" rpy="-1.5707963 0 1.5707963"/>
    <parent link="link:leg0_(2):leg0_shell_(1)"/>
    <child link="link:leg0_(2):leg0_actuator_(1)"/>
  </joint>
  <link name="link:leg0_(2):leg0_actuator_(1)">
    <visual name="link:leg0_(2):leg0_actuator_(1)_visual">
      <origin xyz="0 0 0" rpy="0 0 0"/>
      <geometry name="link:leg0_(2):leg0_actuator_(1)_geometry">
        <mesh filename="meshes/leg0_(2):leg0_actuator_(1).stl"/>
      </geometry>
      <material name="link:leg0_(2):leg0_actuator_(1)_material">
        <color rgba="0.79215686 0.81960784 0.93333333 1"/>
      </material>
    </visual>
    <collision name="link:leg0_(2):leg0_actuator_(1).collision">
      <origin xyz="0 0 0" rpy="0 0 0"/>
      <geometry name="link:leg0_(2):leg0_actuator_(1)_collision_geometry">
        <mesh filename="meshes/leg0_(2):leg0_actuator_(1).stl"/>
      </geometry>
    </collision>
    <inertial name="link:leg0_(2):leg0_actuator_(1)_inertial">
      <mass value="0.9"/>
      <inertia ixx="0.00067098171" iyy="0.00067098171" izz="0.00090724844" ixy="0" ixz="0" iyz="0"/>
      <origin xyz="0 0 -0.029332068" rpy="0 0 0"/>
    </inertial>
  </link>
  <joint name="joint:leg0_(2):Fastened_2" type="fixed">
    <origin xyz="-0.0346 0 -0.069" rpy="1.5707963 0 1.5707963"/>
    <parent link="link:leg0_(2):leg0_shell_(1)"/>
    <child link="link:leg0_(2):leg0_bearing_(1)"/>
  </joint>
  <link name="link:leg0_(2):leg0_bearing_(1)">
    <visual name="link:leg0_(2):leg0_bearing_(1)_visual">
      <origin xyz="0 0 0" rpy="0 0 0"/>
      <geometry name="link:leg0_(2):leg0_bearing_(1)_geometry">
        <mesh filename="meshes/leg0_(2):leg0_bearing_(1).stl"/>
      </geometry>
      <material name="link:leg0_(2):leg0_bearing_(1)_material">
        <color rgba="0.89803922 0.91764706 0.92941176 1"/>
      </material>
    </visual>
    <collision name="link:leg0_(2):leg0_bearing_(1).collision">
      <origin xyz="0 0 0" rpy="0 0 0"/>
      <geometry name="link:leg0_(2):leg0_bearing_(1)_collision_geometry">
        <mesh filename="meshes/leg0_(2):leg0_bearing_(1).stl"/>
      </geometry>
    </collision>
    <inertial name="link:leg0_(2):leg0_bearing_(1)_inertial">
      <mass value="0.053266787"/>
      <inertia ixx="1.8136502e-05" iyy="1.8136502e-05" izz="3.5913995e-05" ixy="0" ixz="0" iyz="0"/>
      <origin xyz="0 0 -0.0035" rpy="0 0 0"/>
    </inertial>
  </link>
  <joint name="joint:left_shoulder_yaw_02" type="revolute">
    <origin xyz="0 0 -0.0315" rpy="0 0 1.5707963"/>
    <parent link="link:arm1_(1):arm-actuator_(1)"/>
    <child link="link:arm2_(1):arm2_shell_(1)"/>
    <limit effort="17" velocity="12.566" lower="-1.5707963" upper="1.5707963"/>
    <axis xyz="0 0 1"/>
  </joint>
  <link name="link:arm2_(1):arm2_shell_(1)">
    <visual name="link:arm2_(1):arm2_shell_(1)_visual">
      <origin xyz="0 0 0" rpy="0 0 0"/>
      <geometry name="link:arm2_(1):arm2_shell_(1)_geometry">
        <mesh filename="meshes/arm2_(1):arm2_shell_(1).stl"/>
      </geometry>
      <material name="link:arm2_(1):arm2_shell_(1)_material">
        <color rgba="0.89803922 0.91764706 0.92941176 1"/>
      </material>
    </visual>
    <collision name="link:arm2_(1):arm2_shell_(1).collision">
      <origin xyz="0 0 0" rpy="0 0 0"/>
      <geometry name="link:arm2_(1):arm2_shell_(1)_collision_geometry">
        <mesh filename="meshes/arm2_(1):arm2_shell_(1).stl"/>
      </geometry>
    </collision>
    <inertial name="link:arm2_(1):arm2_shell_(1)_inertial">
      <mass value="0.11067762"/>
      <inertia ixx="0.00028687578" iyy="0.00024235908" izz="6.900697e-05" ixy="0" ixz="-1.1757297e-05" iyz="0"/>
      <origin xyz="-0.0078729258 0 -0.063311706" rpy="0 0 0"/>
    </inertial>
  </link>
  <joint name="joint:right_shoulder_yaw_02" type="revolute">
    <origin xyz="0 0 -0.0315" rpy="3.1415927 0 0"/>
    <parent link="link:arm1_(1):arm-actuator_(2)"/>
    <child link="link:arm2_(2):arm2_shell_(1)"/>
    <limit effort="17" velocity="12.566" lower="-1.5707963" upper="1.5707963"/>
    <axis xyz="0 0 -1"/>
  </joint>
  <link name="link:arm2_(2):arm2_shell_(1)">
    <visual name="link:arm2_(2):arm2_shell_(1)_visual">
      <origin xyz="0 0 0" rpy="0 0 0"/>
      <geometry name="link:arm2_(2):arm2_shell_(1)_geometry">
        <mesh filename="meshes/arm2_(2):arm2_shell_(1).stl"/>
      </geometry>
      <material name="link:arm2_(2):arm2_shell_(1)_material">
        <color rgba="0.89803922 0.91764706 0.92941176 1"/>
      </material>
    </visual>
    <collision name="link:arm2_(2):arm2_shell_(1).collision">
      <origin xyz="0 0 0" rpy="0 0 0"/>
      <geometry name="link:arm2_(2):arm2_shell_(1)_collision_geometry">
        <mesh filename="meshes/arm2_(2):arm2_shell_(1).stl"/>
      </geometry>
    </collision>
    <inertial name="link:arm2_(2):arm2_shell_(1)_inertial">
      <mass value="0.11067762"/>
      <inertia ixx="0.00024235908" iyy="0.00028687578" izz="6.900697e-05" ixy="0" ixz="0" iyz="1.1757297e-05"/>
      <origin xyz="0 -0.0078729258 0.062811706" rpy="0 0 0"/>
    </inertial>
  </link>
  <joint name="joint:left_hip_roll_03" type="revolute">
    <origin xyz="0 0 -0.0566" rpy="0 0 0"/>
    <parent link="link:leg0_(1):leg0_actuator_(1)"/>
    <child link="link:leg1_(1):leg1_shell_(1)"/>
    <limit effort="60" velocity="6.283" lower="-3.1852259" upper="0.34906585"/>
    <axis xyz="0 0 1"/>
  </joint>
  <link name="link:leg1_(1):leg1_shell_(1)">
    <visual name="link:leg1_(1):leg1_shell_(1)_visual">
      <origin xyz="0 0 0" rpy="0 0 0"/>
      <geometry name="link:leg1_(1):leg1_shell_(1)_geometry">
        <mesh filename="meshes/leg1_(1):leg1_shell_(1).stl"/>
      </geometry>
      <material name="link:leg1_(1):leg1_shell_(1)_material">
        <color rgba="0.89803922 0.91764706 0.92941176 1"/>
      </material>
    </visual>
    <collision name="link:leg1_(1):leg1_shell_(1).collision">
      <origin xyz="0 0 0" rpy="0 0 0"/>
      <geometry name="link:leg1_(1):leg1_shell_(1)_collision_geometry">
        <mesh filename="meshes/leg1_(1):leg1_shell_(1).stl"/>
      </geometry>
    </collision>
    <inertial name="link:leg1_(1):leg1_shell_(1)_inertial">
      <mass value="0.36435193"/>
      <inertia ixx="0.00055726169" iyy="0.0009271849" izz="0.00086978874" ixy="3.3240555e-06" ixz="0.00017286109" iyz="-4.6898041e-06"/>
      <origin xyz="-0.071251288 0.0015393329 0.019722185" rpy="0 0 0"/>
    </inertial>
  </link>
  <joint name="joint:right_hip_roll_03" type="revolute">
    <origin xyz="0 0 -0.0566" rpy="0 0 3.1415927"/>
    <parent link="link:leg0_(2):leg0_actuator_(1)"/>
    <child link="link:leg1_(1):leg1_shell3_(2)"/>
    <limit effort="60" velocity="6.283" lower="-0.34906585" upper="3.1852259"/>
    <axis xyz="0 0 1"/>
  </joint>
  <link name="link:leg1_(1):leg1_shell3_(2)">
    <visual name="link:leg1_(1):leg1_shell3_(2)_visual">
      <origin xyz="0 0 0" rpy="0 0 0"/>
      <geometry name="link:leg1_(1):leg1_shell3_(2)_geometry">
        <mesh filename="meshes/leg1_(1):leg1_shell3_(2).stl"/>
      </geometry>
      <material name="link:leg1_(1):leg1_shell3_(2)_material">
        <color rgba="0.89803922 0.91764706 0.92941176 1"/>
      </material>
    </visual>
    <collision name="link:leg1_(1):leg1_shell3_(2).collision">
      <origin xyz="0 0 0" rpy="0 0 0"/>
      <geometry name="link:leg1_(1):leg1_shell3_(2)_collision_geometry">
        <mesh filename="meshes/leg1_(1):leg1_shell3_(2).stl"/>
      </geometry>
    </collision>
    <inertial name="link:leg1_(1):leg1_shell3_(2)_inertial">
      <mass value="0.36435173"/>
      <inertia ixx="0.00055726131" iyy="0.00092718468" izz="0.00086978844" ixy="-3.3242222e-06" ixz="0.00017286101" iyz="4.6899308e-06"/>
      <origin xyz="-0.07125128 -0.0015393583 0.019722164" rpy="0 0 0"/>
    </inertial>
  </link>
  <joint name="joint:arm2_(1):Fastened_1" type="fixed">
    <origin xyz="-0.0175 0 -0.098" rpy="0 -1.5707963 0"/>
    <parent link="link:arm2_(1):arm2_shell_(1)"/>
    <child link="link:arm2_(1):arm2_actuator_(1)"/>
  </joint>
  <link name="link:arm2_(1):arm2_actuator_(1)">
    <visual name="link:arm2_(1):arm2_actuator_(1)_visual">
      <origin xyz="0 0 0" rpy="0 0 0"/>
      <geometry name="link:arm2_(1):arm2_actuator_(1)_geometry">
        <mesh filename="meshes/arm2_(1):arm2_actuator_(1).stl"/>
      </geometry>
      <material name="link:arm2_(1):arm2_actuator_(1)_material">
        <color rgba="0.79215686 0.81960784 0.93333333 1"/>
      </material>
    </visual>
    <collision name="link:arm2_(1):arm2_actuator_(1).collision">
      <origin xyz="0 0 0" rpy="0 0 0"/>
      <geometry name="link:arm2_(1):arm2_actuator_(1)_collision_geometry">
        <mesh filename="meshes/arm2_(1):arm2_actuator_(1).stl"/>
      </geometry>
    </collision>
    <inertial name="link:arm2_(1):arm2_actuator_(1)_inertial">
      <mass value="0.4"/>
      <inertia ixx="0.00018548163" iyy="0.00018548163" izz="0.00028416296" ixy="0" ixz="0" iyz="0"/>
      <origin xyz="0 0 -0.011585135" rpy="0 0 0"/>
    </inertial>
  </link>
  <joint name="joint:arm2_(2):Fastened_1" type="fixed">
    <origin xyz="0 -0.0175 0.0975" rpy="1.5707963 1.5707963 0"/>
    <parent link="link:arm2_(2):arm2_shell_(1)"/>
    <child link="link:arm2_(2):arm2_actuator_(1)"/>
  </joint>
  <link name="link:arm2_(2):arm2_actuator_(1)">
    <visual name="link:arm2_(2):arm2_actuator_(1)_visual">
      <origin xyz="0 0 0" rpy="0 0 0"/>
      <geometry name="link:arm2_(2):arm2_actuator_(1)_geometry">
        <mesh filename="meshes/arm2_(2):arm2_actuator_(1).stl"/>
      </geometry>
      <material name="link:arm2_(2):arm2_actuator_(1)_material">
        <color rgba="0.79215686 0.81960784 0.93333333 1"/>
      </material>
    </visual>
    <collision name="link:arm2_(2):arm2_actuator_(1).collision">
      <origin xyz="0 0 0" rpy="0 0 0"/>
      <geometry name="link:arm2_(2):arm2_actuator_(1)_collision_geometry">
        <mesh filename="meshes/arm2_(2):arm2_actuator_(1).stl"/>
      </geometry>
    </collision>
    <inertial name="link:arm2_(2):arm2_actuator_(1)_inertial">
      <mass value="0.4"/>
      <inertia ixx="0.00018548163" iyy="0.00018548163" izz="0.00028416296" ixy="0" ixz="0" iyz="0"/>
      <origin xyz="0 0 -0.011585135" rpy="0 0 0"/>
    </inertial>
  </link>
  <joint name="joint:leg1_(1):Fastened_2" type="fixed">
    <origin xyz="-0.0999 0.00011981393 0.0275" rpy="0 1.5707963 0"/>
    <parent link="link:leg1_(1):leg1_shell_(1)"/>
    <child link="link:leg1_(1):leg1_actuator_(1)"/>
  </joint>
  <link name="link:leg1_(1):leg1_actuator_(1)">
    <visual name="link:leg1_(1):leg1_actuator_(1)_visual">
      <origin xyz="0 0 0" rpy="0 0 0"/>
      <geometry name="link:leg1_(1):leg1_actuator_(1)_geometry">
        <mesh filename="meshes/leg1_(1):leg1_actuator_(1).stl"/>
      </geometry>
      <material name="link:leg1_(1):leg1_actuator_(1)_material">
        <color rgba="0.79215686 0.81960784 0.93333333 1"/>
      </material>
    </visual>
    <collision name="link:leg1_(1):leg1_actuator_(1).collision">
      <origin xyz="0 0 0" rpy="0 0 0"/>
      <geometry name="link:leg1_(1):leg1_actuator_(1)_collision_geometry">
        <mesh filename="meshes/leg1_(1):leg1_actuator_(1).stl"/>
      </geometry>
    </collision>
    <inertial name="link:leg1_(1):leg1_actuator_(1)_inertial">
      <mass value="0.9"/>
      <inertia ixx="0.00067098171" iyy="0.00067098171" izz="0.00090724844" ixy="0" ixz="0" iyz="0"/>
      <origin xyz="0 0 -0.029332068" rpy="0 0 0"/>
    </inertial>
  </link>
  <joint name="joint:leg1_(1):Fastened_1" type="fixed">
    <origin xyz="-0.0999 -0.00011981393 0.0275" rpy="0 1.5707963 0"/>
    <parent link="link:leg1_(1):leg1_shell3_(2)"/>
    <child link="link:leg1_(1):leg1_actuator2_(2)"/>
  </joint>
  <link name="link:leg1_(1):leg1_actuator2_(2)">
    <visual name="link:leg1_(1):leg1_actuator2_(2)_visual">
      <origin xyz="0 0 0" rpy="0 0 0"/>
      <geometry name="link:leg1_(1):leg1_actuator2_(2)_geometry">
        <mesh filename="meshes/leg1_(1):leg1_actuator2_(2).stl"/>
      </geometry>
      <material name="link:leg1_(1):leg1_actuator2_(2)_material">
        <color rgba="0.79215686 0.81960784 0.93333333 1"/>
      </material>
    </visual>
    <collision name="link:leg1_(1):leg1_actuator2_(2).collision">
      <origin xyz="0 0 0" rpy="0 0 0"/>
      <geometry name="link:leg1_(1):leg1_actuator2_(2)_collision_geometry">
        <mesh filename="meshes/leg1_(1):leg1_actuator2_(2).stl"/>
      </geometry>
    </collision>
    <inertial name="link:leg1_(1):leg1_actuator2_(2)_inertial">
      <mass value="0.9"/>
      <inertia ixx="0.00067098171" iyy="0.00067098171" izz="0.00090724844" ixy="0" ixz="0" iyz="0"/>
      <origin xyz="0 0 -0.029332068" rpy="0 0 0"/>
    </inertial>
  </link>
  <joint name="joint:left_elbow_02" type="revolute">
    <origin xyz="0 0 0.0085" rpy="3.1415927 0 0"/>
    <parent link="link:arm2_(1):arm2_actuator_(1)"/>
    <child link="link:arm3_(1):arm3_shell_(1)"/>
    <limit effort="17" velocity="12.566" lower="-2.5307274" upper="0"/>
    <axis xyz="0 0 1"/>
  </joint>
  <link name="link:arm3_(1):arm3_shell_(1)">
    <visual name="link:arm3_(1):arm3_shell_(1)_visual">
      <origin xyz="0 0 0" rpy="0 0 0"/>
      <geometry name="link:arm3_(1):arm3_shell_(1)_geometry">
        <mesh filename="meshes/arm3_(1):arm3_shell_(1).stl"/>
      </geometry>
      <material name="link:arm3_(1):arm3_shell_(1)_material">
        <color rgba="0.89803922 0.91764706 0.92941176 1"/>
      </material>
    </visual>
    <collision name="link:arm3_(1):arm3_shell_(1).collision">
      <origin xyz="0 0 0" rpy="0 0 0"/>
      <geometry name="link:arm3_(1):arm3_shell_(1)_collision_geometry">
        <mesh filename="meshes/arm3_(1):arm3_shell_(1).stl"/>
      </geometry>
    </collision>
    <inertial name="link:arm3_(1):arm3_shell_(1)_inertial">
      <mass value="0.1785364"/>
      <inertia ixx="0.00013841579" iyy="0.00056846854" izz="0.00055180031" ixy="0" ixz="8.6928501e-05" iyz="0"/>
      <origin xyz="-0.092186388 0 0.014801529" rpy="0 0 0"/>
    </inertial>
  </link>
  <joint name="joint:right_elbow_02" type="revolute">
    <origin xyz="0 0 0.0085" rpy="3.1415927 0 0"/>
    <parent link="link:arm2_(2):arm2_actuator_(1)"/>
    <child link="link:arm3_(1):arm3_shell2_(1)"/>
    <limit effort="17" velocity="12.566" lower="0" upper="2.5307274"/>
    <axis xyz="0 0 1"/>
  </joint>
  <link name="link:arm3_(1):arm3_shell2_(1)">
    <visual name="link:arm3_(1):arm3_shell2_(1)_visual">
      <origin xyz="0 0 0" rpy="0 0 0"/>
      <geometry name="link:arm3_(1):arm3_shell2_(1)_geometry">
        <mesh filename="meshes/arm3_(1):arm3_shell2_(1).stl"/>
      </geometry>
      <material name="link:arm3_(1):arm3_shell2_(1)_material">
        <color rgba="0.89803922 0.91764706 0.92941176 1"/>
      </material>
    </visual>
    <collision name="link:arm3_(1):arm3_shell2_(1).collision">
      <origin xyz="0 0 0" rpy="0 0 0"/>
      <geometry name="link:arm3_(1):arm3_shell2_(1)_collision_geometry">
        <mesh filename="meshes/arm3_(1):arm3_shell2_(1).stl"/>
      </geometry>
    </collision>
    <inertial name="link:arm3_(1):arm3_shell2_(1)_inertial">
      <mass value="0.1785364"/>
      <inertia ixx="0.00013841579" iyy="0.00056846854" izz="0.00055180031" ixy="0" ixz="8.6928501e-05" iyz="0"/>
      <origin xyz="-0.092186388 0 0.014801529" rpy="0 0 0"/>
    </inertial>
  </link>
  <joint name="joint:left_hip_yaw_03" type="revolute">
    <origin xyz="0 0 -0.0566" rpy="0 0 0"/>
    <parent link="link:leg1_(1):leg1_actuator_(1)"/>
    <child link="link:leg2_(2):leg2_shell_(1)"/>
    <limit effort="60" velocity="6.283" lower="-1.5707963" upper="1.5707963"/>
    <axis xyz="0 0 1"/>
  </joint>
  <link name="link:leg2_(2):leg2_shell_(1)">
    <visual name="link:leg2_(2):leg2_shell_(1)_visual">
      <origin xyz="0 0 0" rpy="0 0 0"/>
      <geometry name="link:leg2_(2):leg2_shell_(1)_geometry">
        <mesh filename="meshes/leg2_(2):leg2_shell_(1).stl"/>
      </geometry>
      <material name="link:leg2_(2):leg2_shell_(1)_material">
        <color rgba="0.89803922 0.91764706 0.92941176 1"/>
      </material>
    </visual>
    <collision name="link:leg2_(2):leg2_shell_(1).collision">
      <origin xyz="0 0 0" rpy="0 0 0"/>
      <geometry name="link:leg2_(2):leg2_shell_(1)_collision_geometry">
        <mesh filename="meshes/leg2_(2):leg2_shell_(1).stl"/>
      </geometry>
    </collision>
    <inertial name="link:leg2_(2):leg2_shell_(1)_inertial">
      <mass value="0.26765588"/>
      <inertia ixx="0.0011769735" iyy="0.0013888869" izz="0.00037795879" ixy="0" ixz="0" iyz="5.1336711e-05"/>
      <origin xyz="2.7794893e-06 0.0095055079 -0.10717619" rpy="0 0 0"/>
    </inertial>
  </link>
  <joint name="joint:right_hip_yaw_03" type="revolute">
    <origin xyz="0 0 -0.0566" rpy="0 0 3.1415927"/>
    <parent link="link:leg1_(1):leg1_actuator2_(2)"/>
    <child link="link:leg2_(1):leg2_shell_(1)"/>
    <limit effort="60" velocity="6.283" lower="-1.5707963" upper="1.5707963"/>
    <axis xyz="0 0 1"/>
  </joint>
  <link name="link:leg2_(1):leg2_shell_(1)">
    <visual name="link:leg2_(1):leg2_shell_(1)_visual">
      <origin xyz="0 0 0" rpy="0 0 0"/>
      <geometry name="link:leg2_(1):leg2_shell_(1)_geometry">
        <mesh filename="meshes/leg2_(1):leg2_shell_(1).stl"/>
      </geometry>
      <material name="link:leg2_(1):leg2_shell_(1)_material">
        <color rgba="0.89803922 0.91764706 0.92941176 1"/>
      </material>
    </visual>
    <collision name="link:leg2_(1):leg2_shell_(1).collision">
      <origin xyz="0 0 0" rpy="0 0 0"/>
      <geometry name="link:leg2_(1):leg2_shell_(1)_collision_geometry">
        <mesh filename="meshes/leg2_(1):leg2_shell_(1).stl"/>
      </geometry>
    </collision>
    <inertial name="link:leg2_(1):leg2_shell_(1)_inertial">
      <mass value="0.26765588"/>
      <inertia ixx="0.0011769735" iyy="0.0013888869" izz="0.00037795879" ixy="0" ixz="0" iyz="5.1336711e-05"/>
      <origin xyz="2.7794893e-06 0.0095055079 -0.10717619" rpy="0 0 0"/>
    </inertial>
  </link>
  <joint name="joint:arm3_(1):Fastened_2" type="fixed">
    <origin xyz="-0.15 0 0.0215" rpy="3.1415927 -1.5707963 0"/>
    <parent link="link:arm3_(1):arm3_shell_(1)"/>
    <child link="link:arm3_(1):arm3_actuator_(1)"/>
  </joint>
  <link name="link:arm3_(1):arm3_actuator_(1)">
    <visual name="link:arm3_(1):arm3_actuator_(1)_visual">
      <origin xyz="0 0 0" rpy="0 0 0"/>
      <geometry name="link:arm3_(1):arm3_actuator_(1)_geometry">
        <mesh filename="meshes/arm3_(1):arm3_actuator_(1).stl"/>
      </geometry>
      <material name="link:arm3_(1):arm3_actuator_(1)_material">
        <color rgba="0.79215686 0.81960784 0.93333333 1"/>
      </material>
    </visual>
    <collision name="link:arm3_(1):arm3_actuator_(1).collision">
      <origin xyz="0 0 0" rpy="0 0 0"/>
      <geometry name="link:arm3_(1):arm3_actuator_(1)_collision_geometry">
        <mesh filename="meshes/arm3_(1):arm3_actuator_(1).stl"/>
      </geometry>
    </collision>
    <inertial name="link:arm3_(1):arm3_actuator_(1)_inertial">
      <mass value="0.4"/>
      <inertia ixx="0.00018548163" iyy="0.00018548163" izz="0.00028416296" ixy="0" ixz="0" iyz="0"/>
      <origin xyz="0 0 -0.011585135" rpy="0 0 0"/>
    </inertial>
  </link>
  <joint name="joint:arm3_(1):Fastened_1" type="fixed">
    <origin xyz="-0.15 0 0.0215" rpy="3.1415927 -1.5707963 0"/>
    <parent link="link:arm3_(1):arm3_shell2_(1)"/>
    <child link="link:arm3_(1):arm3_actuator2_(2)"/>
  </joint>
  <link name="link:arm3_(1):arm3_actuator2_(2)">
    <visual name="link:arm3_(1):arm3_actuator2_(2)_visual">
      <origin xyz="0 0 0" rpy="0 0 0"/>
      <geometry name="link:arm3_(1):arm3_actuator2_(2)_geometry">
        <mesh filename="meshes/arm3_(1):arm3_actuator2_(2).stl"/>
      </geometry>
      <material name="link:arm3_(1):arm3_actuator2_(2)_material">
        <color rgba="0.79215686 0.81960784 0.93333333 1"/>
      </material>
    </visual>
    <collision name="link:arm3_(1):arm3_actuator2_(2).collision">
      <origin xyz="0 0 0" rpy="0 0 0"/>
      <geometry name="link:arm3_(1):arm3_actuator2_(2)_collision_geometry">
        <mesh filename="meshes/arm3_(1):arm3_actuator2_(2).stl"/>
      </geometry>
    </collision>
    <inertial name="link:arm3_(1):arm3_actuator2_(2)_inertial">
      <mass value="0.4"/>
      <inertia ixx="0.00018548163" iyy="0.00018548163" izz="0.00028416296" ixy="0" ixz="0" iyz="0"/>
      <origin xyz="0 0 -0.011585135" rpy="0 0 0"/>
    </inertial>
  </link>
  <joint name="joint:leg2_(2):Fastened_1" type="fixed">
    <origin xyz="0 0.013 -0.1425" rpy="-1.5707963 0 0"/>
    <parent link="link:leg2_(2):leg2_shell_(1)"/>
    <child link="link:leg2_(2):leg2_actuator_(1)"/>
  </joint>
  <link name="link:leg2_(2):leg2_actuator_(1)">
    <visual name="link:leg2_(2):leg2_actuator_(1)_visual">
      <origin xyz="0 0 0" rpy="0 0 0"/>
      <geometry name="link:leg2_(2):leg2_actuator_(1)_geometry">
        <mesh filename="meshes/leg2_(2):leg2_actuator_(1).stl"/>
      </geometry>
      <material name="link:leg2_(2):leg2_actuator_(1)_material">
        <color rgba="0.79215686 0.81960784 0.93333333 1"/>
      </material>
    </visual>
    <collision name="link:leg2_(2):leg2_actuator_(1).collision">
      <origin xyz="0 0 0" rpy="0 0 0"/>
      <geometry name="link:leg2_(2):leg2_actuator_(1)_collision_geometry">
        <mesh filename="meshes/leg2_(2):leg2_actuator_(1).stl"/>
      </geometry>
    </collision>
    <inertial name="link:leg2_(2):leg2_actuator_(1)_inertial">
      <mass value="1.5"/>
      <inertia ixx="0.0015444603" iyy="0.0015746032" izz="0.0025156575" ixy="0" ixz="0" iyz="0"/>
      <origin xyz="0 0 -0.015265182" rpy="0 0 0"/>
    </inertial>
  </link>
  <joint name="joint:leg2_(2):Fastened_2" type="fixed">
    <origin xyz="0 0.0307 -0.1425" rpy="1.5707963 0 0"/>
    <parent link="link:leg2_(2):leg2_shell_(1)"/>
    <child link="link:leg2_(2):leg2_bearing_(1)"/>
  </joint>
  <link name="link:leg2_(2):leg2_bearing_(1)">
    <visual name="link:leg2_(2):leg2_bearing_(1)_visual">
      <origin xyz="0 0 0" rpy="0 0 0"/>
      <geometry name="link:leg2_(2):leg2_bearing_(1)_geometry">
        <mesh filename="meshes/leg2_(2):leg2_bearing_(1).stl"/>
      </geometry>
      <material name="link:leg2_(2):leg2_bearing_(1)_material">
        <color rgba="0.79215686 0.81960784 0.93333333 1"/>
      </material>
    </visual>
    <collision name="link:leg2_(2):leg2_bearing_(1).collision">
      <origin xyz="0 0 0" rpy="0 0 0"/>
      <geometry name="link:leg2_(2):leg2_bearing_(1)_collision_geometry">
        <mesh filename="meshes/leg2_(2):leg2_bearing_(1).stl"/>
      </geometry>
    </collision>
    <inertial name="link:leg2_(2):leg2_bearing_(1)_inertial">
      <mass value="0.053266787"/>
      <inertia ixx="1.8136502e-05" iyy="1.8136502e-05" izz="3.5913995e-05" ixy="0" ixz="0" iyz="0"/>
      <origin xyz="0 0 -0.0035" rpy="0 0 0"/>
    </inertial>
  </link>
  <joint name="joint:leg2_(1):Fastened_1" type="fixed">
    <origin xyz="0 0.013 -0.1425" rpy="-1.5707963 0 0"/>
    <parent link="link:leg2_(1):leg2_shell_(1)"/>
    <child link="link:leg2_(1):leg2_actuator_(1)"/>
  </joint>
  <link name="link:leg2_(1):leg2_actuator_(1)">
    <visual name="link:leg2_(1):leg2_actuator_(1)_visual">
      <origin xyz="0 0 0" rpy="0 0 0"/>
      <geometry name="link:leg2_(1):leg2_actuator_(1)_geometry">
        <mesh filename="meshes/leg2_(1):leg2_actuator_(1).stl"/>
      </geometry>
      <material name="link:leg2_(1):leg2_actuator_(1)_material">
        <color rgba="0.79215686 0.81960784 0.93333333 1"/>
      </material>
    </visual>
    <collision name="link:leg2_(1):leg2_actuator_(1).collision">
      <origin xyz="0 0 0" rpy="0 0 0"/>
      <geometry name="link:leg2_(1):leg2_actuator_(1)_collision_geometry">
        <mesh filename="meshes/leg2_(1):leg2_actuator_(1).stl"/>
      </geometry>
    </collision>
    <inertial name="link:leg2_(1):leg2_actuator_(1)_inertial">
      <mass value="1.5"/>
      <inertia ixx="0.0015444603" iyy="0.0015746032" izz="0.0025156575" ixy="0" ixz="0" iyz="0"/>
      <origin xyz="0 0 -0.015265182" rpy="0 0 0"/>
    </inertial>
  </link>
  <joint name="joint:leg2_(1):Fastened_2" type="fixed">
    <origin xyz="0 0.0307 -0.1425" rpy="1.5707963 0 0"/>
    <parent link="link:leg2_(1):leg2_shell_(1)"/>
    <child link="link:leg2_(1):leg2_bearing_(1)"/>
  </joint>
  <link name="link:leg2_(1):leg2_bearing_(1)">
    <visual name="link:leg2_(1):leg2_bearing_(1)_visual">
      <origin xyz="0 0 0" rpy="0 0 0"/>
      <geometry name="link:leg2_(1):leg2_bearing_(1)_geometry">
        <mesh filename="meshes/leg2_(1):leg2_bearing_(1).stl"/>
      </geometry>
      <material name="link:leg2_(1):leg2_bearing_(1)_material">
        <color rgba="0.79215686 0.81960784 0.93333333 1"/>
      </material>
    </visual>
    <collision name="link:leg2_(1):leg2_bearing_(1).collision">
      <origin xyz="0 0 0" rpy="0 0 0"/>
      <geometry name="link:leg2_(1):leg2_bearing_(1)_collision_geometry">
        <mesh filename="meshes/leg2_(1):leg2_bearing_(1).stl"/>
      </geometry>
    </collision>
    <inertial name="link:leg2_(1):leg2_bearing_(1)_inertial">
      <mass value="0.053266787"/>
      <inertia ixx="1.8136502e-05" iyy="1.8136502e-05" izz="3.5913995e-05" ixy="0" ixz="0" iyz="0"/>
      <origin xyz="0 0 -0.0035" rpy="0 0 0"/>
    </inertial>
  </link>
  <joint name="joint:left_wrist_02" type="revolute">
    <origin xyz="0 0 -0.0315" rpy="0 0 1.5707963"/>
    <parent link="link:arm3_(1):arm3_actuator_(1)"/>
    <child link="link:Hand_(2):hand_shell_(1)"/>
    <limit effort="17" velocity="12.566" lower="-3.1415927" upper="3.1415927"/>
    <axis xyz="0 0 1"/>
  </joint>
  <link name="link:Hand_(2):hand_shell_(1)">
    <visual name="link:Hand_(2):hand_shell_(1)_visual">
      <origin xyz="0 0 0" rpy="0 0 0"/>
      <geometry name="link:Hand_(2):hand_shell_(1)_geometry">
        <mesh filename="meshes/Hand_(2):hand_shell_(1).stl"/>
      </geometry>
      <material name="link:Hand_(2):hand_shell_(1)_material">
        <color rgba="0.89803922 0.91764706 0.92941176 1"/>
      </material>
    </visual>
    <collision name="link:Hand_(2):hand_shell_(1).collision">
      <origin xyz="0 0 0" rpy="0 0 0"/>
      <geometry name="link:Hand_(2):hand_shell_(1)_collision_geometry">
        <mesh filename="meshes/Hand_(2):hand_shell_(1).stl"/>
      </geometry>
    </collision>
    <inertial name="link:Hand_(2):hand_shell_(1)_inertial">
      <mass value="0.27195252"/>
      <inertia ixx="0.00035022716" iyy="0.00081829423" izz="0.00071510642" ixy="0" ixz="-1.9425041e-05" iyz="0"/>
      <origin xyz="0.0020675017 0.00015900006 -0.067885428" rpy="0 0 0"/>
    </inertial>
  </link>
  <joint name="joint:right_wrist_02" type="revolute">
    <origin xyz="0 0 -0.0315" rpy="0 0 -1.5707963"/>
    <parent link="link:arm3_(1):arm3_actuator2_(2)"/>
    <child link="link:Hand_(1):hand_shell_(1)"/>
    <limit effort="17" velocity="12.566" lower="-3.1415927" upper="3.1415927"/>
    <axis xyz="0 0 1"/>
  </joint>
  <link name="link:Hand_(1):hand_shell_(1)">
    <visual name="link:Hand_(1):hand_shell_(1)_visual">
      <origin xyz="0 0 0" rpy="0 0 0"/>
      <geometry name="link:Hand_(1):hand_shell_(1)_geometry">
        <mesh filename="meshes/Hand_(1):hand_shell_(1).stl"/>
      </geometry>
      <material name="link:Hand_(1):hand_shell_(1)_material">
        <color rgba="0.89803922 0.91764706 0.92941176 1"/>
      </material>
    </visual>
    <collision name="link:Hand_(1):hand_shell_(1).collision">
      <origin xyz="0 0 0" rpy="0 0 0"/>
      <geometry name="link:Hand_(1):hand_shell_(1)_collision_geometry">
        <mesh filename="meshes/Hand_(1):hand_shell_(1).stl"/>
      </geometry>
    </collision>
    <inertial name="link:Hand_(1):hand_shell_(1)_inertial">
      <mass value="0.27195252"/>
      <inertia ixx="0.00035022716" iyy="0.00081829423" izz="0.00071510642" ixy="0" ixz="-1.9425041e-05" iyz="0"/>
      <origin xyz="0.0020675017 0.00015900006 -0.067885428" rpy="0 0 0"/>
    </inertial>
  </link>
  <joint name="joint:left_knee_04" type="revolute">
    <origin xyz="0 0 -0.039" rpy="3.1415927 0 0"/>
    <parent link="link:leg2_(2):leg2_actuator_(1)"/>
    <child link="link:leg3_(1):leg3_shell1_(1)"/>
    <limit effort="120" velocity="6.283" lower="0" upper="2.0943951"/>
    <axis xyz="0 0 -1"/>
  </joint>
  <link name="link:leg3_(1):leg3_shell1_(1)">
    <visual name="link:leg3_(1):leg3_shell1_(1)_visual">
      <origin xyz="0 0 0" rpy="0 0 0"/>
      <geometry name="link:leg3_(1):leg3_shell1_(1)_geometry">
        <mesh filename="meshes/leg3_(1):leg3_shell1_(1).stl"/>
      </geometry>
      <material name="link:leg3_(1):leg3_shell1_(1)_material">
        <color rgba="0.89803922 0.91764706 0.92941176 1"/>
      </material>
    </visual>
    <collision name="link:leg3_(1):leg3_shell1_(1).collision">
      <origin xyz="0 0 0" rpy="0 0 0"/>
      <geometry name="link:leg3_(1):leg3_shell1_(1)_collision_geometry">
        <mesh filename="meshes/leg3_(1):leg3_shell1_(1).stl"/>
      </geometry>
    </collision>
    <inertial name="link:leg3_(1):leg3_shell1_(1)_inertial">
      <mass value="0.56425494"/>
      <inertia ixx="0.0046192307" iyy="0.00044138531" izz="0.0047994727" ixy="5.3501388e-05" ixz="-5.8832004e-06" iyz="-0.00046247377"/>
      <origin xyz="0.0019513347 -0.12751752 -0.016278296" rpy="0 0 0"/>
    </inertial>
  </link>
  <joint name="joint:right_knee_04" type="revolute">
    <origin xyz="0 0 -0.039" rpy="3.1415927 0 0"/>
    <parent link="link:leg2_(1):leg2_actuator_(1)"/>
    <child link="link:leg3_(1):leg3_shell11_(2)"/>
    <limit effort="120" velocity="6.283" lower="-2.0943951" upper="0"/>
    <axis xyz="0 0 -1"/>
  </joint>
  <link name="link:leg3_(1):leg3_shell11_(2)">
    <visual name="link:leg3_(1):leg3_shell11_(2)_visual">
      <origin xyz="0 0 0" rpy="0 0 0"/>
      <geometry name="link:leg3_(1):leg3_shell11_(2)_geometry">
        <mesh filename="meshes/leg3_(1):leg3_shell11_(2).stl"/>
      </geometry>
      <material name="link:leg3_(1):leg3_shell11_(2)_material">
        <color rgba="0.89803922 0.91764706 0.92941176 1"/>
      </material>
    </visual>
    <collision name="link:leg3_(1):leg3_shell11_(2).collision">
      <origin xyz="0 0 0" rpy="0 0 0"/>
      <geometry name="link:leg3_(1):leg3_shell11_(2)_collision_geometry">
        <mesh filename="meshes/leg3_(1):leg3_shell11_(2).stl"/>
      </geometry>
    </collision>
    <inertial name="link:leg3_(1):leg3_shell11_(2)_inertial">
      <mass value="0.56426179"/>
      <inertia ixx="0.0046192506" iyy="0.00044138907" izz="0.0047994941" ixy="-5.3508505e-05" ixz="5.8839789e-06" iyz="-0.00046247435"/>
      <origin xyz="-0.001951448 -0.12751815 -0.016278155" rpy="0 0 0"/>
    </inertial>
  </link>
  <joint name="joint:Hand_(2):Fastened_1" type="fixed">
    <origin xyz="0 0 -0.062" rpy="3.1415927 0 0"/>
    <parent link="link:Hand_(2):hand_shell_(1)"/>
    <child link="link:Hand_(2):hand_actuator_(1)"/>
  </joint>
  <link name="link:Hand_(2):hand_actuator_(1)">
    <visual name="link:Hand_(2):hand_actuator_(1)_visual">
      <origin xyz="0 0 0" rpy="0 0 0"/>
      <geometry name="link:Hand_(2):hand_actuator_(1)_geometry">
        <mesh filename="meshes/Hand_(2):hand_actuator_(1).stl"/>
      </geometry>
      <material name="link:Hand_(2):hand_actuator_(1)_material">
        <color rgba="0.79215686 0.81960784 0.93333333 1"/>
      </material>
    </visual>
    <collision name="link:Hand_(2):hand_actuator_(1).collision">
      <origin xyz="0 0 0" rpy="0 0 0"/>
      <geometry name="link:Hand_(2):hand_actuator_(1)_collision_geometry">
        <mesh filename="meshes/Hand_(2):hand_actuator_(1).stl"/>
      </geometry>
    </collision>
    <inertial name="link:Hand_(2):hand_actuator_(1)_inertial">
      <mass value="0.31"/>
      <inertia ixx="0.00013088778" iyy="0.00013088778" izz="0.00012532318" ixy="0" ixz="0" iyz="0"/>
      <origin xyz="0 0 -0.025309195" rpy="0 0 0"/>
    </inertial>
  </link>
  <joint name="joint:Hand_(2):Fastened_2" type="fixed">
    <origin xyz="0 -0.029727738 -0.107" rpy="3.1415927 -1.5707963 0"/>
    <parent link="link:Hand_(2):hand_shell_(1)"/>
    <child link="link:Hand_(2):hand_shell2_(1)"/>
  </joint>
  <link name="link:Hand_(2):hand_shell2_(1)">
    <visual name="link:Hand_(2):hand_shell2_(1)_visual">
      <origin xyz="0 0 0" rpy="0 0 0"/>
      <geometry name="link:Hand_(2):hand_shell2_(1)_geometry">
        <mesh filename="meshes/Hand_(2):hand_shell2_(1).stl"/>
      </geometry>
      <material name="link:Hand_(2):hand_shell2_(1)_material">
        <color rgba="0.89803922 0.91764706 0.92941176 1"/>
      </material>
    </visual>
    <collision name="link:Hand_(2):hand_shell2_(1).collision">
      <origin xyz="0 0 0" rpy="0 0 0"/>
      <geometry name="link:Hand_(2):hand_shell2_(1)_collision_geometry">
        <mesh filename="meshes/Hand_(2):hand_shell2_(1).stl"/>
      </geometry>
    </collision>
    <inertial name="link:Hand_(2):hand_shell2_(1)_inertial">
      <mass value="0.03852471"/>
      <inertia ixx="8.1216505e-05" iyy="6.8941484e-05" izz="1.2300663e-05" ixy="0" ixz="0" iyz="2.3790915e-06"/>
      <origin xyz="-0.00099449627 -0.030012003 0" rpy="0 0 0"/>
    </inertial>
  </link>
  <joint name="joint:Hand_(1):Fastened_1" type="fixed">
    <origin xyz="0 0 -0.062" rpy="3.1415927 0 0"/>
    <parent link="link:Hand_(1):hand_shell_(1)"/>
    <child link="link:Hand_(1):hand_actuator_(1)"/>
  </joint>
  <link name="link:Hand_(1):hand_actuator_(1)">
    <visual name="link:Hand_(1):hand_actuator_(1)_visual">
      <origin xyz="0 0 0" rpy="0 0 0"/>
      <geometry name="link:Hand_(1):hand_actuator_(1)_geometry">
        <mesh filename="meshes/Hand_(1):hand_actuator_(1).stl"/>
      </geometry>
      <material name="link:Hand_(1):hand_actuator_(1)_material">
        <color rgba="0.79215686 0.81960784 0.93333333 1"/>
      </material>
    </visual>
    <collision name="link:Hand_(1):hand_actuator_(1).collision">
      <origin xyz="0 0 0" rpy="0 0 0"/>
      <geometry name="link:Hand_(1):hand_actuator_(1)_collision_geometry">
        <mesh filename="meshes/Hand_(1):hand_actuator_(1).stl"/>
      </geometry>
    </collision>
    <inertial name="link:Hand_(1):hand_actuator_(1)_inertial">
      <mass value="0.31"/>
      <inertia ixx="0.00013088778" iyy="0.00013088778" izz="0.00012532318" ixy="0" ixz="0" iyz="0"/>
      <origin xyz="0 0 -0.025309195" rpy="0 0 0"/>
    </inertial>
  </link>
  <joint name="joint:Hand_(1):Fastened_2" type="fixed">
    <origin xyz="0 -0.029727738 -0.107" rpy="3.1415927 -1.5707963 0"/>
    <parent link="link:Hand_(1):hand_shell_(1)"/>
    <child link="link:Hand_(1):hand_shell2_(1)"/>
  </joint>
  <link name="link:Hand_(1):hand_shell2_(1)">
    <visual name="link:Hand_(1):hand_shell2_(1)_visual">
      <origin xyz="0 0 0" rpy="0 0 0"/>
      <geometry name="link:Hand_(1):hand_shell2_(1)_geometry">
        <mesh filename="meshes/Hand_(1):hand_shell2_(1).stl"/>
      </geometry>
      <material name="link:Hand_(1):hand_shell2_(1)_material">
        <color rgba="0.89803922 0.91764706 0.92941176 1"/>
      </material>
    </visual>
    <collision name="link:Hand_(1):hand_shell2_(1).collision">
      <origin xyz="0 0 0" rpy="0 0 0"/>
      <geometry name="link:Hand_(1):hand_shell2_(1)_collision_geometry">
        <mesh filename="meshes/Hand_(1):hand_shell2_(1).stl"/>
      </geometry>
    </collision>
    <inertial name="link:Hand_(1):hand_shell2_(1)_inertial">
      <mass value="0.03852471"/>
      <inertia ixx="8.1216505e-05" iyy="6.8941484e-05" izz="1.2300663e-05" ixy="0" ixz="0" iyz="2.3790915e-06"/>
      <origin xyz="-0.00099449627 -0.030012003 0" rpy="0 0 0"/>
    </inertial>
  </link>
  <joint name="joint:leg3_(1):Fastened_3" type="fixed">
    <origin xyz="0 -0.11 -0.0274" rpy="0 0 0"/>
    <parent link="link:leg3_(1):leg3_shell1_(1)"/>
    <child link="link:leg3_(1):leg3_actuator_(1)"/>
  </joint>
  <link name="link:leg3_(1):leg3_actuator_(1)">
    <visual name="link:leg3_(1):leg3_actuator_(1)_visual">
      <origin xyz="0 0 0" rpy="0 0 0"/>
      <geometry name="link:leg3_(1):leg3_actuator_(1)_geometry">
        <mesh filename="meshes/leg3_(1):leg3_actuator_(1).stl"/>
      </geometry>
      <material name="link:leg3_(1):leg3_actuator_(1)_material">
        <color rgba="0.79215686 0.81960784 0.93333333 1"/>
      </material>
    </visual>
    <collision name="link:leg3_(1):leg3_actuator_(1).collision">
      <origin xyz="0 0 0" rpy="0 0 0"/>
      <geometry name="link:leg3_(1):leg3_actuator_(1)_collision_geometry">
        <mesh filename="meshes/leg3_(1):leg3_actuator_(1).stl"/>
      </geometry>
    </collision>
    <inertial name="link:leg3_(1):leg3_actuator_(1)_inertial">
      <mass value="0.4"/>
      <inertia ixx="0.00018548163" iyy="0.00018548163" izz="0.00028416296" ixy="0" ixz="0" iyz="0"/>
      <origin xyz="0 0 -0.016414865" rpy="0 0 0"/>
    </inertial>
  </link>
  <joint name="joint:leg3_(1):Fastened_5" type="fixed">
    <origin xyz="0 -0.11 0.0075" rpy="3.1415927 0 0"/>
    <parent link="link:leg3_(1):leg3_shell1_(1)"/>
    <child link="link:leg3_(1):leg3_shell3_(1)"/>
  </joint>
  <link name="link:leg3_(1):leg3_shell3_(1)">
    <visual name="link:leg3_(1):leg3_shell3_(1)_visual">
      <origin xyz="0 0 0" rpy="0 0 0"/>
      <geometry name="link:leg3_(1):leg3_shell3_(1)_geometry">
        <mesh filename="meshes/leg3_(1):leg3_shell3_(1).stl"/>
      </geometry>
      <material name="link:leg3_(1):leg3_shell3_(1)_material">
        <color rgba="0.89803922 0.91764706 0.92941176 1"/>
      </material>
    </visual>
    <collision name="link:leg3_(1):leg3_shell3_(1).collision">
      <origin xyz="0 0 0" rpy="0 0 0"/>
      <geometry name="link:leg3_(1):leg3_shell3_(1)_collision_geometry">
        <mesh filename="meshes/leg3_(1):leg3_shell3_(1).stl"/>
      </geometry>
    </collision>
    <inertial name="link:leg3_(1):leg3_shell3_(1)_inertial">
      <mass value="0.14570047"/>
      <inertia ixx="0.00063417533" iyy="5.6135452e-05" izz="0.00068889977" ixy="-3.6668809e-06" ixz="0" iyz="-6.4804723e-06"/>
      <origin xyz="0.00080671853 0.094588499 0.0006232858" rpy="0 0 0"/>
    </inertial>
  </link>
  <joint name="joint:right_ankle_02" type="revolute">
    <origin xyz="0 -0.3 -0.0345" rpy="3.1415927 0 3.1415927"/>
    <parent link="link:leg3_(1):leg3_shell11_(2)"/>
    <child link="link:foot_flat_(1):foot3_(2)"/>
    <limit effort="17" velocity="12.566" lower="-0.6981317" upper="0.6981317"/>
    <axis xyz="0 0 -1"/>
  </joint>
  <link name="link:foot_flat_(1):foot3_(2)">
    <visual name="link:foot_flat_(1):foot3_(2)_visual">
      <origin xyz="0 0 0" rpy="0 0 0"/>
      <geometry name="link:foot_flat_(1):foot3_(2)_geometry">
        <mesh filename="meshes/foot_flat_(1):foot3_(2).stl"/>
      </geometry>
      <material name="link:foot_flat_(1):foot3_(2)_material">
        <color rgba="0.89803922 0.91764706 0.92941176 1"/>
      </material>
    </visual>
    <collision name="link:foot_flat_(1):foot3_(2).collision">
      <origin xyz="0 0 0" rpy="0 0 0"/>
      <geometry name="link:foot_flat_(1):foot3_(2)_collision_geometry">
        <mesh filename="meshes/foot_flat_(1):foot3_(2).stl"/>
      </geometry>
    </collision>
    <inertial name="link:foot_flat_(1):foot3_(2)_inertial">
      <mass value="0.3129012"/>
      <inertia ixx="0.00015598551" iyy="0.0009939881" izz="0.00089276253" ixy="1.5359534e-05" ixz="1.580541e-05" iyz="-2.6026885e-06"/>
      <origin xyz="0.014045581 -0.013644469 -0.023401374" rpy="0 0 0"/>
    </inertial>
  </link>
  <joint name="joint:leg3_(1):Fastened_2" type="fixed">
    <origin xyz="0 -0.11 -0.0274" rpy="0 0 3.1415927"/>
    <parent link="link:leg3_(1):leg3_shell11_(2)"/>
    <child link="link:leg3_(1):leg3_actuator2_(2)"/>
  </joint>
  <link name="link:leg3_(1):leg3_actuator2_(2)">
    <visual name="link:leg3_(1):leg3_actuator2_(2)_visual">
      <origin xyz="0 0 0" rpy="0 0 0"/>
      <geometry name="link:leg3_(1):leg3_actuator2_(2)_geometry">
        <mesh filename="meshes/leg3_(1):leg3_actuator2_(2).stl"/>
      </geometry>
      <material name="link:leg3_(1):leg3_actuator2_(2)_material">
        <color rgba="0.79215686 0.81960784 0.93333333 1"/>
      </material>
    </visual>
    <collision name="link:leg3_(1):leg3_actuator2_(2).collision">
      <origin xyz="0 0 0" rpy="0 0 0"/>
      <geometry name="link:leg3_(1):leg3_actuator2_(2)_collision_geometry">
        <mesh filename="meshes/leg3_(1):leg3_actuator2_(2).stl"/>
      </geometry>
    </collision>
    <inertial name="link:leg3_(1):leg3_actuator2_(2)_inertial">
      <mass value="0.4"/>
      <inertia ixx="0.00018548163" iyy="0.00018548163" izz="0.00028416296" ixy="0" ixz="0" iyz="0"/>
      <origin xyz="0 0 -0.016414865" rpy="0 0 0"/>
    </inertial>
  </link>
  <joint name="joint:leg3_(1):Fastened_4" type="fixed">
    <origin xyz="0 -0.11 0.0075" rpy="3.1415927 0 3.1415927"/>
    <parent link="link:leg3_(1):leg3_shell11_(2)"/>
    <child link="link:leg3_(1):leg3_shell33_(2)"/>
  </joint>
  <link name="link:leg3_(1):leg3_shell33_(2)">
    <visual name="link:leg3_(1):leg3_shell33_(2)_visual">
      <origin xyz="0 0 0" rpy="0 0 0"/>
      <geometry name="link:leg3_(1):leg3_shell33_(2)_geometry">
        <mesh filename="meshes/leg3_(1):leg3_shell33_(2).stl"/>
      </geometry>
      <material name="link:leg3_(1):leg3_shell33_(2)_material">
        <color rgba="0.89803922 0.91764706 0.92941176 1"/>
      </material>
    </visual>
    <collision name="link:leg3_(1):leg3_shell33_(2).collision">
      <origin xyz="0 0 0" rpy="0 0 0"/>
      <geometry name="link:leg3_(1):leg3_shell33_(2)_collision_geometry">
        <mesh filename="meshes/leg3_(1):leg3_shell33_(2).stl"/>
      </geometry>
    </collision>
    <inertial name="link:leg3_(1):leg3_shell33_(2)_inertial">
      <mass value="0.14569982"/>
      <inertia ixx="0.00063417464" iyy="5.6135157e-05" izz="0.0006888988" ixy="3.6666303e-06" ixz="0" iyz="6.4804451e-06"/>
      <origin xyz="0.00080661127 -0.094588414 0.00062328876" rpy="0 0 0"/>
    </inertial>
  </link>
  <joint name="joint:Hand_(2):Fastened_3" type="fixed">
    <origin xyz="-0.0010182322 -0.042356503 -0.0545" rpy="3.1415927 0 0"/>
    <parent link="link:Hand_(2):hand_shell2_(1)"/>
    <child link="link:Hand_(2):hand_part2_(1)"/>
  </joint>
  <link name="link:Hand_(2):hand_part2_(1)">
    <visual name="link:Hand_(2):hand_part2_(1)_visual">
      <origin xyz="0 0 0" rpy="0 0 0"/>
      <geometry name="link:Hand_(2):hand_part2_(1)_geometry">
        <mesh filename="meshes/Hand_(2):hand_part2_(1).stl"/>
      </geometry>
      <material name="link:Hand_(2):hand_part2_(1)_material">
        <color rgba="0.79215686 0.81960784 0.93333333 1"/>
      </material>
    </visual>
    <collision name="link:Hand_(2):hand_part2_(1).collision">
      <origin xyz="0 0 0" rpy="0 0 0"/>
      <geometry name="link:Hand_(2):hand_part2_(1)_collision_geometry">
        <mesh filename="meshes/Hand_(2):hand_part2_(1).stl"/>
      </geometry>
    </collision>
    <inertial name="link:Hand_(2):hand_part2_(1)_inertial">
      <mass value="0.022065392"/>
      <inertia ixx="2.8604312e-06" iyy="6.0887761e-06" izz="8.0150705e-06" ixy="-1.5779589e-06" ixz="0" iyz="0"/>
      <origin xyz="-0.021080169 -0.008838172 -0.015263073" rpy="0 0 0"/>
    </inertial>
  </link>
  <joint name="joint:Hand_(2):Fastened_5" type="fixed">
    <origin xyz="-0.0010182322 -0.017663497 0.0545" rpy="3.1415927 0 0"/>
    <parent link="link:Hand_(2):hand_shell2_(1)"/>
    <child link="link:Hand_(2):hand_part_(1)"/>
  </joint>
  <link name="link:Hand_(2):hand_part_(1)">
    <visual name="link:Hand_(2):hand_part_(1)_visual">
      <origin xyz="0 0 0" rpy="0 0 0"/>
      <geometry name="link:Hand_(2):hand_part_(1)_geometry">
        <mesh filename="meshes/Hand_(2):hand_part_(1).stl"/>
      </geometry>
      <material name="link:Hand_(2):hand_part_(1)_material">
        <color rgba="0.79215686 0.81960784 0.93333333 1"/>
      </material>
    </visual>
    <collision name="link:Hand_(2):hand_part_(1).collision">
      <origin xyz="0 0 0" rpy="0 0 0"/>
      <geometry name="link:Hand_(2):hand_part_(1)_collision_geometry">
        <mesh filename="meshes/Hand_(2):hand_part_(1).stl"/>
      </geometry>
    </collision>
    <inertial name="link:Hand_(2):hand_part_(1)_inertial">
      <mass value="0.022065392"/>
      <inertia ixx="2.8604312e-06" iyy="6.0887761e-06" izz="8.0150705e-06" ixy="1.5779589e-06" ixz="0" iyz="0"/>
      <origin xyz="-0.021080169 0.008838172 0.015263073" rpy="0 0 0"/>
    </inertial>
  </link>
  <joint name="joint:Hand_(1):Fastened_3" type="fixed">
    <origin xyz="-0.0010182322 -0.042356503 -0.0545" rpy="3.1415927 0 0"/>
    <parent link="link:Hand_(1):hand_shell2_(1)"/>
    <child link="link:Hand_(1):hand_part2_(1)"/>
  </joint>
  <link name="link:Hand_(1):hand_part2_(1)">
    <visual name="link:Hand_(1):hand_part2_(1)_visual">
      <origin xyz="0 0 0" rpy="0 0 0"/>
      <geometry name="link:Hand_(1):hand_part2_(1)_geometry">
        <mesh filename="meshes/Hand_(1):hand_part2_(1).stl"/>
      </geometry>
      <material name="link:Hand_(1):hand_part2_(1)_material">
        <color rgba="0.79215686 0.81960784 0.93333333 1"/>
      </material>
    </visual>
    <collision name="link:Hand_(1):hand_part2_(1).collision">
      <origin xyz="0 0 0" rpy="0 0 0"/>
      <geometry name="link:Hand_(1):hand_part2_(1)_collision_geometry">
        <mesh filename="meshes/Hand_(1):hand_part2_(1).stl"/>
      </geometry>
    </collision>
    <inertial name="link:Hand_(1):hand_part2_(1)_inertial">
      <mass value="0.022065392"/>
      <inertia ixx="2.8604312e-06" iyy="6.0887761e-06" izz="8.0150705e-06" ixy="-1.5779589e-06" ixz="0" iyz="0"/>
      <origin xyz="-0.021080169 -0.008838172 -0.015263073" rpy="0 0 0"/>
    </inertial>
  </link>
  <joint name="joint:Hand_(1):Fastened_5" type="fixed">
    <origin xyz="-0.0010182322 -0.017663497 0.0545" rpy="3.1415927 0 0"/>
    <parent link="link:Hand_(1):hand_shell2_(1)"/>
    <child link="link:Hand_(1):hand_part_(1)"/>
  </joint>
  <link name="link:Hand_(1):hand_part_(1)">
    <visual name="link:Hand_(1):hand_part_(1)_visual">
      <origin xyz="0 0 0" rpy="0 0 0"/>
      <geometry name="link:Hand_(1):hand_part_(1)_geometry">
        <mesh filename="meshes/Hand_(1):hand_part_(1).stl"/>
      </geometry>
      <material name="link:Hand_(1):hand_part_(1)_material">
        <color rgba="0.79215686 0.81960784 0.93333333 1"/>
      </material>
    </visual>
    <collision name="link:Hand_(1):hand_part_(1).collision">
      <origin xyz="0 0 0" rpy="0 0 0"/>
      <geometry name="link:Hand_(1):hand_part_(1)_collision_geometry">
        <mesh filename="meshes/Hand_(1):hand_part_(1).stl"/>
      </geometry>
    </collision>
    <inertial name="link:Hand_(1):hand_part_(1)_inertial">
      <mass value="0.022065392"/>
      <inertia ixx="2.8604312e-06" iyy="6.0887761e-06" izz="8.0150705e-06" ixy="1.5779589e-06" ixz="0" iyz="0"/>
      <origin xyz="-0.021080169 0.008838172 0.015263073" rpy="0 0 0"/>
    </inertial>
  </link>
  <joint name="joint:left_ankle_02" type="revolute">
    <origin xyz="0 0.19 -0.001" rpy="3.1415927 0 0"/>
    <parent link="link:leg3_(1):leg3_shell3_(1)"/>
    <child link="link:foot_flat_(1):foot1_(1)"/>
    <limit effort="17" velocity="12.566" lower="-0.6981317" upper="0.6981317"/>
    <axis xyz="0 0 -1"/>
  </joint>
  <link name="link:foot_flat_(1):foot1_(1)">
    <visual name="link:foot_flat_(1):foot1_(1)_visual">
      <origin xyz="0 0 0" rpy="0 0 0"/>
      <geometry name="link:foot_flat_(1):foot1_(1)_geometry">
        <mesh filename="meshes/foot_flat_(1):foot1_(1).stl"/>
      </geometry>
      <material name="link:foot_flat_(1):foot1_(1)_material">
        <color rgba="0.89803922 0.91764706 0.92941176 1"/>
      </material>
    </visual>
    <collision name="link:foot_flat_(1):foot1_(1).collision">
      <origin xyz="0 0 0" rpy="0 0 0"/>
      <geometry name="link:foot_flat_(1):foot1_(1)_collision_geometry">
        <mesh filename="meshes/foot_flat_(1):foot1_(1).stl"/>
      </geometry>
    </collision>
    <inertial name="link:foot_flat_(1):foot1_(1)_inertial">
      <mass value="0.31290138"/>
      <inertia ixx="0.0001559855" iyy="0.00099398838" izz="0.00089276282" ixy="1.5359606e-05" ixz="-1.580541e-05" iyz="2.6026876e-06"/>
      <origin xyz="0.014045559 -0.013644464 -0.019598625" rpy="0 0 0"/>
    </inertial>
  </link>
  <joint name="joint:foot_flat_(1):Fastened_2" type="fixed">
    <origin xyz="0.0325 -0.015 -0.0445" rpy="-1.5707963 0 0"/>
    <parent link="link:foot_flat_(1):foot3_(2)"/>
    <child link="link:foot_flat_(1):foot4_(1)"/>
  </joint>
  <link name="link:foot_flat_(1):foot4_(1)">
    <visual name="link:foot_flat_(1):foot4_(1)_visual">
      <origin xyz="0 0 0" rpy="0 0 0"/>
      <geometry name="link:foot_flat_(1):foot4_(1)_geometry">
        <mesh filename="meshes/foot_flat_(1):foot4_(1).stl"/>
      </geometry>
      <material name="link:foot_flat_(1):foot4_(1)_material">
        <color rgba="0.79215686 0.81960784 0.93333333 1"/>
      </material>
    </visual>
    <collision name="link:foot_flat_(1):foot4_(1).collision">
      <origin xyz="0 0 0" rpy="0 0 0"/>
      <geometry name="link:foot_flat_(1):foot4_(1)_collision_geometry">
        <mesh filename="meshes/foot_flat_(1):foot4_(1).stl"/>
      </geometry>
    </collision>
    <inertial name="link:foot_flat_(1):foot4_(1)_inertial">
      <mass value="0.26918988"/>
      <inertia ixx="0.00010525807" iyy="0.0010723113" izz="0.0011580688" ixy="-1.6096967e-05" ixz="-4.1181427e-06" iyz="0"/>
      <origin xyz="-0.0026596486 -0.020401479 -0.011131125" rpy="0 0 0"/>
    </inertial>
  </link>
  <joint name="joint:Hand_(2):Fastened_6" type="fixed">
    <origin xyz="-0.05 -0.0125 -0.0125" rpy="3.1415927 0 0"/>
    <parent link="link:Hand_(2):hand_part2_(1)"/>
    <child link="link:Hand_(2):hand_umi2_(1)"/>
  </joint>
  <link name="link:Hand_(2):hand_umi2_(1)">
    <visual name="link:Hand_(2):hand_umi2_(1)_visual">
      <origin xyz="0 0 0" rpy="0 0 0"/>
      <geometry name="link:Hand_(2):hand_umi2_(1)_geometry">
        <mesh filename="meshes/Hand_(2):hand_umi2_(1).stl"/>
      </geometry>
      <material name="link:Hand_(2):hand_umi2_(1)_material">
        <color rgba="0.79215686 0.81960784 0.93333333 1"/>
      </material>
    </visual>
    <collision name="link:Hand_(2):hand_umi2_(1).collision">
      <origin xyz="0 0 0" rpy="0 0 0"/>
      <geometry name="link:Hand_(2):hand_umi2_(1)_collision_geometry">
        <mesh filename="meshes/Hand_(2):hand_umi2_(1).stl"/>
      </geometry>
    </collision>
    <inertial name="link:Hand_(2):hand_umi2_(1)_inertial">
      <mass value="0.064227671"/>
      <inertia ixx="1.6527818e-05" iyy="6.0431617e-05" izz="6.1915193e-05" ixy="0" ixz="6.1464183e-06" iyz="0"/>
      <origin xyz="0.0061009097 0.00058732212 -0.0021018821" rpy="0 0 0"/>
    </inertial>
  </link>
  <joint name="joint:Hand_(2):Fastened_4" type="fixed">
    <origin xyz="-0.05 0.0125 0.0125" rpy="0 0 0"/>
    <parent link="link:Hand_(2):hand_part_(1)"/>
    <child link="link:Hand_(2):hand_umi_(1)"/>
  </joint>
  <link name="link:Hand_(2):hand_umi_(1)">
    <visual name="link:Hand_(2):hand_umi_(1)_visual">
      <origin xyz="0 0 0" rpy="0 0 0"/>
      <geometry name="link:Hand_(2):hand_umi_(1)_geometry">
        <mesh filename="meshes/Hand_(2):hand_umi_(1).stl"/>
      </geometry>
      <material name="link:Hand_(2):hand_umi_(1)_material">
        <color rgba="0.79215686 0.81960784 0.93333333 1"/>
      </material>
    </visual>
    <collision name="link:Hand_(2):hand_umi_(1).collision">
      <origin xyz="0 0 0" rpy="0 0 0"/>
      <geometry name="link:Hand_(2):hand_umi_(1)_collision_geometry">
        <mesh filename="meshes/Hand_(2):hand_umi_(1).stl"/>
      </geometry>
    </collision>
    <inertial name="link:Hand_(2):hand_umi_(1)_inertial">
      <mass value="0.064227671"/>
      <inertia ixx="1.6527818e-05" iyy="6.0431617e-05" izz="6.1915193e-05" ixy="0" ixz="6.1464183e-06" iyz="0"/>
      <origin xyz="0.0061009097 0.00058732212 -0.0021018821" rpy="0 0 0"/>
    </inertial>
  </link>
  <joint name="joint:Hand_(1):Fastened_6" type="fixed">
    <origin xyz="-0.05 -0.0125 -0.0125" rpy="3.1415927 0 0"/>
    <parent link="link:Hand_(1):hand_part2_(1)"/>
    <child link="link:Hand_(1):hand_umi2_(1)"/>
  </joint>
  <link name="link:Hand_(1):hand_umi2_(1)">
    <visual name="link:Hand_(1):hand_umi2_(1)_visual">
      <origin xyz="0 0 0" rpy="0 0 0"/>
      <geometry name="link:Hand_(1):hand_umi2_(1)_geometry">
        <mesh filename="meshes/Hand_(1):hand_umi2_(1).stl"/>
      </geometry>
      <material name="link:Hand_(1):hand_umi2_(1)_material">
        <color rgba="0.79215686 0.81960784 0.93333333 1"/>
      </material>
    </visual>
    <collision name="link:Hand_(1):hand_umi2_(1).collision">
      <origin xyz="0 0 0" rpy="0 0 0"/>
      <geometry name="link:Hand_(1):hand_umi2_(1)_collision_geometry">
        <mesh filename="meshes/Hand_(1):hand_umi2_(1).stl"/>
      </geometry>
    </collision>
    <inertial name="link:Hand_(1):hand_umi2_(1)_inertial">
      <mass value="0.064227671"/>
      <inertia ixx="1.6527818e-05" iyy="6.0431617e-05" izz="6.1915193e-05" ixy="0" ixz="6.1464183e-06" iyz="0"/>
      <origin xyz="0.0061009097 0.00058732212 -0.0021018821" rpy="0 0 0"/>
    </inertial>
  </link>
  <joint name="joint:Hand_(1):Fastened_4" type="fixed">
    <origin xyz="-0.05 0.0125 0.0125" rpy="0 0 0"/>
    <parent link="link:Hand_(1):hand_part_(1)"/>
    <child link="link:Hand_(1):hand_umi_(1)"/>
  </joint>
  <link name="link:Hand_(1):hand_umi_(1)">
    <visual name="link:Hand_(1):hand_umi_(1)_visual">
      <origin xyz="0 0 0" rpy="0 0 0"/>
      <geometry name="link:Hand_(1):hand_umi_(1)_geometry">
        <mesh filename="meshes/Hand_(1):hand_umi_(1).stl"/>
      </geometry>
      <material name="link:Hand_(1):hand_umi_(1)_material">
        <color rgba="0.79215686 0.81960784 0.93333333 1"/>
      </material>
    </visual>
    <collision name="link:Hand_(1):hand_umi_(1).collision">
      <origin xyz="0 0 0" rpy="0 0 0"/>
      <geometry name="link:Hand_(1):hand_umi_(1)_collision_geometry">
        <mesh filename="meshes/Hand_(1):hand_umi_(1).stl"/>
      </geometry>
    </collision>
    <inertial name="link:Hand_(1):hand_umi_(1)_inertial">
      <mass value="0.064227671"/>
      <inertia ixx="1.6527818e-05" iyy="6.0431617e-05" izz="6.1915193e-05" ixy="0" ixz="6.1464183e-06" iyz="0"/>
      <origin xyz="0.0061009097 0.00058732212 -0.0021018821" rpy="0 0 0"/>
    </inertial>
  </link>
  <joint name="joint:foot_flat_(1):Fastened_1" type="fixed">
    <origin xyz="0.0325 -0.015 -0.0405" rpy="-1.5707963 0 0"/>
    <parent link="link:foot_flat_(1):foot1_(1)"/>
    <child link="link:foot_flat_(1):foot2_(1)"/>
  </joint>
  <link name="link:foot_flat_(1):foot2_(1)">
    <visual name="link:foot_flat_(1):foot2_(1)_visual">
      <origin xyz="0 0 0" rpy="0 0 0"/>
      <geometry name="link:foot_flat_(1):foot2_(1)_geometry">
        <mesh filename="meshes/foot_flat_(1):foot2_(1).stl"/>
      </geometry>
      <material name="link:foot_flat_(1):foot2_(1)_material">
        <color rgba="0.79215686 0.81960784 0.93333333 1"/>
      </material>
    </visual>
    <collision name="link:foot_flat_(1):foot2_(1).collision">
      <origin xyz="0 0 0" rpy="0 0 0"/>
      <geometry name="link:foot_flat_(1):foot2_(1)_collision_geometry">
        <mesh filename="meshes/foot_flat_(1):foot2_(1).stl"/>
      </geometry>
    </collision>
    <inertial name="link:foot_flat_(1):foot2_(1)_inertial">
      <mass value="0.26918986"/>
      <inertia ixx="0.00010525805" iyy="0.0010723111" izz="0.0011580686" ixy="1.6097044e-05" ixz="-4.1181425e-06" iyz="0"/>
      <origin xyz="-0.0026596521 -0.021598533 -0.011131125" rpy="0 0 0"/>
    </inertial>
  </link>
</robot>
