<?xml version="1.0" ?>
<robot name="kbotv2p0_nohands">
  <link name="link:Torso_Side_Right_(1)">
    <visual name="link:Torso_Side_Right_(1)_visual">
      <origin xyz="0 0 0" rpy="0 0 0"/>
      <geometry name="link:Torso_Side_Right_(1)_geometry">
        <mesh filename="meshes/Torso_Side_Right_(1).stl"/>
      </geometry>
      <material name="link:Torso_Side_Right_(1)_material">
        <color rgba="0.2627451 0.28235294 0.30196078 1"/>
      </material>
    </visual>
    <collision name="link:Torso_Side_Right_(1).collision">
      <origin xyz="0 0 0" rpy="0 0 0"/>
      <geometry name="link:Torso_Side_Right_(1)_collision_geometry">
        <mesh filename="meshes/Torso_Side_Right_(1).stl"/>
      </geometry>
    </collision>
    <inertial name="link:Torso_Side_Right_(1)_inertial">
      <mass value="0.43527679"/>
      <inertia ixx="0.0084865784" iyy="0.0077504129" izz="0.00085236756" ixy="0" ixz="-0.00018345329" iyz="2.9342906e-05"/>
      <origin xyz="0 0 0" rpy="0 0 0"/>
    </inertial>
  </link>
  <joint name="joint:dof_right_shldr" type="fixed">
    <origin xyz="-0.0050314863 0.04900736 0.096020703" rpy="-1.5707963 0 1.5707963"/>
    <parent link="link:Torso_Side_Right_(1)"/>
    <child link="link:Torso_Side_Cover_Right_(1)"/>
  </joint>
  <link name="link:Torso_Side_Cover_Right_(1)">
    <visual name="link:Torso_Side_Cover_Right_(1)_visual">
      <origin xyz="0 0 0" rpy="0 0 0"/>
      <geometry name="link:Torso_Side_Cover_Right_(1)_geometry">
        <mesh filename="meshes/Torso_Side_Cover_Right_(1).stl"/>
      </geometry>
      <material name="link:Torso_Side_Cover_Right_(1)_material">
        <color rgba="0.2627451 0.28235294 0.30196078 1"/>
      </material>
    </visual>
    <collision name="link:Torso_Side_Cover_Right_(1).collision">
      <origin xyz="0 0 0" rpy="0 0 0"/>
      <geometry name="link:Torso_Side_Cover_Right_(1)_collision_geometry">
        <mesh filename="meshes/Torso_Side_Cover_Right_(1).stl"/>
      </geometry>
    </collision>
    <inertial name="link:Torso_Side_Cover_Right_(1)_inertial">
      <mass value="0.062512404"/>
      <inertia ixx="0.00021463124" iyy="0.00014112468" izz="0.00034013778" ixy="1.1881246e-06" ixz="0" iyz="4.4885961e-06"/>
      <origin xyz="-0.04861866 -0.0090527459 0.01875895" rpy="0 0 0"/>
    </inertial>
  </link>
  <joint name="joint:dof_batt_slot" type="fixed">
    <origin xyz="0.019568514 0.026877095 -0.024505624" rpy="-1.5707963 0 1.5707963"/>
    <parent link="link:Torso_Side_Right_(1)"/>
    <child link="link:BATT-SLOT_(1)"/>
  </joint>
  <link name="link:BATT-SLOT_(1)">
    <visual name="link:BATT-SLOT_(1)_visual">
      <origin xyz="0 0 0" rpy="0 0 0"/>
      <geometry name="link:BATT-SLOT_(1)_geometry">
        <mesh filename="meshes/BATT-SLOT_(1).stl"/>
      </geometry>
      <material name="link:BATT-SLOT_(1)_material">
        <color rgba="0.2627451 0.28235294 0.30196078 1"/>
      </material>
    </visual>
    <collision name="link:BATT-SLOT_(1).collision">
      <origin xyz="0 0 0" rpy="0 0 0"/>
      <geometry name="link:BATT-SLOT_(1)_collision_geometry">
        <mesh filename="meshes/BATT-SLOT_(1).stl"/>
      </geometry>
    </collision>
    <inertial name="link:BATT-SLOT_(1)_inertial">
      <mass value="0.86427791"/>
      <inertia ixx="0.0088498034" iyy="0.0036484288" izz="0.0071632484" ixy="0.00032486515" ixz="3.6676175e-06" iyz="1.2487149e-05"/>
      <origin xyz="-0.026479195 0.040947059 -0.073103568" rpy="0 0 0"/>
    </inertial>
  </link>
  <joint name="joint:dof_top_torso" type="fixed">
    <origin xyz="0.019968514 0.03000736 0.1910207" rpy="-1.5707963 0 1.5707963"/>
    <parent link="link:Torso_Side_Right_(1)"/>
    <child link="link:Torso-top_(1)"/>
  </joint>
  <link name="link:Torso-top_(1)">
    <visual name="link:Torso-top_(1)_visual">
      <origin xyz="0 0 0" rpy="0 0 0"/>
      <geometry name="link:Torso-top_(1)_geometry">
        <mesh filename="meshes/Torso-top_(1).stl"/>
      </geometry>
      <material name="link:Torso-top_(1)_material">
        <color rgba="0.2627451 0.28235294 0.30196078 1"/>
      </material>
    </visual>
    <collision name="link:Torso-top_(1).collision">
      <origin xyz="0 0 0" rpy="0 0 0"/>
      <geometry name="link:Torso-top_(1)_collision_geometry">
        <mesh filename="meshes/Torso-top_(1).stl"/>
      </geometry>
    </collision>
    <inertial name="link:Torso-top_(1)_inertial">
      <mass value="0.1481213"/>
      <inertia ixx="0.00045250964" iyy="0.0006853482" izz="0.00024839065" ixy="3.5557901e-06" ixz="0" iyz="0"/>
      <origin xyz="-0.03149781 0.0059162158 -0.07297296" rpy="0 0 0"/>
    </inertial>
  </link>
  <joint name="joint:dof_btm" type="fixed">
    <origin xyz="0.019968514 7.3596502e-06 -0.2079793" rpy="-1.5707963 0 1.5707963"/>
    <parent link="link:Torso_Side_Right_(1)"/>
    <child link="link:Torso_Bottom_(1)"/>
  </joint>
  <link name="link:Torso_Bottom_(1)">
    <visual name="link:Torso_Bottom_(1)_visual">
      <origin xyz="0 0 0" rpy="0 0 0"/>
      <geometry name="link:Torso_Bottom_(1)_geometry">
        <mesh filename="meshes/Torso_Bottom_(1).stl"/>
      </geometry>
      <material name="link:Torso_Bottom_(1)_material">
        <color rgba="0.2627451 0.28235294 0.30196078 1"/>
      </material>
    </visual>
    <collision name="link:Torso_Bottom_(1).collision">
      <origin xyz="0 0 0" rpy="0 0 0"/>
      <geometry name="link:Torso_Bottom_(1)_collision_geometry">
        <mesh filename="meshes/Torso_Bottom_(1).stl"/>
      </geometry>
    </collision>
    <inertial name="link:Torso_Bottom_(1)_inertial">
      <mass value="0.27510224"/>
      <inertia ixx="0.00070218869" iyy="0.0010887906" izz="0.00042690749" ixy="-5.7194057e-06" ixz="0" iyz="0"/>
      <origin xyz="-0.0013151622 0.0028752246 -0.07293958" rpy="0 0 0"/>
    </inertial>
  </link>
  <joint name="joint:dof_right_rs03" type="fixed">
    <origin xyz="0.014968514 7.3596502e-06 0.1260207" rpy="3.1415927 -1.5707963 0"/>
    <parent link="link:Torso_Side_Right_(1)"/>
    <child link="link:RS03_(3)"/>
  </joint>
  <link name="link:RS03_(3)">
    <visual name="link:RS03_(3)_visual">
      <origin xyz="0 0 0" rpy="0 0 0"/>
      <geometry name="link:RS03_(3)_geometry">
        <mesh filename="meshes/RS03_(3).stl"/>
      </geometry>
      <material name="link:RS03_(3)_material">
        <color rgba="0.2627451 0.28235294 0.30196078 1"/>
      </material>
    </visual>
    <collision name="link:RS03_(3).collision">
      <origin xyz="0 0 0" rpy="0 0 0"/>
      <geometry name="link:RS03_(3)_collision_geometry">
        <mesh filename="meshes/RS03_(3).stl"/>
      </geometry>
    </collision>
    <inertial name="link:RS03_(3)_inertial">
      <mass value="0.88"/>
      <inertia ixx="0.00065607101" iyy="0.00065607101" izz="0.00088708736" ixy="0" ixz="0" iyz="0"/>
      <origin xyz="0 0 -0.014732068" rpy="0 0 0"/>
    </inertial>
  </link>
  <joint name="joint:dof_batt_2slot" type="fixed">
    <origin xyz="-0.060978562 0.042792597 -0.072501341" rpy="1.5707963 0 -1.5259763"/>
    <parent link="link:BATT-SLOT_(1)"/>
    <child link="link:Battery_Back_Case_(1)"/>
  </joint>
  <link name="link:Battery_Back_Case_(1)">
    <visual name="link:Battery_Back_Case_(1)_visual">
      <origin xyz="0 0 0" rpy="0 0 0"/>
      <geometry name="link:Battery_Back_Case_(1)_geometry">
        <mesh filename="meshes/Battery_Back_Case_(1).stl"/>
      </geometry>
      <material name="link:Battery_Back_Case_(1)_material">
        <color rgba="0.49803922 0.49803922 0.49803922 1"/>
      </material>
    </visual>
    <collision name="link:Battery_Back_Case_(1).collision">
      <origin xyz="0 0 0" rpy="0 0 0"/>
      <geometry name="link:Battery_Back_Case_(1)_collision_geometry">
        <mesh filename="meshes/Battery_Back_Case_(1).stl"/>
      </geometry>
    </collision>
    <inertial name="link:Battery_Back_Case_(1)_inertial">
      <mass value="0.21851552"/>
      <inertia ixx="0.000527492" iyy="0.0014258588" izz="0.0018841024" ixy="2.86523e-05" ixz="1.4683833e-05" iyz="-4.3484311e-06"/>
      <origin xyz="0.006958454 -0.0025386017 -0.012720062" rpy="0 0 0"/>
    </inertial>
  </link>
  <joint name="joint:dof_head_fix" type="fixed">
    <origin xyz="-0.051 -0.00700022 -0.009818" rpy="-1.5707963 1.5707963 0"/>
    <parent link="link:Torso-top_(1)"/>
    <child link="link:head_back_(1)"/>
  </joint>
  <link name="link:head_back_(1)">
    <visual name="link:head_back_(1)_visual">
      <origin xyz="0 0 0" rpy="0 0 0"/>
      <geometry name="link:head_back_(1)_geometry">
        <mesh filename="meshes/head_back_(1).stl"/>
      </geometry>
      <material name="link:head_back_(1)_material">
        <color rgba="0.2627451 0.28235294 0.30196078 1"/>
      </material>
    </visual>
    <collision name="link:head_back_(1).collision">
      <origin xyz="0 0 0" rpy="0 0 0"/>
      <geometry name="link:head_back_(1)_collision_geometry">
        <mesh filename="meshes/head_back_(1).stl"/>
      </geometry>
    </collision>
    <inertial name="link:head_back_(1)_inertial">
      <mass value="0.26680769"/>
      <inertia ixx="0.001482545" iyy="0.0018609267" izz="0.00095077488" ixy="0" ixz="0" iyz="-0.00010981727"/>
      <origin xyz="0.063188381 -0.027634955 -0.063985798" rpy="0 0 0"/>
    </inertial>
  </link>
  <joint name="joint:dof_left_torso" type="fixed">
    <origin xyz="-0.04 0 -0.146" rpy="0 0 0"/>
    <parent link="link:Torso-top_(1)"/>
    <child link="link:Torso_Side_Left_(1)"/>
  </joint>
  <link name="link:Torso_Side_Left_(1)">
    <visual name="link:Torso_Side_Left_(1)_visual">
      <origin xyz="0 0 0" rpy="0 0 0"/>
      <geometry name="link:Torso_Side_Left_(1)_geometry">
        <mesh filename="meshes/Torso_Side_Left_(1).stl"/>
      </geometry>
      <material name="link:Torso_Side_Left_(1)_material">
        <color rgba="0.2627451 0.28235294 0.30196078 1"/>
      </material>
    </visual>
    <collision name="link:Torso_Side_Left_(1).collision">
      <origin xyz="0 0 0" rpy="0 0 0"/>
      <geometry name="link:Torso_Side_Left_(1)_collision_geometry">
        <mesh filename="meshes/Torso_Side_Left_(1).stl"/>
      </geometry>
    </collision>
    <inertial name="link:Torso_Side_Left_(1)_inertial">
      <mass value="0.43850267"/>
      <inertia ixx="0.0078257379" iyy="0.00085683403" izz="0.0085657627" ixy="-3.0840034e-05" ixz="0" iyz="0.00018517049"/>
      <origin xyz="0.0099659219 0.19089627 -0.019947218" rpy="0 0 0"/>
    </inertial>
  </link>
  <joint name="joint:dof_front_panel" type="fixed">
    <origin xyz="-0.10096002 0.01677278 -0.139" rpy="0 1.5707963 0"/>
    <parent link="link:Torso-top_(1)"/>
    <child link="link:torso-front-up_(1)"/>
  </joint>
  <link name="link:torso-front-up_(1)">
    <visual name="link:torso-front-up_(1)_visual">
      <origin xyz="0 0 0" rpy="0 0 0"/>
      <geometry name="link:torso-front-up_(1)_geometry">
        <mesh filename="meshes/torso-front-up_(1).stl"/>
      </geometry>
      <material name="link:torso-front-up_(1)_material">
        <color rgba="0.2627451 0.28235294 0.30196078 1"/>
      </material>
    </visual>
    <collision name="link:torso-front-up_(1).collision">
      <origin xyz="0 0 0" rpy="0 0 0"/>
      <geometry name="link:torso-front-up_(1)_collision_geometry">
        <mesh filename="meshes/torso-front-up_(1).stl"/>
      </geometry>
    </collision>
    <inertial name="link:torso-front-up_(1)_inertial">
      <mass value="0.067020771"/>
      <inertia ixx="6.9688928e-05" iyy="0.00012311092" izz="0.0001927585" ixy="0" ixz="0" iyz="0"/>
      <origin xyz="-0.066 0.052236849 -0.00069643835" rpy="0 0 0"/>
    </inertial>
  </link>
  <joint name="joint:dof_right_hip" type="fixed">
    <origin xyz="-0.0355 0.0125 -0.046" rpy="1.5707963 1.5707963 0"/>
    <parent link="link:Torso_Bottom_(1)"/>
    <child link="link:KC-D-101R_R_Hip_Static_(1)"/>
  </joint>
  <link name="link:KC-D-101R_R_Hip_Static_(1)">
    <visual name="link:KC-D-101R_R_Hip_Static_(1)_visual">
      <origin xyz="0 0 0" rpy="0 0 0"/>
      <geometry name="link:KC-D-101R_R_Hip_Static_(1)_geometry">
        <mesh filename="meshes/KC-D-101R_R_Hip_Static_(1).stl"/>
      </geometry>
      <material name="link:KC-D-101R_R_Hip_Static_(1)_material">
        <color rgba="0.2627451 0.28235294 0.30196078 1"/>
      </material>
    </visual>
    <collision name="link:KC-D-101R_R_Hip_Static_(1).collision">
      <origin xyz="0 0 0" rpy="0 0 0"/>
      <geometry name="link:KC-D-101R_R_Hip_Static_(1)_collision_geometry">
        <mesh filename="meshes/KC-D-101R_R_Hip_Static_(1).stl"/>
      </geometry>
    </collision>
    <inertial name="link:KC-D-101R_R_Hip_Static_(1)_inertial">
      <mass value="0.46998986"/>
      <inertia ixx="0.0016767364" iyy="0.0008309258" izz="0.0011702024" ixy="4.0451595e-06" ixz="0.00015901301" iyz="-2.5236839e-05"/>
      <origin xyz="0.00061149651 0.034829983 -0.036218995" rpy="0 0 0"/>
    </inertial>
  </link>
  <joint name="joint:dof_left_hip" type="fixed">
    <origin xyz="-0.0355 0.0125 -0.097" rpy="1.5707963 1.5707963 0"/>
    <parent link="link:Torso_Bottom_(1)"/>
    <child link="link:KC-D-101L_L_Hip_Static_(1)"/>
  </joint>
  <link name="link:KC-D-101L_L_Hip_Static_(1)">
    <visual name="link:KC-D-101L_L_Hip_Static_(1)_visual">
      <origin xyz="0 0 0" rpy="0 0 0"/>
      <geometry name="link:KC-D-101L_L_Hip_Static_(1)_geometry">
        <mesh filename="meshes/KC-D-101L_L_Hip_Static_(1).stl"/>
      </geometry>
      <material name="link:KC-D-101L_L_Hip_Static_(1)_material">
        <color rgba="0.2627451 0.28235294 0.30196078 1"/>
      </material>
    </visual>
    <collision name="link:KC-D-101L_L_Hip_Static_(1).collision">
      <origin xyz="0 0 0" rpy="0 0 0"/>
      <geometry name="link:KC-D-101L_L_Hip_Static_(1)_collision_geometry">
        <mesh filename="meshes/KC-D-101L_L_Hip_Static_(1).stl"/>
      </geometry>
    </collision>
    <inertial name="link:KC-D-101L_L_Hip_Static_(1)_inertial">
      <mass value="0.46680568"/>
      <inertia ixx="0.0016538447" iyy="0.00081433251" izz="0.0011623464" ixy="-3.4162443e-06" ixz="-0.00015567447" iyz="-2.2195227e-05"/>
      <origin xyz="0.0024949841 0.03491055 -0.035742034" rpy="0 0 0"/>
    </inertial>
  </link>
  <joint name="joint:dof_right_shoulder_pitch_03" type="revolute">
    <origin xyz="0 0 -0.042" rpy="0 0 -1.5707963"/>
    <parent link="link:RS03_(3)"/>
    <child link="link:KC-C-104R_PitchHardstopDriven_(1)"/>
    <limit effort="60" velocity="6.283" lower="-2.6179939" upper="2.0943951"/>
    <axis xyz="0 0 1"/>
  </joint>
  <link name="link:KC-C-104R_PitchHardstopDriven_(1)">
    <visual name="link:KC-C-104R_PitchHardstopDriven_(1)_visual">
      <origin xyz="0 0 0" rpy="0 0 0"/>
      <geometry name="link:KC-C-104R_PitchHardstopDriven_(1)_geometry">
        <mesh filename="meshes/KC-C-104R_PitchHardstopDriven_(1).stl"/>
      </geometry>
      <material name="link:KC-C-104R_PitchHardstopDriven_(1)_material">
        <color rgba="0.2627451 0.28235294 0.30196078 1"/>
      </material>
    </visual>
    <collision name="link:KC-C-104R_PitchHardstopDriven_(1).collision">
      <origin xyz="0 0 0" rpy="0 0 0"/>
      <geometry name="link:KC-C-104R_PitchHardstopDriven_(1)_collision_geometry">
        <mesh filename="meshes/KC-C-104R_PitchHardstopDriven_(1).stl"/>
      </geometry>
    </collision>
    <inertial name="link:KC-C-104R_PitchHardstopDriven_(1)_inertial">
      <mass value="0.020105633"/>
      <inertia ixx="4.3216372e-06" iyy="3.7451305e-06" izz="7.9654018e-06" ixy="-1.6836283e-06" ixz="0" iyz="0"/>
      <origin xyz="-0.0053409868 -0.0063958873 -0.00275" rpy="0 0 0"/>
    </inertial>
  </link>
  <joint name="joint:fixed_right03_hrdstop" type="fixed">
    <origin xyz="0 0 -0.042" rpy="0 0 -1.5707963"/>
    <parent link="link:RS03_(3)"/>
    <child link="link:KC-C-103R_PitchHardstopStatic_(1)"/>
  </joint>
  <link name="link:KC-C-103R_PitchHardstopStatic_(1)">
    <visual name="link:KC-C-103R_PitchHardstopStatic_(1)_visual">
      <origin xyz="0 0 0" rpy="0 0 0"/>
      <geometry name="link:KC-C-103R_PitchHardstopStatic_(1)_geometry">
        <mesh filename="meshes/KC-C-103R_PitchHardstopStatic_(1).stl"/>
      </geometry>
      <material name="link:KC-C-103R_PitchHardstopStatic_(1)_material">
        <color rgba="0.2627451 0.28235294 0.30196078 1"/>
      </material>
    </visual>
    <collision name="link:KC-C-103R_PitchHardstopStatic_(1).collision">
      <origin xyz="0 0 0" rpy="0 0 0"/>
      <geometry name="link:KC-C-103R_PitchHardstopStatic_(1)_collision_geometry">
        <mesh filename="meshes/KC-C-103R_PitchHardstopStatic_(1).stl"/>
      </geometry>
    </collision>
    <inertial name="link:KC-C-103R_PitchHardstopStatic_(1)_inertial">
      <mass value="0.014930382"/>
      <inertia ixx="2.0594563e-06" iyy="1e-06" izz="2.6591859e-06" ixy="0" ixz="0" iyz="0"/>
      <origin xyz="0.035720597 -0.00010513232 -0.0019624697" rpy="0 0 0"/>
    </inertial>
  </link>
  <joint name="joint:fixed_batt1" type="fixed">
    <origin xyz="0.11174925 -0.0012009951 -0.0384" rpy="3.1415927 0 0"/>
    <parent link="link:Battery_Back_Case_(1)"/>
    <child link="link:Battery_Middle_Cover_(1)"/>
  </joint>
  <link name="link:Battery_Middle_Cover_(1)">
    <visual name="link:Battery_Middle_Cover_(1)_visual">
      <origin xyz="0 0 0" rpy="0 0 0"/>
      <geometry name="link:Battery_Middle_Cover_(1)_geometry">
        <mesh filename="meshes/Battery_Middle_Cover_(1).stl"/>
      </geometry>
      <material name="link:Battery_Middle_Cover_(1)_material">
        <color rgba="0.97254902 0.52941176 0.0039215686 1"/>
      </material>
    </visual>
    <collision name="link:Battery_Middle_Cover_(1).collision">
      <origin xyz="0 0 0" rpy="0 0 0"/>
      <geometry name="link:Battery_Middle_Cover_(1)_collision_geometry">
        <mesh filename="meshes/Battery_Middle_Cover_(1).stl"/>
      </geometry>
    </collision>
    <inertial name="link:Battery_Middle_Cover_(1)_inertial">
      <mass value="0.19320769"/>
      <inertia ixx="0.0004249215" iyy="0.0011869971" izz="0.001576403" ixy="2.0791511e-06" ixz="-4.9290873e-06" iyz="0"/>
      <origin xyz="-0.10716041 -0.00014929691 0.023386155" rpy="0 0 0"/>
    </inertial>
  </link>
  <joint name="joint:fixed_batt2" type="fixed">
    <origin xyz="-0.011050748 -0.0012009951 -0.003" rpy="0 0 -1.5707963"/>
    <parent link="link:Battery_Back_Case_(1)"/>
    <child link="link:Battery_CellPack_(1)"/>
  </joint>
  <link name="link:Battery_CellPack_(1)">
    <visual name="link:Battery_CellPack_(1)_visual">
      <origin xyz="0 0 0" rpy="0 0 0"/>
      <geometry name="link:Battery_CellPack_(1)_geometry">
        <mesh filename="meshes/Battery_CellPack_(1).stl"/>
      </geometry>
      <material name="link:Battery_CellPack_(1)_material">
        <color rgba="0.23137255 0.38039216 0.70588235 1"/>
      </material>
    </visual>
    <collision name="link:Battery_CellPack_(1).collision">
      <origin xyz="0 0 0" rpy="0 0 0"/>
      <geometry name="link:Battery_CellPack_(1)_collision_geometry">
        <mesh filename="meshes/Battery_CellPack_(1).stl"/>
      </geometry>
    </collision>
    <inertial name="link:Battery_CellPack_(1)_inertial">
      <mass value="2.6498866"/>
      <inertia ixx="0.007485488" iyy="0.00438225" izz="0.010114838" ixy="0" ixz="0" iyz="0"/>
      <origin xyz="0 0 -0.0315" rpy="0 0 0"/>
    </inertial>
  </link>
  <joint name="joint:dof_comp_holder" type="fixed">
    <origin xyz="0.048181993 0.014219086 0.013200834" rpy="0.011110653 0 0"/>
    <parent link="link:head_back_(1)"/>
    <child link="link:Comp_Holder_(1)"/>
  </joint>
  <link name="link:Comp_Holder_(1)">
    <visual name="link:Comp_Holder_(1)_visual">
      <origin xyz="0 0 0" rpy="0 0 0"/>
      <geometry name="link:Comp_Holder_(1)_geometry">
        <mesh filename="meshes/Comp_Holder_(1).stl"/>
      </geometry>
      <material name="link:Comp_Holder_(1)_material">
        <color rgba="0.2627451 0.28235294 0.30196078 1"/>
      </material>
    </visual>
    <collision name="link:Comp_Holder_(1).collision">
      <origin xyz="0 0 0" rpy="0 0 0"/>
      <geometry name="link:Comp_Holder_(1)_collision_geometry">
        <mesh filename="meshes/Comp_Holder_(1).stl"/>
      </geometry>
    </collision>
    <inertial name="link:Comp_Holder_(1)_inertial">
      <mass value="0.3707883"/>
      <inertia ixx="0.00097371489" iyy="0.00092958183" izz="0.00062630833" ixy="-4.1652298e-06" ixz="-1.1791607e-05" iyz="-0.00019249231"/>
      <origin xyz="0.014856346 -0.027788002 -0.032075328" rpy="0 0 0"/>
    </inertial>
  </link>
  <joint name="joint:dof_mid_head" type="fixed">
    <origin xyz="0.0095174944 0.0046795312 -0.17619807" rpy="2.9670597 0 0"/>
    <parent link="link:head_back_(1)"/>
    <child link="link:LOCKED_Middle_Cover_(1)"/>
  </joint>
  <link name="link:LOCKED_Middle_Cover_(1)">
    <visual name="link:LOCKED_Middle_Cover_(1)_visual">
      <origin xyz="0 0 0" rpy="0 0 0"/>
      <geometry name="link:LOCKED_Middle_Cover_(1)_geometry">
        <mesh filename="meshes/LOCKED_Middle_Cover_(1).stl"/>
      </geometry>
      <material name="link:LOCKED_Middle_Cover_(1)_material">
        <color rgba="0.2627451 0.28235294 0.30196078 1"/>
      </material>
    </visual>
    <collision name="link:LOCKED_Middle_Cover_(1).collision">
      <origin xyz="0 0 0" rpy="0 0 0"/>
      <geometry name="link:LOCKED_Middle_Cover_(1)_collision_geometry">
        <mesh filename="meshes/LOCKED_Middle_Cover_(1).stl"/>
      </geometry>
    </collision>
    <inertial name="link:LOCKED_Middle_Cover_(1)_inertial">
      <mass value="0.082517077"/>
      <inertia ixx="0.00021246086" iyy="0.00052329382" izz="0.00031535936" ixy="0" ixz="0" iyz="-5.0709488e-06"/>
      <origin xyz="0.053829261 -0.011428535 -0.088863279" rpy="0 0 0"/>
    </inertial>
  </link>
  <joint name="joint:dof_left_shldr" type="fixed">
    <origin xyz="0.053 0.022 -0.025" rpy="0 0 0"/>
    <parent link="link:Torso_Side_Left_(1)"/>
    <child link="link:Torso_Side_Cover_Left_(1)"/>
  </joint>
  <link name="link:Torso_Side_Cover_Left_(1)">
    <visual name="link:Torso_Side_Cover_Left_(1)_visual">
      <origin xyz="0 0 0" rpy="0 0 0"/>
      <geometry name="link:Torso_Side_Cover_Left_(1)_geometry">
        <mesh filename="meshes/Torso_Side_Cover_Left_(1).stl"/>
      </geometry>
      <material name="link:Torso_Side_Cover_Left_(1)_material">
        <color rgba="0.2627451 0.28235294 0.30196078 1"/>
      </material>
    </visual>
    <collision name="link:Torso_Side_Cover_Left_(1).collision">
      <origin xyz="0 0 0" rpy="0 0 0"/>
      <geometry name="link:Torso_Side_Cover_Left_(1)_collision_geometry">
        <mesh filename="meshes/Torso_Side_Cover_Left_(1).stl"/>
      </geometry>
    </collision>
    <inertial name="link:Torso_Side_Cover_Left_(1)_inertial">
      <mass value="0.06369199"/>
      <inertia ixx="0.00021890368" iyy="0.00014418838" izz="0.0003472233" ixy="1.2664073e-06" ixz="0" iyz="-4.4684908e-06"/>
      <origin xyz="-0.042533208 0.063366906 -0.018741306" rpy="0 0 0"/>
    </inertial>
  </link>
  <joint name="joint:dof_left_rs03" type="fixed">
    <origin xyz="0.01 0.065 -0.005" rpy="0 0 1.5707963"/>
    <parent link="link:Torso_Side_Left_(1)"/>
    <child link="link:RS03_(4)"/>
  </joint>
  <link name="link:RS03_(4)">
    <visual name="link:RS03_(4)_visual">
      <origin xyz="0 0 0" rpy="0 0 0"/>
      <geometry name="link:RS03_(4)_geometry">
        <mesh filename="meshes/RS03_(4).stl"/>
      </geometry>
      <material name="link:RS03_(4)_material">
        <color rgba="0.2627451 0.28235294 0.30196078 1"/>
      </material>
    </visual>
    <collision name="link:RS03_(4).collision">
      <origin xyz="0 0 0" rpy="0 0 0"/>
      <geometry name="link:RS03_(4)_collision_geometry">
        <mesh filename="meshes/RS03_(4).stl"/>
      </geometry>
    </collision>
    <inertial name="link:RS03_(4)_inertial">
      <mass value="0.88"/>
      <inertia ixx="0.00065607101" iyy="0.00065607101" izz="0.00088708736" ixy="0" ixz="0" iyz="0"/>
      <origin xyz="0 0 -0.014732068" rpy="0 0 0"/>
    </inertial>
  </link>
  <joint name="joint:dof_front_top" type="fixed">
    <origin xyz="-0.132 0.10189601 0.0030858611" rpy="0 0 0"/>
    <parent link="link:torso-front-up_(1)"/>
    <child link="link:Torso_Inside_(1)"/>
  </joint>
  <link name="link:Torso_Inside_(1)">
    <visual name="link:Torso_Inside_(1)_visual">
      <origin xyz="0 0 0" rpy="0 0 0"/>
      <geometry name="link:Torso_Inside_(1)_geometry">
        <mesh filename="meshes/Torso_Inside_(1).stl"/>
      </geometry>
      <material name="link:Torso_Inside_(1)_material">
        <color rgba="0.2627451 0.28235294 0.30196078 1"/>
      </material>
    </visual>
    <collision name="link:Torso_Inside_(1).collision">
      <origin xyz="0 0 0" rpy="0 0 0"/>
      <geometry name="link:Torso_Inside_(1)_collision_geometry">
        <mesh filename="meshes/Torso_Inside_(1).stl"/>
      </geometry>
    </collision>
    <inertial name="link:Torso_Inside_(1)_inertial">
      <mass value="0.14409811"/>
      <inertia ixx="0.00051114624" iyy="0.0012503038" izz="0.00074877071" ixy="0" ixz="0" iyz="0"/>
      <origin xyz="0.066011806 0.013461507 0.066155695" rpy="0 0 0"/>
    </inertial>
  </link>
  <joint name="joint:dof_right_hip" type="fixed">
    <origin xyz="0.0115 0.0355 -0.064" rpy="-1.5707963 0 1.5707963"/>
    <parent link="link:KC-D-101R_R_Hip_Static_(1)"/>
    <child link="link:RS04_(2)"/>
  </joint>
  <link name="link:RS04_(2)">
    <visual name="link:RS04_(2)_visual">
      <origin xyz="0 0 0" rpy="0 0 0"/>
      <geometry name="link:RS04_(2)_geometry">
        <mesh filename="meshes/RS04_(2).stl"/>
      </geometry>
      <material name="link:RS04_(2)_material">
        <color rgba="0.2627451 0.28235294 0.30196078 1"/>
      </material>
    </visual>
    <collision name="link:RS04_(2).collision">
      <origin xyz="0 0 0" rpy="0 0 0"/>
      <geometry name="link:RS04_(2)_collision_geometry">
        <mesh filename="meshes/RS04_(2).stl"/>
      </geometry>
    </collision>
    <inertial name="link:RS04_(2)_inertial">
      <mass value="1.42"/>
      <inertia ixx="0.001482289" iyy="0.001482289" izz="0.0023882984" ixy="0" ixz="0" iyz="0"/>
      <origin xyz="0 0 0.015085056" rpy="0 0 0"/>
    </inertial>
  </link>
  <joint name="joint:dof_right_hip_idle" type="fixed">
    <origin xyz="-0.0025 -0.0255 -0.090171573" rpy="-1.5707963 0 0"/>
    <parent link="link:KC-D-101R_R_Hip_Static_(1)"/>
    <child link="link:KC-D-107R_R_Cover_(1)"/>
  </joint>
  <link name="link:KC-D-107R_R_Cover_(1)">
    <visual name="link:KC-D-107R_R_Cover_(1)_visual">
      <origin xyz="0 0 0" rpy="0 0 0"/>
      <geometry name="link:KC-D-107R_R_Cover_(1)_geometry">
        <mesh filename="meshes/KC-D-107R_R_Cover_(1).stl"/>
      </geometry>
      <material name="link:KC-D-107R_R_Cover_(1)_material">
        <color rgba="0.2627451 0.28235294 0.30196078 1"/>
      </material>
    </visual>
    <collision name="link:KC-D-107R_R_Cover_(1).collision">
      <origin xyz="0 0 0" rpy="0 0 0"/>
      <geometry name="link:KC-D-107R_R_Cover_(1)_collision_geometry">
        <mesh filename="meshes/KC-D-107R_R_Cover_(1).stl"/>
      </geometry>
    </collision>
    <inertial name="link:KC-D-107R_R_Cover_(1)_inertial">
      <mass value="0.01892127"/>
      <inertia ixx="4.4111449e-05" iyy="4.2294207e-05" izz="8.9224346e-06" ixy="0" ixz="0" iyz="0"/>
      <origin xyz="-0.0099213816 0.020090008 0.061112883" rpy="0 0 0"/>
    </inertial>
  </link>
  <joint name="joint:dof_left_hip" type="fixed">
    <origin xyz="-0.009 0.0355 -0.064" rpy="1.5707963 0 1.5707963"/>
    <parent link="link:KC-D-101L_L_Hip_Static_(1)"/>
    <child link="link:RS04_(4)"/>
  </joint>
  <link name="link:RS04_(4)">
    <visual name="link:RS04_(4)_visual">
      <origin xyz="0 0 0" rpy="0 0 0"/>
      <geometry name="link:RS04_(4)_geometry">
        <mesh filename="meshes/RS04_(4).stl"/>
      </geometry>
      <material name="link:RS04_(4)_material">
        <color rgba="0.2627451 0.28235294 0.30196078 1"/>
      </material>
    </visual>
    <collision name="link:RS04_(4).collision">
      <origin xyz="0 0 0" rpy="0 0 0"/>
      <geometry name="link:RS04_(4)_collision_geometry">
        <mesh filename="meshes/RS04_(4).stl"/>
      </geometry>
    </collision>
    <inertial name="link:RS04_(4)_inertial">
      <mass value="1.42"/>
      <inertia ixx="0.001482289" iyy="0.001482289" izz="0.0023882984" ixy="0" ixz="0" iyz="0"/>
      <origin xyz="0 0 0.015085056" rpy="0 0 0"/>
    </inertial>
  </link>
  <joint name="joint:dof_left_hip_idle" type="fixed">
    <origin xyz="-0.0025 -0.0255 -0.090171573" rpy="-1.5707963 0 0"/>
    <parent link="link:KC-D-101L_L_Hip_Static_(1)"/>
    <child link="link:KC-D-107L_L_Cover_(1)"/>
  </joint>
  <link name="link:KC-D-107L_L_Cover_(1)">
    <visual name="link:KC-D-107L_L_Cover_(1)_visual">
      <origin xyz="0 0 0" rpy="0 0 0"/>
      <geometry name="link:KC-D-107L_L_Cover_(1)_geometry">
        <mesh filename="meshes/KC-D-107L_L_Cover_(1).stl"/>
      </geometry>
      <material name="link:KC-D-107L_L_Cover_(1)_material">
        <color rgba="0.2627451 0.28235294 0.30196078 1"/>
      </material>
    </visual>
    <collision name="link:KC-D-107L_L_Cover_(1).collision">
      <origin xyz="0 0 0" rpy="0 0 0"/>
      <geometry name="link:KC-D-107L_L_Cover_(1)_collision_geometry">
        <mesh filename="meshes/KC-D-107L_L_Cover_(1).stl"/>
      </geometry>
    </collision>
    <inertial name="link:KC-D-107L_L_Cover_(1)_inertial">
      <mass value="0.018921274"/>
      <inertia ixx="4.4111451e-05" iyy="4.2294209e-05" izz="8.9224352e-06" ixy="0" ixz="0" iyz="0"/>
      <origin xyz="0.01792138 0.02009001 0.061112878" rpy="0 0 0"/>
    </inertial>
  </link>
  <joint name="joint:fixed_right_Shldrhrdstp" type="fixed">
    <origin xyz="0 0 -0.0055" rpy="3.1415927 0 -0.34906585"/>
    <parent link="link:KC-C-104R_PitchHardstopDriven_(1)"/>
    <child link="link:KC-C-101R_ShldYokeDrive_(1)"/>
  </joint>
  <link name="link:KC-C-101R_ShldYokeDrive_(1)">
    <visual name="link:KC-C-101R_ShldYokeDrive_(1)_visual">
      <origin xyz="0 0 0" rpy="0 0 0"/>
      <geometry name="link:KC-C-101R_ShldYokeDrive_(1)_geometry">
        <mesh filename="meshes/KC-C-101R_ShldYokeDrive_(1).stl"/>
      </geometry>
      <material name="link:KC-C-101R_ShldYokeDrive_(1)_material">
        <color rgba="0.2627451 0.28235294 0.30196078 1"/>
      </material>
    </visual>
    <collision name="link:KC-C-101R_ShldYokeDrive_(1).collision">
      <origin xyz="0 0 0" rpy="0 0 0"/>
      <geometry name="link:KC-C-101R_ShldYokeDrive_(1)_collision_geometry">
        <mesh filename="meshes/KC-C-101R_ShldYokeDrive_(1).stl"/>
      </geometry>
    </collision>
    <inertial name="link:KC-C-101R_ShldYokeDrive_(1)_inertial">
      <mass value="0.40626602"/>
      <inertia ixx="0.00085159842" iyy="0.00068785275" izz="0.00066178752" ixy="-2.2453403e-05" ixz="0.00017108472" iyz="-6.7567749e-05"/>
      <origin xyz="-0.0252343 0.0046946437 0.043691201" rpy="0 0 0"/>
    </inertial>
  </link>
  <joint name="joint:fixed_batt3" type="fixed">
    <origin xyz="-0.0025 0.0445 0.0315" rpy="3.1415927 0 1.5707963"/>
    <parent link="link:Battery_Middle_Cover_(1)"/>
    <child link="link:Battery_Cover_(1)"/>
  </joint>
  <link name="link:Battery_Cover_(1)">
    <visual name="link:Battery_Cover_(1)_visual">
      <origin xyz="0 0 0" rpy="0 0 0"/>
      <geometry name="link:Battery_Cover_(1)_geometry">
        <mesh filename="meshes/Battery_Cover_(1).stl"/>
      </geometry>
      <material name="link:Battery_Cover_(1)_material">
        <color rgba="0.97254902 0.52941176 0.0039215686 1"/>
      </material>
    </visual>
    <collision name="link:Battery_Cover_(1).collision">
      <origin xyz="0 0 0" rpy="0 0 0"/>
      <geometry name="link:Battery_Cover_(1)_collision_geometry">
        <mesh filename="meshes/Battery_Cover_(1).stl"/>
      </geometry>
    </collision>
    <inertial name="link:Battery_Cover_(1)_inertial">
      <mass value="0.1768278"/>
      <inertia ixx="0.0011065925" iyy="0.00031241889" izz="0.0013960138" ixy="0" ixz="0" iyz="2.0351869e-06"/>
      <origin xyz="-0.044531738 -0.10345728 -0.01616656" rpy="0 0 0"/>
    </inertial>
  </link>
  <joint name="joint:fixed_battHandle" type="fixed">
    <origin xyz="-0.065149829 0.02 0.043750211" rpy="-1.5707963 -1.5259763 0"/>
    <parent link="link:Battery_Middle_Cover_(1)"/>
    <child link="link:Battery_Handle_(1)"/>
  </joint>
  <link name="link:Battery_Handle_(1)">
    <visual name="link:Battery_Handle_(1)_visual">
      <origin xyz="0 0 0" rpy="0 0 0"/>
      <geometry name="link:Battery_Handle_(1)_geometry">
        <mesh filename="meshes/Battery_Handle_(1).stl"/>
      </geometry>
      <material name="link:Battery_Handle_(1)_material">
        <color rgba="0.49803922 0.49803922 0.49803922 1"/>
      </material>
    </visual>
    <collision name="link:Battery_Handle_(1).collision">
      <origin xyz="0 0 0" rpy="0 0 0"/>
      <geometry name="link:Battery_Handle_(1)_collision_geometry">
        <mesh filename="meshes/Battery_Handle_(1).stl"/>
      </geometry>
    </collision>
    <inertial name="link:Battery_Handle_(1)_inertial">
      <mass value="0.10790176"/>
      <inertia ixx="0.00029602912" iyy="1.068651e-05" izz="0.00029582985" ixy="0" ixz="0" iyz="0"/>
      <origin xyz="0.0054174965 -0.043695143 -0.020000001" rpy="0 0 0"/>
    </inertial>
  </link>
  <joint name="joint:frame_imu_site" type="fixed">
    <origin xyz="0.044814957 -0.07901795 -0.045823042" rpy="1.5707963 -1.5596879 1.5707963"/>
    <parent link="link:Comp_Holder_(1)"/>
    <child link="link:imu_(1)"/>
  </joint>
  <link name="link:imu_(1)">
    <visual name="link:imu_(1)_visual">
      <origin xyz="0 0 0" rpy="0 0 0"/>
      <geometry name="link:imu_(1)_geometry">
        <mesh filename="meshes/imu_(1).stl"/>
      </geometry>
      <material name="link:imu_(1)_material">
        <color rgba="0.61568627 0.81176471 0.92941176 1"/>
      </material>
    </visual>
    <collision name="link:imu_(1).collision">
      <origin xyz="0 0 0" rpy="0 0 0"/>
      <geometry name="link:imu_(1)_collision_geometry">
        <mesh filename="meshes/imu_(1).stl"/>
      </geometry>
    </collision>
    <inertial name="link:imu_(1)_inertial">
      <mass value="0.0057"/>
      <inertia ixx="1e-06" iyy="1.168665e-06" izz="1.5351984e-06" ixy="0" ixz="0" iyz="0"/>
      <origin xyz="0.014736918 -0.012 0.003" rpy="0 0 0"/>
    </inertial>
  </link>
  <joint name="joint:dof_lcd" type="fixed">
    <origin xyz="-0.023613593 -0.02195 -0.104" rpy="-1.5707963 0 0"/>
    <parent link="link:LOCKED_Middle_Cover_(1)"/>
    <child link="link:7inlcd_(1)"/>
  </joint>
  <link name="link:7inlcd_(1)">
    <visual name="link:7inlcd_(1)_visual">
      <origin xyz="0 0 0" rpy="0 0 0"/>
      <geometry name="link:7inlcd_(1)_geometry">
        <mesh filename="meshes/7inlcd_(1).stl"/>
      </geometry>
      <material name="link:7inlcd_(1)_material">
        <color rgba="0.64705882 0.64705882 0.64705882 1"/>
      </material>
    </visual>
    <collision name="link:7inlcd_(1).collision">
      <origin xyz="0 0 0" rpy="0 0 0"/>
      <geometry name="link:7inlcd_(1)_collision_geometry">
        <mesh filename="meshes/7inlcd_(1).stl"/>
      </geometry>
    </collision>
    <inertial name="link:7inlcd_(1)_inertial">
      <mass value="0.555"/>
      <inertia ixx="0.00041235478" iyy="0.0010111256" izz="0.0011929477" ixy="-5.1565927e-06" ixz="-6.8876144e-05" iyz="-1.3295631e-05"/>
      <origin xyz="0.085012732 -0.043015155 0.0048079728" rpy="0 0 0"/>
    </inertial>
  </link>
  <joint name="joint:dof_front_head" type="fixed">
    <origin xyz="-0.033668593 -0.0179 -0.1225" rpy="-1.5707963 0 0"/>
    <parent link="link:LOCKED_Middle_Cover_(1)"/>
    <child link="link:front_cover_(1)"/>
  </joint>
  <link name="link:front_cover_(1)">
    <visual name="link:front_cover_(1)_visual">
      <origin xyz="0 0 0" rpy="0 0 0"/>
      <geometry name="link:front_cover_(1)_geometry">
        <mesh filename="meshes/front_cover_(1).stl"/>
      </geometry>
      <material name="link:front_cover_(1)_material">
        <color rgba="0.2627451 0.28235294 0.30196078 1"/>
      </material>
    </visual>
    <collision name="link:front_cover_(1).collision">
      <origin xyz="0 0 0" rpy="0 0 0"/>
      <geometry name="link:front_cover_(1)_collision_geometry">
        <mesh filename="meshes/front_cover_(1).stl"/>
      </geometry>
    </collision>
    <inertial name="link:front_cover_(1)_inertial">
      <mass value="0.092631052"/>
      <inertia ixx="0.00029269163" iyy="0.00038693647" izz="0.00067280029" ixy="0" ixz="0" iyz="-2.4958263e-06"/>
      <origin xyz="0.087496646 -0.044617667 -0.011757344" rpy="0 0 0"/>
    </inertial>
  </link>
  <joint name="joint:dof_left_shoulder_pitch_03" type="revolute">
    <origin xyz="0 0 -0.042" rpy="0 0 -1.5707963"/>
    <parent link="link:RS03_(4)"/>
    <child link="link:KC-C-104L_PitchHardstopDriven_(1)"/>
    <limit effort="60" velocity="6.283" lower="-1.0471976" upper="3.4906585"/>
    <axis xyz="0 0 1"/>
  </joint>
  <link name="link:KC-C-104L_PitchHardstopDriven_(1)">
    <visual name="link:KC-C-104L_PitchHardstopDriven_(1)_visual">
      <origin xyz="0 0 0" rpy="0 0 0"/>
      <geometry name="link:KC-C-104L_PitchHardstopDriven_(1)_geometry">
        <mesh filename="meshes/KC-C-104L_PitchHardstopDriven_(1).stl"/>
      </geometry>
      <material name="link:KC-C-104L_PitchHardstopDriven_(1)_material">
        <color rgba="0.2627451 0.28235294 0.30196078 1"/>
      </material>
    </visual>
    <collision name="link:KC-C-104L_PitchHardstopDriven_(1).collision">
      <origin xyz="0 0 0" rpy="0 0 0"/>
      <geometry name="link:KC-C-104L_PitchHardstopDriven_(1)_collision_geometry">
        <mesh filename="meshes/KC-C-104L_PitchHardstopDriven_(1).stl"/>
      </geometry>
    </collision>
    <inertial name="link:KC-C-104L_PitchHardstopDriven_(1)_inertial">
      <mass value="0.020105633"/>
      <inertia ixx="4.3216372e-06" iyy="3.7451305e-06" izz="7.9654018e-06" ixy="1.6836283e-06" ixz="0" iyz="0"/>
      <origin xyz="-0.0053409868 0.0063958873 -0.00275" rpy="0 0 0"/>
    </inertial>
  </link>
  <joint name="joint:fixed_left03_hrdstop" type="fixed">
    <origin xyz="0 0 -0.042" rpy="0 0 -1.5707963"/>
    <parent link="link:RS03_(4)"/>
    <child link="link:KC-C-103L_PitchHardstopStatic_(1)"/>
  </joint>
  <link name="link:KC-C-103L_PitchHardstopStatic_(1)">
    <visual name="link:KC-C-103L_PitchHardstopStatic_(1)_visual">
      <origin xyz="0 0 0" rpy="0 0 0"/>
      <geometry name="link:KC-C-103L_PitchHardstopStatic_(1)_geometry">
        <mesh filename="meshes/KC-C-103L_PitchHardstopStatic_(1).stl"/>
      </geometry>
      <material name="link:KC-C-103L_PitchHardstopStatic_(1)_material">
        <color rgba="0.2627451 0.28235294 0.30196078 1"/>
      </material>
    </visual>
    <collision name="link:KC-C-103L_PitchHardstopStatic_(1).collision">
      <origin xyz="0 0 0" rpy="0 0 0"/>
      <geometry name="link:KC-C-103L_PitchHardstopStatic_(1)_collision_geometry">
        <mesh filename="meshes/KC-C-103L_PitchHardstopStatic_(1).stl"/>
      </geometry>
    </collision>
    <inertial name="link:KC-C-103L_PitchHardstopStatic_(1)_inertial">
      <mass value="0.014930382"/>
      <inertia ixx="2.0594563e-06" iyy="1e-06" izz="2.6591859e-06" ixy="0" ixz="0" iyz="0"/>
      <origin xyz="0.035720597 0.00010513232 -0.0019624697" rpy="0 0 0"/>
    </inertial>
  </link>
  <joint name="joint:dof_back_top" type="fixed">
    <origin xyz="0.132 0 0.13582828" rpy="0 0 0"/>
    <parent link="link:Torso_Inside_(1)"/>
    <child link="link:top_cover_(1)"/>
  </joint>
  <link name="link:top_cover_(1)">
    <visual name="link:top_cover_(1)_visual">
      <origin xyz="0 0 0" rpy="0 0 0"/>
      <geometry name="link:top_cover_(1)_geometry">
        <mesh filename="meshes/top_cover_(1).stl"/>
      </geometry>
      <material name="link:top_cover_(1)_material">
        <color rgba="0.2627451 0.28235294 0.30196078 1"/>
      </material>
    </visual>
    <collision name="link:top_cover_(1).collision">
      <origin xyz="0 0 0" rpy="0 0 0"/>
      <geometry name="link:top_cover_(1)_collision_geometry">
        <mesh filename="meshes/top_cover_(1).stl"/>
      </geometry>
    </collision>
    <inertial name="link:top_cover_(1)_inertial">
      <mass value="0.067020771"/>
      <inertia ixx="6.9688928e-05" iyy="0.00012311092" izz="0.0001927585" ixy="0" ixz="0" iyz="0"/>
      <origin xyz="-0.066 -0.04965916 0.0037822994" rpy="0 0 0"/>
    </inertial>
  </link>
  <joint name="joint:dof_front_btm" type="fixed">
    <origin xyz="0.13218648 0.027103991 0" rpy="0 0 0"/>
    <parent link="link:Torso_Inside_(1)"/>
    <child link="link:front_bottom_cover_(1)"/>
  </joint>
  <link name="link:front_bottom_cover_(1)">
    <visual name="link:front_bottom_cover_(1)_visual">
      <origin xyz="0 0 0" rpy="0 0 0"/>
      <geometry name="link:front_bottom_cover_(1)_geometry">
        <mesh filename="meshes/front_bottom_cover_(1).stl"/>
      </geometry>
      <material name="link:front_bottom_cover_(1)_material">
        <color rgba="0.2627451 0.28235294 0.30196078 1"/>
      </material>
    </visual>
    <collision name="link:front_bottom_cover_(1).collision">
      <origin xyz="0 0 0" rpy="0 0 0"/>
      <geometry name="link:front_bottom_cover_(1)_collision_geometry">
        <mesh filename="meshes/front_bottom_cover_(1).stl"/>
      </geometry>
    </collision>
    <inertial name="link:front_bottom_cover_(1)_inertial">
      <mass value="0.15340635"/>
      <inertia ixx="0.00078013528" iyy="0.00027703925" izz="0.001054012" ixy="0" ixz="0" iyz="-3.4681412e-05"/>
      <origin xyz="-0.066175623 0.11769776 0.0020759295" rpy="0 0 0"/>
    </inertial>
  </link>
  <joint name="joint:dof_right_hip_pitch_04" type="revolute">
    <origin xyz="0 0 0.039" rpy="3.1415927 0 0"/>
    <parent link="link:RS04_(2)"/>
    <child link="link:KC-D-102R_R_Hip_Yoke_Drive_(1)"/>
    <limit effort="120" velocity="6.283" lower="-2.2165682" upper="1.0471976"/>
    <axis xyz="0 0 1"/>
  </joint>
  <link name="link:KC-D-102R_R_Hip_Yoke_Drive_(1)">
    <visual name="link:KC-D-102R_R_Hip_Yoke_Drive_(1)_visual">
      <origin xyz="0 0 0" rpy="0 0 0"/>
      <geometry name="link:KC-D-102R_R_Hip_Yoke_Drive_(1)_geometry">
        <mesh filename="meshes/KC-D-102R_R_Hip_Yoke_Drive_(1).stl"/>
      </geometry>
      <material name="link:KC-D-102R_R_Hip_Yoke_Drive_(1)_material">
        <color rgba="0.2627451 0.28235294 0.30196078 1"/>
      </material>
    </visual>
    <collision name="link:KC-D-102R_R_Hip_Yoke_Drive_(1).collision">
      <origin xyz="0 0 0" rpy="0 0 0"/>
      <geometry name="link:KC-D-102R_R_Hip_Yoke_Drive_(1)_collision_geometry">
        <mesh filename="meshes/KC-D-102R_R_Hip_Yoke_Drive_(1).stl"/>
      </geometry>
    </collision>
    <inertial name="link:KC-D-102R_R_Hip_Yoke_Drive_(1)_inertial">
      <mass value="0.37010673"/>
      <inertia ixx="0.00061835551" iyy="0.0005116577" izz="0.00057747641" ixy="-9.8354096e-05" ixz="-0.0001293346" iyz="-0.00010750725"/>
      <origin xyz="-0.024812988 -0.0048137679 -0.037959889" rpy="0 0 0"/>
    </inertial>
  </link>
  <joint name="joint:fix_righthippitch_hardstop2_vis" type="fixed">
    <origin xyz="0 0 0.039" rpy="0 0 1.5707963"/>
    <parent link="link:RS04_(2)"/>
    <child link="link:KC-D-104R_Hip_Yoke_Hardstop_vis_(1)"/>
  </joint>
  <link name="link:KC-D-104R_Hip_Yoke_Hardstop_vis_(1)">
    <visual name="link:KC-D-104R_Hip_Yoke_Hardstop_vis_(1)_visual">
      <origin xyz="0 0 0" rpy="0 0 0"/>
      <geometry name="link:KC-D-104R_Hip_Yoke_Hardstop_vis_(1)_geometry">
        <mesh filename="meshes/KC-D-104R_Hip_Yoke_Hardstop_vis_(1).stl"/>
      </geometry>
      <material name="link:KC-D-104R_Hip_Yoke_Hardstop_vis_(1)_material">
        <color rgba="0.91764706 0.91764706 0.91764706 1"/>
      </material>
    </visual>
    <collision name="link:KC-D-104R_Hip_Yoke_Hardstop_vis_(1).collision">
      <origin xyz="0 0 0" rpy="0 0 0"/>
      <geometry name="link:KC-D-104R_Hip_Yoke_Hardstop_vis_(1)_collision_geometry">
        <mesh filename="meshes/KC-D-104R_Hip_Yoke_Hardstop_vis_(1).stl"/>
      </geometry>
    </collision>
    <inertial name="link:KC-D-104R_Hip_Yoke_Hardstop_vis_(1)_inertial">
      <mass value="0.055070391"/>
      <inertia ixx="4.7072934e-05" iyy="5.4538015e-05" izz="0.00010101832" ixy="-1.5505009e-05" ixz="0" iyz="0"/>
      <origin xyz="0.011195052 -0.018076125 0.0039647007" rpy="0 0 0"/>
    </inertial>
  </link>
  <joint name="joint:dof_left_hip_pitch_04" type="revolute">
    <origin xyz="0 0 0.039" rpy="3.1415927 0 0"/>
    <parent link="link:RS04_(4)"/>
    <child link="link:KC-D-102L_L_Hip_Yoke_Drive_(1)"/>
    <limit effort="120" velocity="6.283" lower="-1.0471976" upper="2.2165682"/>
    <axis xyz="0 0 1"/>
  </joint>
  <link name="link:KC-D-102L_L_Hip_Yoke_Drive_(1)">
    <visual name="link:KC-D-102L_L_Hip_Yoke_Drive_(1)_visual">
      <origin xyz="0 0 0" rpy="0 0 0"/>
      <geometry name="link:KC-D-102L_L_Hip_Yoke_Drive_(1)_geometry">
        <mesh filename="meshes/KC-D-102L_L_Hip_Yoke_Drive_(1).stl"/>
      </geometry>
      <material name="link:KC-D-102L_L_Hip_Yoke_Drive_(1)_material">
        <color rgba="0.2627451 0.28235294 0.30196078 1"/>
      </material>
    </visual>
    <collision name="link:KC-D-102L_L_Hip_Yoke_Drive_(1).collision">
      <origin xyz="0 0 0" rpy="0 0 0"/>
      <geometry name="link:KC-D-102L_L_Hip_Yoke_Drive_(1)_collision_geometry">
        <mesh filename="meshes/KC-D-102L_L_Hip_Yoke_Drive_(1).stl"/>
      </geometry>
    </collision>
    <inertial name="link:KC-D-102L_L_Hip_Yoke_Drive_(1)_inertial">
      <mass value="0.3701026"/>
      <inertia ixx="0.00061834711" iyy="0.00051165257" izz="0.00057746413" ixy="9.8358257e-05" ixz="-0.00012933314" iyz="0.0001075092"/>
      <origin xyz="-0.024813339 0.0048133129 -0.037959995" rpy="0 0 0"/>
    </inertial>
  </link>
  <joint name="joint:fix_lefthippitch_hardstop2_vis" type="fixed">
    <origin xyz="0 0 0.039" rpy="0 0 0"/>
    <parent link="link:RS04_(4)"/>
    <child link="link:KC-D-104_L_Hip_Yoke_Hardstop_vis_(1)"/>
  </joint>
  <link name="link:KC-D-104_L_Hip_Yoke_Hardstop_vis_(1)">
    <visual name="link:KC-D-104_L_Hip_Yoke_Hardstop_vis_(1)_visual">
      <origin xyz="0 0 0" rpy="0 0 0"/>
      <geometry name="link:KC-D-104_L_Hip_Yoke_Hardstop_vis_(1)_geometry">
        <mesh filename="meshes/KC-D-104_L_Hip_Yoke_Hardstop_vis_(1).stl"/>
      </geometry>
      <material name="link:KC-D-104_L_Hip_Yoke_Hardstop_vis_(1)_material">
        <color rgba="0.91764706 0.91764706 0.91764706 1"/>
      </material>
    </visual>
    <collision name="link:KC-D-104_L_Hip_Yoke_Hardstop_vis_(1).collision">
      <origin xyz="0 0 0" rpy="0 0 0"/>
      <geometry name="link:KC-D-104_L_Hip_Yoke_Hardstop_vis_(1)_collision_geometry">
        <mesh filename="meshes/KC-D-104_L_Hip_Yoke_Hardstop_vis_(1).stl"/>
      </geometry>
    </collision>
    <inertial name="link:KC-D-104_L_Hip_Yoke_Hardstop_vis_(1)_inertial">
      <mass value="0.055070391"/>
      <inertia ixx="5.4538013e-05" iyy="4.7072934e-05" izz="0.00010101832" ixy="-1.5505009e-05" ixz="0" iyz="0"/>
      <origin xyz="0.018076126 -0.011195052 0.0039647007" rpy="0 0 0"/>
    </inertial>
  </link>
  <joint name="joint:dof_right_shoulder_roll_03" type="revolute">
    <origin xyz="-0.023727239 0.0086360086 0.0745" rpy="0.34906585 1.5707963 0"/>
    <parent link="link:KC-C-101R_ShldYokeDrive_(1)"/>
    <child link="link:RS03_(5)"/>
    <limit effort="60" velocity="6.283" lower="-1.6580628" upper="0.38397244"/>
    <axis xyz="0 0 -1"/>
  </joint>
  <link name="link:RS03_(5)">
    <visual name="link:RS03_(5)_visual">
      <origin xyz="0 0 0" rpy="0 0 0"/>
      <geometry name="link:RS03_(5)_geometry">
        <mesh filename="meshes/RS03_(5).stl"/>
      </geometry>
      <material name="link:RS03_(5)_material">
        <color rgba="0.2627451 0.28235294 0.30196078 1"/>
      </material>
    </visual>
    <collision name="link:RS03_(5).collision">
      <origin xyz="0 0 0" rpy="0 0 0"/>
      <geometry name="link:RS03_(5)_collision_geometry">
        <mesh filename="meshes/RS03_(5).stl"/>
      </geometry>
    </collision>
    <inertial name="link:RS03_(5)_inertial">
      <mass value="0.88"/>
      <inertia ixx="0.00065607101" iyy="0.00065607101" izz="0.00088708736" ixy="0" ixz="0" iyz="0"/>
      <origin xyz="0 0 0.027267932" rpy="0 0 0"/>
    </inertial>
  </link>
  <joint name="joint:dof_right_idleShlr" type="fixed">
    <origin xyz="0.018907874 -0.054769903 0.015" rpy="-2.7925268 1.5707963 0"/>
    <parent link="link:KC-C-101R_ShldYokeDrive_(1)"/>
    <child link="link:KC-C-102R_ShldYokeIdle_(1)"/>
  </joint>
  <link name="link:KC-C-102R_ShldYokeIdle_(1)">
    <visual name="link:KC-C-102R_ShldYokeIdle_(1)_visual">
      <origin xyz="0 0 0" rpy="0 0 0"/>
      <geometry name="link:KC-C-102R_ShldYokeIdle_(1)_geometry">
        <mesh filename="meshes/KC-C-102R_ShldYokeIdle_(1).stl"/>
      </geometry>
      <material name="link:KC-C-102R_ShldYokeIdle_(1)_material">
        <color rgba="0.2627451 0.28235294 0.30196078 1"/>
      </material>
    </visual>
    <collision name="link:KC-C-102R_ShldYokeIdle_(1).collision">
      <origin xyz="0 0 0" rpy="0 0 0"/>
      <geometry name="link:KC-C-102R_ShldYokeIdle_(1)_collision_geometry">
        <mesh filename="meshes/KC-C-102R_ShldYokeIdle_(1).stl"/>
      </geometry>
    </collision>
    <inertial name="link:KC-C-102R_ShldYokeIdle_(1)_inertial">
      <mass value="0.11166005"/>
      <inertia ixx="0.00011293083" iyy="0.00012163991" izz="0.00022813133" ixy="0" ixz="-1.2168997e-06" iyz="0"/>
      <origin xyz="-0.034775072 -0.044822052 -0.011364281" rpy="0 0 0"/>
    </inertial>
  </link>
  <joint name="joint:fixed_battFront" type="fixed">
    <origin xyz="-0.0445 0.0115 -0.02625" rpy="0 0 0"/>
    <parent link="link:Battery_Cover_(1)"/>
    <child link="link:Battery_Plate_(1)"/>
  </joint>
  <link name="link:Battery_Plate_(1)">
    <visual name="link:Battery_Plate_(1)_visual">
      <origin xyz="0 0 0" rpy="0 0 0"/>
      <geometry name="link:Battery_Plate_(1)_geometry">
        <mesh filename="meshes/Battery_Plate_(1).stl"/>
      </geometry>
      <material name="link:Battery_Plate_(1)_material">
        <color rgba="0.2627451 0.28235294 0.30196078 1"/>
      </material>
    </visual>
    <collision name="link:Battery_Plate_(1).collision">
      <origin xyz="0 0 0" rpy="0 0 0"/>
      <geometry name="link:Battery_Plate_(1)_collision_geometry">
        <mesh filename="meshes/Battery_Plate_(1).stl"/>
      </geometry>
    </collision>
    <inertial name="link:Battery_Plate_(1)_inertial">
      <mass value="0.17427956"/>
      <inertia ixx="0.00090779665" iyy="0.00033693327" izz="0.0012446137" ixy="0" ixz="0" iyz="0"/>
      <origin xyz="0 -0.12131232 -0.001" rpy="0 0 0"/>
    </inertial>
  </link>
  <joint name="joint:fixed_left_Shldrhrdstp" type="fixed">
    <origin xyz="0 0 -0.0055" rpy="0 0 0"/>
    <parent link="link:KC-C-104L_PitchHardstopDriven_(1)"/>
    <child link="link:KC-C-101L_ShldYokeDrive_(2)"/>
  </joint>
  <link name="link:KC-C-101L_ShldYokeDrive_(2)">
    <visual name="link:KC-C-101L_ShldYokeDrive_(2)_visual">
      <origin xyz="0 0 0" rpy="0 0 0"/>
      <geometry name="link:KC-C-101L_ShldYokeDrive_(2)_geometry">
        <mesh filename="meshes/KC-C-101L_ShldYokeDrive_(2).stl"/>
      </geometry>
      <material name="link:KC-C-101L_ShldYokeDrive_(2)_material">
        <color rgba="0.2627451 0.28235294 0.30196078 1"/>
      </material>
    </visual>
    <collision name="link:KC-C-101L_ShldYokeDrive_(2).collision">
      <origin xyz="0 0 0" rpy="0 0 0"/>
      <geometry name="link:KC-C-101L_ShldYokeDrive_(2)_collision_geometry">
        <mesh filename="meshes/KC-C-101L_ShldYokeDrive_(2).stl"/>
      </geometry>
    </collision>
    <inertial name="link:KC-C-101L_ShldYokeDrive_(2)_inertial">
      <mass value="0.40625687"/>
      <inertia ixx="0.00084685439" iyy="0.00069254722" izz="0.00066178759" ixy="3.5429382e-05" ixz="-0.00018387057" iyz="4.9822326e-06"/>
      <origin xyz="-0.025317843 -0.004218818 -0.04369014" rpy="0 0 0"/>
    </inertial>
  </link>
  <joint name="joint:dof_right_hip_roll_03" type="revolute">
    <origin xyz="-0.02925 -0.03 -0.071" rpy="3.1415927 -1.5707963 0"/>
    <parent link="link:KC-D-102R_R_Hip_Yoke_Drive_(1)"/>
    <child link="link:RS03_(2)"/>
    <limit effort="60" velocity="6.283" lower="-2.268928" upper="0.20943951"/>
    <axis xyz="0 0 -1"/>
  </joint>
  <link name="link:RS03_(2)">
    <visual name="link:RS03_(2)_visual">
      <origin xyz="0 0 0" rpy="0 0 0"/>
      <geometry name="link:RS03_(2)_geometry">
        <mesh filename="meshes/RS03_(2).stl"/>
      </geometry>
      <material name="link:RS03_(2)_material">
        <color rgba="0.2627451 0.28235294 0.30196078 1"/>
      </material>
    </visual>
    <collision name="link:RS03_(2).collision">
      <origin xyz="0 0 0" rpy="0 0 0"/>
      <geometry name="link:RS03_(2)_collision_geometry">
        <mesh filename="meshes/RS03_(2).stl"/>
      </geometry>
    </collision>
    <inertial name="link:RS03_(2)_inertial">
      <mass value="0.88"/>
      <inertia ixx="0.00065607101" iyy="0.00065607101" izz="0.00088708736" ixy="0" ixz="0" iyz="0"/>
      <origin xyz="0 0 0.027267932" rpy="0 0 0"/>
    </inertial>
  </link>
  <joint name="joint:dof_hipyoke_right" type="fixed">
    <origin xyz="0.0255 0.045355239 -0.02" rpy="0 -1.5707963 0"/>
    <parent link="link:KC-D-102R_R_Hip_Yoke_Drive_(1)"/>
    <child link="link:KC-D-103R_R_Hip_Yoke_Idle_(1)"/>
  </joint>
  <link name="link:KC-D-103R_R_Hip_Yoke_Idle_(1)">
    <visual name="link:KC-D-103R_R_Hip_Yoke_Idle_(1)_visual">
      <origin xyz="0 0 0" rpy="0 0 0"/>
      <geometry name="link:KC-D-103R_R_Hip_Yoke_Idle_(1)_geometry">
        <mesh filename="meshes/KC-D-103R_R_Hip_Yoke_Idle_(1).stl"/>
      </geometry>
      <material name="link:KC-D-103R_R_Hip_Yoke_Idle_(1)_material">
        <color rgba="0.2627451 0.28235294 0.30196078 1"/>
      </material>
    </visual>
    <collision name="link:KC-D-103R_R_Hip_Yoke_Idle_(1).collision">
      <origin xyz="0 0 0" rpy="0 0 0"/>
      <geometry name="link:KC-D-103R_R_Hip_Yoke_Idle_(1)_collision_geometry">
        <mesh filename="meshes/KC-D-103R_R_Hip_Yoke_Idle_(1).stl"/>
      </geometry>
    </collision>
    <inertial name="link:KC-D-103R_R_Hip_Yoke_Idle_(1)_inertial">
      <mass value="0.14948241"/>
      <inertia ixx="0.00015434767" iyy="0.00011856968" izz="0.00024715073" ixy="-4.7228401e-05" ixz="-4.2464441e-06" iyz="-8.5050212e-06"/>
      <origin xyz="-0.021170078 -0.048558138 -0.019398147" rpy="0 0 0"/>
    </inertial>
  </link>
  <joint name="joint:fix_righthippitch_hardstop" type="fixed">
    <origin xyz="-0.05121878 0.0017885992 -0.009" rpy="3.1415927 0 0"/>
    <parent link="link:KC-D-102R_R_Hip_Yoke_Drive_(1)"/>
    <child link="link:KC-D-105R_HipYokeHardstopTooth_vis_(1)"/>
  </joint>
  <link name="link:KC-D-105R_HipYokeHardstopTooth_vis_(1)">
    <visual name="link:KC-D-105R_HipYokeHardstopTooth_vis_(1)_visual">
      <origin xyz="0 0 0" rpy="0 0 0"/>
      <geometry name="link:KC-D-105R_HipYokeHardstopTooth_vis_(1)_geometry">
        <mesh filename="meshes/KC-D-105R_HipYokeHardstopTooth_vis_(1).stl"/>
      </geometry>
      <material name="link:KC-D-105R_HipYokeHardstopTooth_vis_(1)_material">
        <color rgba="0.91764706 0.91764706 0.91764706 1"/>
      </material>
    </visual>
    <collision name="link:KC-D-105R_HipYokeHardstopTooth_vis_(1).collision">
      <origin xyz="0 0 0" rpy="0 0 0"/>
      <geometry name="link:KC-D-105R_HipYokeHardstopTooth_vis_(1)_collision_geometry">
        <mesh filename="meshes/KC-D-105R_HipYokeHardstopTooth_vis_(1).stl"/>
      </geometry>
    </collision>
    <inertial name="link:KC-D-105R_HipYokeHardstopTooth_vis_(1)_inertial">
      <mass value="0.010838984"/>
      <inertia ixx="1e-06" iyy="1e-06" izz="1e-06" ixy="0" ixz="0" iyz="0"/>
      <origin xyz="0.0030896161 0.00010789177 -0.003720621" rpy="0 0 0"/>
    </inertial>
  </link>
  <joint name="joint:dof_left_hip_roll_03" type="revolute">
    <origin xyz="-0.02925 0.03 -0.071" rpy="0 1.5707963 0"/>
    <parent link="link:KC-D-102L_L_Hip_Yoke_Drive_(1)"/>
    <child link="link:RS03_(6)"/>
    <limit effort="60" velocity="6.283" lower="-0.20943951" upper="2.268928"/>
    <axis xyz="0 0 -1"/>
  </joint>
  <link name="link:RS03_(6)">
    <visual name="link:RS03_(6)_visual">
      <origin xyz="0 0 0" rpy="0 0 0"/>
      <geometry name="link:RS03_(6)_geometry">
        <mesh filename="meshes/RS03_(6).stl"/>
      </geometry>
      <material name="link:RS03_(6)_material">
        <color rgba="0.2627451 0.28235294 0.30196078 1"/>
      </material>
    </visual>
    <collision name="link:RS03_(6).collision">
      <origin xyz="0 0 0" rpy="0 0 0"/>
      <geometry name="link:RS03_(6)_collision_geometry">
        <mesh filename="meshes/RS03_(6).stl"/>
      </geometry>
    </collision>
    <inertial name="link:RS03_(6)_inertial">
      <mass value="0.88"/>
      <inertia ixx="0.00065607101" iyy="0.00065607101" izz="0.00088708736" ixy="0" ixz="0" iyz="0"/>
      <origin xyz="0 0 0.027267932" rpy="0 0 0"/>
    </inertial>
  </link>
  <joint name="joint:fix_lefthippitch_hardstop" type="fixed">
    <origin xyz="-0.05121878 -0.0017885992 -0.009" rpy="3.1415927 0 0"/>
    <parent link="link:KC-D-102L_L_Hip_Yoke_Drive_(1)"/>
    <child link="link:KC-D-105L_HipYokeHardstopTooth_vis_(1)"/>
  </joint>
  <link name="link:KC-D-105L_HipYokeHardstopTooth_vis_(1)">
    <visual name="link:KC-D-105L_HipYokeHardstopTooth_vis_(1)_visual">
      <origin xyz="0 0 0" rpy="0 0 0"/>
      <geometry name="link:KC-D-105L_HipYokeHardstopTooth_vis_(1)_geometry">
        <mesh filename="meshes/KC-D-105L_HipYokeHardstopTooth_vis_(1).stl"/>
      </geometry>
      <material name="link:KC-D-105L_HipYokeHardstopTooth_vis_(1)_material">
        <color rgba="0.91764706 0.91764706 0.91764706 1"/>
      </material>
    </visual>
    <collision name="link:KC-D-105L_HipYokeHardstopTooth_vis_(1).collision">
      <origin xyz="0 0 0" rpy="0 0 0"/>
      <geometry name="link:KC-D-105L_HipYokeHardstopTooth_vis_(1)_collision_geometry">
        <mesh filename="meshes/KC-D-105L_HipYokeHardstopTooth_vis_(1).stl"/>
      </geometry>
    </collision>
    <inertial name="link:KC-D-105L_HipYokeHardstopTooth_vis_(1)_inertial">
      <mass value="0.010838984"/>
      <inertia ixx="1e-06" iyy="1e-06" izz="1e-06" ixy="0" ixz="0" iyz="0"/>
      <origin xyz="0.0030896161 -0.00010789177 -0.003720621" rpy="0 0 0"/>
    </inertial>
  </link>
  <joint name="joint:dof_hipyoke_left" type="fixed">
    <origin xyz="0.0255 -0.045355239 -0.02" rpy="3.1415927 1.5707963 0"/>
    <parent link="link:KC-D-102L_L_Hip_Yoke_Drive_(1)"/>
    <child link="link:KC-D-103L_L_Hip_Yoke_Idle_(1)"/>
  </joint>
  <link name="link:KC-D-103L_L_Hip_Yoke_Idle_(1)">
    <visual name="link:KC-D-103L_L_Hip_Yoke_Idle_(1)_visual">
      <origin xyz="0 0 0" rpy="0 0 0"/>
      <geometry name="link:KC-D-103L_L_Hip_Yoke_Idle_(1)_geometry">
        <mesh filename="meshes/KC-D-103L_L_Hip_Yoke_Idle_(1).stl"/>
      </geometry>
      <material name="link:KC-D-103L_L_Hip_Yoke_Idle_(1)_material">
        <color rgba="0.2627451 0.28235294 0.30196078 1"/>
      </material>
    </visual>
    <collision name="link:KC-D-103L_L_Hip_Yoke_Idle_(1).collision">
      <origin xyz="0 0 0" rpy="0 0 0"/>
      <geometry name="link:KC-D-103L_L_Hip_Yoke_Idle_(1)_collision_geometry">
        <mesh filename="meshes/KC-D-103L_L_Hip_Yoke_Idle_(1).stl"/>
      </geometry>
    </collision>
    <inertial name="link:KC-D-103L_L_Hip_Yoke_Idle_(1)_inertial">
      <mass value="0.14948211"/>
      <inertia ixx="0.00015434714" iyy="0.00011857035" izz="0.00024714935" ixy="4.7228544e-05" ixz="4.2464533e-06" iyz="-8.5052217e-06"/>
      <origin xyz="0.021170143 -0.048558022 -0.019398155" rpy="0 0 0"/>
    </inertial>
  </link>
  <joint name="joint:dof_right_fixshldr03" type="fixed">
    <origin xyz="0 0 0.0025" rpy="3.1415927 0 0"/>
    <parent link="link:RS03_(5)"/>
    <child link="link:KC-C-201R_UpBicepDrive_(1)"/>
  </joint>
  <link name="link:KC-C-201R_UpBicepDrive_(1)">
    <visual name="link:KC-C-201R_UpBicepDrive_(1)_visual">
      <origin xyz="0 0 0" rpy="0 0 0"/>
      <geometry name="link:KC-C-201R_UpBicepDrive_(1)_geometry">
        <mesh filename="meshes/KC-C-201R_UpBicepDrive_(1).stl"/>
      </geometry>
      <material name="link:KC-C-201R_UpBicepDrive_(1)_material">
        <color rgba="0.2627451 0.28235294 0.30196078 1"/>
      </material>
    </visual>
    <collision name="link:KC-C-201R_UpBicepDrive_(1).collision">
      <origin xyz="0 0 0" rpy="0 0 0"/>
      <geometry name="link:KC-C-201R_UpBicepDrive_(1)_collision_geometry">
        <mesh filename="meshes/KC-C-201R_UpBicepDrive_(1).stl"/>
      </geometry>
    </collision>
    <inertial name="link:KC-C-201R_UpBicepDrive_(1)_inertial">
      <mass value="0.29073373"/>
      <inertia ixx="0.001296495" iyy="0.00047023589" izz="0.0015548806" ixy="-7.6135753e-05" ixz="6.161579e-06" iyz="-3.6255915e-05"/>
      <origin xyz="-0.0074856549 -0.061913646 -0.01064394" rpy="0 0 0"/>
    </inertial>
  </link>
  <joint name="joint:fixed_right_Shldrbearing1" type="fixed">
    <origin xyz="-0.0595 -0.045 -0.014" rpy="0 0 0"/>
    <parent link="link:KC-C-102R_ShldYokeIdle_(1)"/>
    <child link="link:Bearing_(1)"/>
  </joint>
  <link name="link:Bearing_(1)">
    <visual name="link:Bearing_(1)_visual">
      <origin xyz="0 0 0" rpy="0 0 0"/>
      <geometry name="link:Bearing_(1)_geometry">
        <mesh filename="meshes/Bearing_(1).stl"/>
      </geometry>
      <material name="link:Bearing_(1)_material">
        <color rgba="0.2627451 0.28235294 0.30196078 1"/>
      </material>
    </visual>
    <collision name="link:Bearing_(1).collision">
      <origin xyz="0 0 0" rpy="0 0 0"/>
      <geometry name="link:Bearing_(1)_collision_geometry">
        <mesh filename="meshes/Bearing_(1).stl"/>
      </geometry>
    </collision>
    <inertial name="link:Bearing_(1)_inertial">
      <mass value="0.03284554"/>
      <inertia ixx="4.2274947e-06" iyy="4.2274947e-06" izz="8.1867508e-06" ixy="0" ixz="0" iyz="0"/>
      <origin xyz="0 0 0" rpy="0 0 0"/>
    </inertial>
  </link>
  <joint name="joint:dof_left_shoulder_roll_03" type="revolute">
    <origin xyz="-0.02525 0 -0.0745" rpy="3.1415927 1.5707963 0"/>
    <parent link="link:KC-C-101L_ShldYokeDrive_(2)"/>
    <child link="link:RS03_(8)"/>
    <limit effort="60" velocity="6.283" lower="-0.38397244" upper="1.6580628"/>
    <axis xyz="0 0 1"/>
  </joint>
  <link name="link:RS03_(8)">
    <visual name="link:RS03_(8)_visual">
      <origin xyz="0 0 0" rpy="0 0 0"/>
      <geometry name="link:RS03_(8)_geometry">
        <mesh filename="meshes/RS03_(8).stl"/>
      </geometry>
      <material name="link:RS03_(8)_material">
        <color rgba="0.2627451 0.28235294 0.30196078 1"/>
      </material>
    </visual>
    <collision name="link:RS03_(8).collision">
      <origin xyz="0 0 0" rpy="0 0 0"/>
      <geometry name="link:RS03_(8)_collision_geometry">
        <mesh filename="meshes/RS03_(8).stl"/>
      </geometry>
    </collision>
    <inertial name="link:RS03_(8)_inertial">
      <mass value="0.88"/>
      <inertia ixx="0.00065607101" iyy="0.00065607101" izz="0.00088708736" ixy="0" ixz="0" iyz="0"/>
      <origin xyz="0 0 -0.027267932" rpy="0 0 0"/>
    </inertial>
  </link>
  <joint name="joint:dof_left_idleShlr" type="fixed">
    <origin xyz="0.0365 -0.04 -0.018" rpy="3.1415927 1.5707963 0"/>
    <parent link="link:KC-C-101L_ShldYokeDrive_(2)"/>
    <child link="link:KC-C-102L_ShldYokeIdle_(1)"/>
  </joint>
  <link name="link:KC-C-102L_ShldYokeIdle_(1)">
    <visual name="link:KC-C-102L_ShldYokeIdle_(1)_visual">
      <origin xyz="0 0 0" rpy="0 0 0"/>
      <geometry name="link:KC-C-102L_ShldYokeIdle_(1)_geometry">
        <mesh filename="meshes/KC-C-102L_ShldYokeIdle_(1).stl"/>
      </geometry>
      <material name="link:KC-C-102L_ShldYokeIdle_(1)_material">
        <color rgba="0.2627451 0.28235294 0.30196078 1"/>
      </material>
    </visual>
    <collision name="link:KC-C-102L_ShldYokeIdle_(1).collision">
      <origin xyz="0 0 0" rpy="0 0 0"/>
      <geometry name="link:KC-C-102L_ShldYokeIdle_(1)_collision_geometry">
        <mesh filename="meshes/KC-C-102L_ShldYokeIdle_(1).stl"/>
      </geometry>
    </collision>
    <inertial name="link:KC-C-102L_ShldYokeIdle_(1)_inertial">
      <mass value="0.11166394"/>
      <inertia ixx="0.00011293482" iyy="0.0001216442" izz="0.00022813924" ixy="0" ixz="1.2173175e-06" iyz="0"/>
      <origin xyz="0.031775796 -0.039821589 -0.011364187" rpy="0 0 0"/>
    </inertial>
  </link>
  <joint name="joint:dof_hiproll_upperthigh_right" type="fixed">
    <origin xyz="0 0 0.0566" rpy="0 0 0"/>
    <parent link="link:RS03_(2)"/>
    <child link="link:KC-D-201R_UpperThigh_Idle_(1)"/>
  </joint>
  <link name="link:KC-D-201R_UpperThigh_Idle_(1)">
    <visual name="link:KC-D-201R_UpperThigh_Idle_(1)_visual">
      <origin xyz="0 0 0" rpy="0 0 0"/>
      <geometry name="link:KC-D-201R_UpperThigh_Idle_(1)_geometry">
        <mesh filename="meshes/KC-D-201R_UpperThigh_Idle_(1).stl"/>
      </geometry>
      <material name="link:KC-D-201R_UpperThigh_Idle_(1)_material">
        <color rgba="0.2627451 0.28235294 0.30196078 1"/>
      </material>
    </visual>
    <collision name="link:KC-D-201R_UpperThigh_Idle_(1).collision">
      <origin xyz="0 0 0" rpy="0 0 0"/>
      <geometry name="link:KC-D-201R_UpperThigh_Idle_(1)_collision_geometry">
        <mesh filename="meshes/KC-D-201R_UpperThigh_Idle_(1).stl"/>
      </geometry>
    </collision>
    <inertial name="link:KC-D-201R_UpperThigh_Idle_(1)_inertial">
      <mass value="0.18071864"/>
      <inertia ixx="0.00059446592" iyy="0.00029472919" izz="0.00084154083" ixy="-4.536931e-06" ixz="0" iyz="-5.0687145e-05"/>
      <origin xyz="-0.0017002702 0.041044109 0.0052149719" rpy="0 0 0"/>
    </inertial>
  </link>
  <joint name="joint:dof_hiproll_upperthigh_left" type="fixed">
    <origin xyz="0 0 0.0566" rpy="0 0 0"/>
    <parent link="link:RS03_(6)"/>
    <child link="link:KC-D-201L_UpperThigh_Idle_(1)"/>
  </joint>
  <link name="link:KC-D-201L_UpperThigh_Idle_(1)">
    <visual name="link:KC-D-201L_UpperThigh_Idle_(1)_visual">
      <origin xyz="0 0 0" rpy="0 0 0"/>
      <geometry name="link:KC-D-201L_UpperThigh_Idle_(1)_geometry">
        <mesh filename="meshes/KC-D-201L_UpperThigh_Idle_(1).stl"/>
      </geometry>
      <material name="link:KC-D-201L_UpperThigh_Idle_(1)_material">
        <color rgba="0.2627451 0.28235294 0.30196078 1"/>
      </material>
    </visual>
    <collision name="link:KC-D-201L_UpperThigh_Idle_(1).collision">
      <origin xyz="0 0 0" rpy="0 0 0"/>
      <geometry name="link:KC-D-201L_UpperThigh_Idle_(1)_collision_geometry">
        <mesh filename="meshes/KC-D-201L_UpperThigh_Idle_(1).stl"/>
      </geometry>
    </collision>
    <inertial name="link:KC-D-201L_UpperThigh_Idle_(1)_inertial">
      <mass value="0.18070756"/>
      <inertia ixx="0.00059435879" iyy="0.00029470516" izz="0.00084142971" ixy="4.4601237e-06" ixz="0" iyz="-5.0678685e-05"/>
      <origin xyz="0.0017074254 0.041037626 0.0052146527" rpy="0 0 0"/>
    </inertial>
  </link>
  <joint name="joint:dof_right_upper_bicep_idle" type="fixed">
    <origin xyz="-0.0505 -0.0875 -0.0395" rpy="-3.1415927 0 0"/>
    <parent link="link:KC-C-201R_UpBicepDrive_(1)"/>
    <child link="link:KC-C-202R_UpBicepIdle_(1)"/>
  </joint>
  <link name="link:KC-C-202R_UpBicepIdle_(1)">
    <visual name="link:KC-C-202R_UpBicepIdle_(1)_visual">
      <origin xyz="0 0 0" rpy="0 0 0"/>
      <geometry name="link:KC-C-202R_UpBicepIdle_(1)_geometry">
        <mesh filename="meshes/KC-C-202R_UpBicepIdle_(1).stl"/>
      </geometry>
      <material name="link:KC-C-202R_UpBicepIdle_(1)_material">
        <color rgba="0.2627451 0.28235294 0.30196078 1"/>
      </material>
    </visual>
    <collision name="link:KC-C-202R_UpBicepIdle_(1).collision">
      <origin xyz="0 0 0" rpy="0 0 0"/>
      <geometry name="link:KC-C-202R_UpBicepIdle_(1)_collision_geometry">
        <mesh filename="meshes/KC-C-202R_UpBicepIdle_(1).stl"/>
      </geometry>
    </collision>
    <inertial name="link:KC-C-202R_UpBicepIdle_(1)_inertial">
      <mass value="0.099904741"/>
      <inertia ixx="0.00029834934" iyy="0.00012069266" izz="0.00040468899" ixy="2.8293251e-05" ixz="2.848668e-06" iyz="-1.5969284e-05"/>
      <origin xyz="0.044189009 -0.047231546 0.017014811" rpy="0 0 0"/>
    </inertial>
  </link>
  <joint name="joint:dof_right_bicepyaw_02" type="fixed">
    <origin xyz="-0.013 -0.1375 -0.0277502" rpy="1.5707963 0 0"/>
    <parent link="link:KC-C-201R_UpBicepDrive_(1)"/>
    <child link="link:RS02_(3)"/>
  </joint>
  <link name="link:RS02_(3)">
    <visual name="link:RS02_(3)_visual">
      <origin xyz="0 0 0" rpy="0 0 0"/>
      <geometry name="link:RS02_(3)_geometry">
        <mesh filename="meshes/RS02_(3).stl"/>
      </geometry>
      <material name="link:RS02_(3)_material">
        <color rgba="0.2627451 0.28235294 0.30196078 1"/>
      </material>
    </visual>
    <collision name="link:RS02_(3).collision">
      <origin xyz="0 0 0" rpy="0 0 0"/>
      <geometry name="link:RS02_(3)_collision_geometry">
        <mesh filename="meshes/RS02_(3).stl"/>
      </geometry>
    </collision>
    <inertial name="link:RS02_(3)_inertial">
      <mass value="0.4"/>
      <inertia ixx="0.00018548163" iyy="0.00018548163" izz="0.00028416296" ixy="0" ixz="0" iyz="0"/>
      <origin xyz="0 0 -0.016414865" rpy="0 0 0"/>
    </inertial>
  </link>
  <joint name="joint:fixed_right_Shldrbearing2" type="fixed">
    <origin xyz="0 0 -0.0035" rpy="0 0 0"/>
    <parent link="link:Bearing_(1)"/>
    <child link="link:KC-C-105X_ShldYokeBearingPin_(1)"/>
  </joint>
  <link name="link:KC-C-105X_ShldYokeBearingPin_(1)">
    <visual name="link:KC-C-105X_ShldYokeBearingPin_(1)_visual">
      <origin xyz="0 0 0" rpy="0 0 0"/>
      <geometry name="link:KC-C-105X_ShldYokeBearingPin_(1)_geometry">
        <mesh filename="meshes/KC-C-105X_ShldYokeBearingPin_(1).stl"/>
      </geometry>
      <material name="link:KC-C-105X_ShldYokeBearingPin_(1)_material">
        <color rgba="0.2627451 0.28235294 0.30196078 1"/>
      </material>
    </visual>
    <collision name="link:KC-C-105X_ShldYokeBearingPin_(1).collision">
      <origin xyz="0 0 0" rpy="0 0 0"/>
      <geometry name="link:KC-C-105X_ShldYokeBearingPin_(1)_collision_geometry">
        <mesh filename="meshes/KC-C-105X_ShldYokeBearingPin_(1).stl"/>
      </geometry>
    </collision>
    <inertial name="link:KC-C-105X_ShldYokeBearingPin_(1)_inertial">
      <mass value="0.013970656"/>
      <inertia ixx="1e-06" iyy="1e-06" izz="1.4322278e-06" ixy="0" ixz="0" iyz="0"/>
      <origin xyz="0 0 0.0032487995" rpy="0 0 0"/>
    </inertial>
  </link>
  <joint name="joint:dof_left_fixshldr03" type="fixed">
    <origin xyz="0 0 -0.0025" rpy="0 0 0"/>
    <parent link="link:RS03_(8)"/>
    <child link="link:KC-C-201L_UpBicepDrive_(2)"/>
  </joint>
  <link name="link:KC-C-201L_UpBicepDrive_(2)">
    <visual name="link:KC-C-201L_UpBicepDrive_(2)_visual">
      <origin xyz="0 0 0" rpy="0 0 0"/>
      <geometry name="link:KC-C-201L_UpBicepDrive_(2)_geometry">
        <mesh filename="meshes/KC-C-201L_UpBicepDrive_(2).stl"/>
      </geometry>
      <material name="link:KC-C-201L_UpBicepDrive_(2)_material">
        <color rgba="0.2627451 0.28235294 0.30196078 1"/>
      </material>
    </visual>
    <collision name="link:KC-C-201L_UpBicepDrive_(2).collision">
      <origin xyz="0 0 0" rpy="0 0 0"/>
      <geometry name="link:KC-C-201L_UpBicepDrive_(2)_collision_geometry">
        <mesh filename="meshes/KC-C-201L_UpBicepDrive_(2).stl"/>
      </geometry>
    </collision>
    <inertial name="link:KC-C-201L_UpBicepDrive_(2)_inertial">
      <mass value="0.29070578"/>
      <inertia ixx="0.0012964101" iyy="0.00047021015" izz="0.0015547621" ixy="7.6107204e-05" ixz="-6.1588974e-06" iyz="-3.6268033e-05"/>
      <origin xyz="0.0074839521 -0.06190759 -0.010644497" rpy="0 0 0"/>
    </inertial>
  </link>
  <joint name="joint:fixed_left_Shldrbearing1" type="fixed">
    <origin xyz="0.0565 -0.04 -0.014" rpy="0 0 0"/>
    <parent link="link:KC-C-102L_ShldYokeIdle_(1)"/>
    <child link="link:Bearing_(2)"/>
  </joint>
  <link name="link:Bearing_(2)">
    <visual name="link:Bearing_(2)_visual">
      <origin xyz="0 0 0" rpy="0 0 0"/>
      <geometry name="link:Bearing_(2)_geometry">
        <mesh filename="meshes/Bearing_(2).stl"/>
      </geometry>
      <material name="link:Bearing_(2)_material">
        <color rgba="0.2627451 0.28235294 0.30196078 1"/>
      </material>
    </visual>
    <collision name="link:Bearing_(2).collision">
      <origin xyz="0 0 0" rpy="0 0 0"/>
      <geometry name="link:Bearing_(2)_collision_geometry">
        <mesh filename="meshes/Bearing_(2).stl"/>
      </geometry>
    </collision>
    <inertial name="link:Bearing_(2)_inertial">
      <mass value="0.03284554"/>
      <inertia ixx="4.2274947e-06" iyy="4.2274947e-06" izz="8.1867508e-06" ixy="0" ixz="0" iyz="0"/>
      <origin xyz="0 0 0" rpy="0 0 0"/>
    </inertial>
  </link>
  <joint name="joint:fixed_left_shldrbearing2" type="fixed">
    <origin xyz="0.0565 -0.04 -0.0185" rpy="-3.1415927 0 0"/>
    <parent link="link:KC-C-102L_ShldYokeIdle_(1)"/>
    <child link="link:KC-C-105X_ShldYokeBearingPin_(2)"/>
  </joint>
  <link name="link:KC-C-105X_ShldYokeBearingPin_(2)">
    <visual name="link:KC-C-105X_ShldYokeBearingPin_(2)_visual">
      <origin xyz="0 0 0" rpy="0 0 0"/>
      <geometry name="link:KC-C-105X_ShldYokeBearingPin_(2)_geometry">
        <mesh filename="meshes/KC-C-105X_ShldYokeBearingPin_(2).stl"/>
      </geometry>
      <material name="link:KC-C-105X_ShldYokeBearingPin_(2)_material">
        <color rgba="0.2627451 0.28235294 0.30196078 1"/>
      </material>
    </visual>
    <collision name="link:KC-C-105X_ShldYokeBearingPin_(2).collision">
      <origin xyz="0 0 0" rpy="0 0 0"/>
      <geometry name="link:KC-C-105X_ShldYokeBearingPin_(2)_collision_geometry">
        <mesh filename="meshes/KC-C-105X_ShldYokeBearingPin_(2).stl"/>
      </geometry>
    </collision>
    <inertial name="link:KC-C-105X_ShldYokeBearingPin_(2)_inertial">
      <mass value="0.013970656"/>
      <inertia ixx="1e-06" iyy="1e-06" izz="1.4322278e-06" ixy="0" ixz="0" iyz="0"/>
      <origin xyz="0 0 -0.0047487995" rpy="0 0 0"/>
    </inertial>
  </link>
  <joint name="joint:dof_upperthigh_shell_right" type="fixed">
    <origin xyz="-0.0495 0.064783996 -0.0156" rpy="3.1415927 0 0"/>
    <parent link="link:KC-D-201R_UpperThigh_Idle_(1)"/>
    <child link="link:KC-D-201R_UpperThigh_Act_(1)"/>
  </joint>
  <link name="link:KC-D-201R_UpperThigh_Act_(1)">
    <visual name="link:KC-D-201R_UpperThigh_Act_(1)_visual">
      <origin xyz="0 0 0" rpy="0 0 0"/>
      <geometry name="link:KC-D-201R_UpperThigh_Act_(1)_geometry">
        <mesh filename="meshes/KC-D-201R_UpperThigh_Act_(1).stl"/>
      </geometry>
      <material name="link:KC-D-201R_UpperThigh_Act_(1)_material">
        <color rgba="0.2627451 0.28235294 0.30196078 1"/>
      </material>
    </visual>
    <collision name="link:KC-D-201R_UpperThigh_Act_(1).collision">
      <origin xyz="0 0 0" rpy="0 0 0"/>
      <geometry name="link:KC-D-201R_UpperThigh_Act_(1)_collision_geometry">
        <mesh filename="meshes/KC-D-201R_UpperThigh_Act_(1).stl"/>
      </geometry>
    </collision>
    <inertial name="link:KC-D-201R_UpperThigh_Act_(1)_inertial">
      <mass value="0.40470344"/>
      <inertia ixx="0.001844218" iyy="0.00095797954" izz="0.0022375504" ixy="2.7867504e-05" ixz="7.809526e-06" iyz="2.10017e-05"/>
      <origin xyz="0.049667254 -0.0049689419 0.034745295" rpy="0 0 0"/>
    </inertial>
  </link>
  <joint name="joint:fix_hipyoke_pin_right" type="fixed">
    <origin xyz="0 0 0.008" rpy="0 0 0"/>
    <parent link="link:KC-D-201R_UpperThigh_Idle_(1)"/>
    <child link="link:KC-D-106X_Hip_Bearing_Pin_R_vis_(1)"/>
  </joint>
  <link name="link:KC-D-106X_Hip_Bearing_Pin_R_vis_(1)">
    <visual name="link:KC-D-106X_Hip_Bearing_Pin_R_vis_(1)_visual">
      <origin xyz="0 0 0" rpy="0 0 0"/>
      <geometry name="link:KC-D-106X_Hip_Bearing_Pin_R_vis_(1)_geometry">
        <mesh filename="meshes/KC-D-106X_Hip_Bearing_Pin_R_vis_(1).stl"/>
      </geometry>
      <material name="link:KC-D-106X_Hip_Bearing_Pin_R_vis_(1)_material">
        <color rgba="0.2627451 0.28235294 0.30196078 1"/>
      </material>
    </visual>
    <collision name="link:KC-D-106X_Hip_Bearing_Pin_R_vis_(1).collision">
      <origin xyz="0 0 0" rpy="0 0 0"/>
      <geometry name="link:KC-D-106X_Hip_Bearing_Pin_R_vis_(1)_collision_geometry">
        <mesh filename="meshes/KC-D-106X_Hip_Bearing_Pin_R_vis_(1).stl"/>
      </geometry>
    </collision>
    <inertial name="link:KC-D-106X_Hip_Bearing_Pin_R_vis_(1)_inertial">
      <mass value="0.020333023"/>
      <inertia ixx="1.4930779e-06" iyy="1.4930779e-06" izz="2.0950887e-06" ixy="0" ixz="0" iyz="0"/>
      <origin xyz="0 0 0.0085050638" rpy="0 0 0"/>
    </inertial>
  </link>
  <joint name="joint:dof_upperthigh_shell_left" type="fixed">
    <origin xyz="0.0495 0.064783996 -0.0156" rpy="0 0 0"/>
    <parent link="link:KC-D-201L_UpperThigh_Idle_(1)"/>
    <child link="link:KC-D-201L_UpperThigh_Act_(1)"/>
  </joint>
  <link name="link:KC-D-201L_UpperThigh_Act_(1)">
    <visual name="link:KC-D-201L_UpperThigh_Act_(1)_visual">
      <origin xyz="0 0 0" rpy="0 0 0"/>
      <geometry name="link:KC-D-201L_UpperThigh_Act_(1)_geometry">
        <mesh filename="meshes/KC-D-201L_UpperThigh_Act_(1).stl"/>
      </geometry>
      <material name="link:KC-D-201L_UpperThigh_Act_(1)_material">
        <color rgba="0.2627451 0.28235294 0.30196078 1"/>
      </material>
    </visual>
    <collision name="link:KC-D-201L_UpperThigh_Act_(1).collision">
      <origin xyz="0 0 0" rpy="0 0 0"/>
      <geometry name="link:KC-D-201L_UpperThigh_Act_(1)_collision_geometry">
        <mesh filename="meshes/KC-D-201L_UpperThigh_Act_(1).stl"/>
      </geometry>
    </collision>
    <inertial name="link:KC-D-201L_UpperThigh_Act_(1)_inertial">
      <mass value="0.40476998"/>
      <inertia ixx="0.0018442474" iyy="0.0009580566" izz="0.0022375577" ixy="2.7858204e-05" ixz="7.8094632e-06" iyz="2.0999617e-05"/>
      <origin xyz="-0.049671592 0.0049667002 -0.034748843" rpy="0 0 0"/>
    </inertial>
  </link>
  <joint name="joint:fix_hipyoke_pin_left" type="fixed">
    <origin xyz="0 0 0.008" rpy="3.1415927 0 0"/>
    <parent link="link:KC-D-201L_UpperThigh_Idle_(1)"/>
    <child link="link:KC-D-106X_Hip_Bearing_Pin_L_vis_(1)"/>
  </joint>
  <link name="link:KC-D-106X_Hip_Bearing_Pin_L_vis_(1)">
    <visual name="link:KC-D-106X_Hip_Bearing_Pin_L_vis_(1)_visual">
      <origin xyz="0 0 0" rpy="0 0 0"/>
      <geometry name="link:KC-D-106X_Hip_Bearing_Pin_L_vis_(1)_geometry">
        <mesh filename="meshes/KC-D-106X_Hip_Bearing_Pin_L_vis_(1).stl"/>
      </geometry>
      <material name="link:KC-D-106X_Hip_Bearing_Pin_L_vis_(1)_material">
        <color rgba="0.2627451 0.28235294 0.30196078 1"/>
      </material>
    </visual>
    <collision name="link:KC-D-106X_Hip_Bearing_Pin_L_vis_(1).collision">
      <origin xyz="0 0 0" rpy="0 0 0"/>
      <geometry name="link:KC-D-106X_Hip_Bearing_Pin_L_vis_(1)_collision_geometry">
        <mesh filename="meshes/KC-D-106X_Hip_Bearing_Pin_L_vis_(1).stl"/>
      </geometry>
    </collision>
    <inertial name="link:KC-D-106X_Hip_Bearing_Pin_L_vis_(1)_inertial">
      <mass value="0.020333023"/>
      <inertia ixx="1.4930779e-06" iyy="1.4930779e-06" izz="2.0950887e-06" ixy="0" ixz="0" iyz="0"/>
      <origin xyz="0 0 -0.0085050638" rpy="0 0 0"/>
    </inertial>
  </link>
  <joint name="joint:dof_right_shoulder_yaw_02" type="revolute">
    <origin xyz="0 0 0.0035" rpy="3.1415927 0 0"/>
    <parent link="link:RS02_(3)"/>
    <child link="link:KC-C-202R_(1)"/>
    <limit effort="17" velocity="12.566" lower="-1.6580628" upper="1.6580628"/>
    <axis xyz="0 0 1"/>
  </joint>
  <link name="link:KC-C-202R_(1)">
    <visual name="link:KC-C-202R_(1)_visual">
      <origin xyz="0 0 0" rpy="0 0 0"/>
      <geometry name="link:KC-C-202R_(1)_geometry">
        <mesh filename="meshes/KC-C-202R_(1).stl"/>
      </geometry>
      <material name="link:KC-C-202R_(1)_material">
        <color rgba="0.2627451 0.28235294 0.30196078 1"/>
      </material>
    </visual>
    <collision name="link:KC-C-202R_(1).collision">
      <origin xyz="0 0 0" rpy="0 0 0"/>
      <geometry name="link:KC-C-202R_(1)_collision_geometry">
        <mesh filename="meshes/KC-C-202R_(1).stl"/>
      </geometry>
    </collision>
    <inertial name="link:KC-C-202R_(1)_inertial">
      <mass value="0.26779064"/>
      <inertia ixx="0.00079312575" iyy="0.00062880023" izz="0.00024765351" ixy="-1.4620841e-06" ixz="-7.6691719e-06" iyz="2.3412519e-05"/>
      <origin xyz="0.020969628 0.0023596779 -0.05896397" rpy="0 0 0"/>
    </inertial>
  </link>
  <joint name="joint:fix_right_yaw_hardstop_vis" type="fixed">
    <origin xyz="0 0 0" rpy="0 0 0"/>
    <parent link="link:RS02_(3)"/>
    <child link="link:KC-C-203X_(1)"/>
  </joint>
  <link name="link:KC-C-203X_(1)">
    <visual name="link:KC-C-203X_(1)_visual">
      <origin xyz="0 0 0" rpy="0 0 0"/>
      <geometry name="link:KC-C-203X_(1)_geometry">
        <mesh filename="meshes/KC-C-203X_(1).stl"/>
      </geometry>
      <material name="link:KC-C-203X_(1)_material">
        <color rgba="0.2627451 0.28235294 0.30196078 1"/>
      </material>
    </visual>
    <collision name="link:KC-C-203X_(1).collision">
      <origin xyz="0 0 0" rpy="0 0 0"/>
      <geometry name="link:KC-C-203X_(1)_collision_geometry">
        <mesh filename="meshes/KC-C-203X_(1).stl"/>
      </geometry>
    </collision>
    <inertial name="link:KC-C-203X_(1)_inertial">
      <mass value="0.0058708317"/>
      <inertia ixx="1e-06" iyy="1e-06" izz="1e-06" ixy="0" ixz="0" iyz="0"/>
      <origin xyz="-0.034998395 0 0.006989243" rpy="0 0 0"/>
    </inertial>
  </link>
  <joint name="joint:dof_left_upper_bicep_idle" type="fixed">
    <origin xyz="0.0505 -0.0875 -0.0395" rpy="-3.1415927 0 0"/>
    <parent link="link:KC-C-201L_UpBicepDrive_(2)"/>
    <child link="link:KC-C-202L_UpBicepIdle_(1)"/>
  </joint>
  <link name="link:KC-C-202L_UpBicepIdle_(1)">
    <visual name="link:KC-C-202L_UpBicepIdle_(1)_visual">
      <origin xyz="0 0 0" rpy="0 0 0"/>
      <geometry name="link:KC-C-202L_UpBicepIdle_(1)_geometry">
        <mesh filename="meshes/KC-C-202L_UpBicepIdle_(1).stl"/>
      </geometry>
      <material name="link:KC-C-202L_UpBicepIdle_(1)_material">
        <color rgba="0.2627451 0.28235294 0.30196078 1"/>
      </material>
    </visual>
    <collision name="link:KC-C-202L_UpBicepIdle_(1).collision">
      <origin xyz="0 0 0" rpy="0 0 0"/>
      <geometry name="link:KC-C-202L_UpBicepIdle_(1)_collision_geometry">
        <mesh filename="meshes/KC-C-202L_UpBicepIdle_(1).stl"/>
      </geometry>
    </collision>
    <inertial name="link:KC-C-202L_UpBicepIdle_(1)_inertial">
      <mass value="0.099902395"/>
      <inertia ixx="0.00029832969" iyy="0.00012069186" izz="0.000404671" ixy="-2.8315545e-05" ixz="-2.8475904e-06" iyz="-1.5967509e-05"/>
      <origin xyz="-0.044186658 -0.047233152 0.017014764" rpy="0 0 0"/>
    </inertial>
  </link>
  <joint name="joint:dof_left_bicepyaw02" type="fixed">
    <origin xyz="0.013 -0.1375 -0.0277502" rpy="1.5707963 0 0"/>
    <parent link="link:KC-C-201L_UpBicepDrive_(2)"/>
    <child link="link:RS02_(6)"/>
  </joint>
  <link name="link:RS02_(6)">
    <visual name="link:RS02_(6)_visual">
      <origin xyz="0 0 0" rpy="0 0 0"/>
      <geometry name="link:RS02_(6)_geometry">
        <mesh filename="meshes/RS02_(6).stl"/>
      </geometry>
      <material name="link:RS02_(6)_material">
        <color rgba="0.2627451 0.28235294 0.30196078 1"/>
      </material>
    </visual>
    <collision name="link:RS02_(6).collision">
      <origin xyz="0 0 0" rpy="0 0 0"/>
      <geometry name="link:RS02_(6)_collision_geometry">
        <mesh filename="meshes/RS02_(6).stl"/>
      </geometry>
    </collision>
    <inertial name="link:RS02_(6)_inertial">
      <mass value="0.4"/>
      <inertia ixx="0.00018548163" iyy="0.00018548163" izz="0.00028416296" ixy="0" ixz="0" iyz="0"/>
      <origin xyz="0 0 -0.016414865" rpy="0 0 0"/>
    </inertial>
  </link>
  <joint name="joint:dof_hipyaw_upperthigh_right" type="fixed">
    <origin xyz="0.0495 -0.074716004 0.01675" rpy="-1.5707963 0 0"/>
    <parent link="link:KC-D-201R_UpperThigh_Act_(1)"/>
    <child link="link:RS03_(1)"/>
  </joint>
  <link name="link:RS03_(1)">
    <visual name="link:RS03_(1)_visual">
      <origin xyz="0 0 0" rpy="0 0 0"/>
      <geometry name="link:RS03_(1)_geometry">
        <mesh filename="meshes/RS03_(1).stl"/>
      </geometry>
      <material name="link:RS03_(1)_material">
        <color rgba="0.2627451 0.28235294 0.30196078 1"/>
      </material>
    </visual>
    <collision name="link:RS03_(1).collision">
      <origin xyz="0 0 0" rpy="0 0 0"/>
      <geometry name="link:RS03_(1)_collision_geometry">
        <mesh filename="meshes/RS03_(1).stl"/>
      </geometry>
    </collision>
    <inertial name="link:RS03_(1)_inertial">
      <mass value="0.88"/>
      <inertia ixx="0.00065607101" iyy="0.00065607101" izz="0.00088708736" ixy="0" ixz="0" iyz="0"/>
      <origin xyz="0 0 0.024767932" rpy="0 0 0"/>
    </inertial>
  </link>
  <joint name="joint:dof_hipyaw_upperthigh_left" type="fixed">
    <origin xyz="-0.0495 0.074716004 -0.01675" rpy="1.5707963 0 0"/>
    <parent link="link:KC-D-201L_UpperThigh_Act_(1)"/>
    <child link="link:RS03_(7)"/>
  </joint>
  <link name="link:RS03_(7)">
    <visual name="link:RS03_(7)_visual">
      <origin xyz="0 0 0" rpy="0 0 0"/>
      <geometry name="link:RS03_(7)_geometry">
        <mesh filename="meshes/RS03_(7).stl"/>
      </geometry>
      <material name="link:RS03_(7)_material">
        <color rgba="0.2627451 0.28235294 0.30196078 1"/>
      </material>
    </visual>
    <collision name="link:RS03_(7).collision">
      <origin xyz="0 0 0" rpy="0 0 0"/>
      <geometry name="link:RS03_(7)_collision_geometry">
        <mesh filename="meshes/RS03_(7).stl"/>
      </geometry>
    </collision>
    <inertial name="link:RS03_(7)_inertial">
      <mass value="0.88"/>
      <inertia ixx="0.00065607101" iyy="0.00065607101" izz="0.00088708736" ixy="0" ixz="0" iyz="0"/>
      <origin xyz="0 0 0.024767932" rpy="0 0 0"/>
    </inertial>
  </link>
  <joint name="joint:dof_right_lowerbicep_idle" type="fixed">
    <origin xyz="0 0.0345 -0.02675" rpy="1.5707963 0 1.5707963"/>
    <parent link="link:KC-C-202R_(1)"/>
    <child link="link:KC-C-201R_(1)"/>
  </joint>
  <link name="link:KC-C-201R_(1)">
    <visual name="link:KC-C-201R_(1)_visual">
      <origin xyz="0 0 0" rpy="0 0 0"/>
      <geometry name="link:KC-C-201R_(1)_geometry">
        <mesh filename="meshes/KC-C-201R_(1).stl"/>
      </geometry>
      <material name="link:KC-C-201R_(1)_material">
        <color rgba="0.2627451 0.28235294 0.30196078 1"/>
      </material>
    </visual>
    <collision name="link:KC-C-201R_(1).collision">
      <origin xyz="0 0 0" rpy="0 0 0"/>
      <geometry name="link:KC-C-201R_(1)_collision_geometry">
        <mesh filename="meshes/KC-C-201R_(1).stl"/>
      </geometry>
    </collision>
    <inertial name="link:KC-C-201R_(1)_inertial">
      <mass value="0.075717091"/>
      <inertia ixx="0.000142134" iyy="8.1429551e-05" izz="0.00020015558" ixy="1.3963745e-05" ixz="0" iyz="9.065757e-06"/>
      <origin xyz="-0.030865117 -0.035839118 -0.023015656" rpy="0 0 0"/>
    </inertial>
  </link>
  <joint name="joint:dof_right_elbow02fix" type="fixed">
    <origin xyz="0.014 -0.01 -0.137" rpy="0 1.5707963 0"/>
    <parent link="link:KC-C-202R_(1)"/>
    <child link="link:RS02_(2)"/>
  </joint>
  <link name="link:RS02_(2)">
    <visual name="link:RS02_(2)_visual">
      <origin xyz="0 0 0" rpy="0 0 0"/>
      <geometry name="link:RS02_(2)_geometry">
        <mesh filename="meshes/RS02_(2).stl"/>
      </geometry>
      <material name="link:RS02_(2)_material">
        <color rgba="0.2627451 0.28235294 0.30196078 1"/>
      </material>
    </visual>
    <collision name="link:RS02_(2).collision">
      <origin xyz="0 0 0" rpy="0 0 0"/>
      <geometry name="link:RS02_(2)_collision_geometry">
        <mesh filename="meshes/RS02_(2).stl"/>
      </geometry>
    </collision>
    <inertial name="link:RS02_(2)_inertial">
      <mass value="0.4"/>
      <inertia ixx="0.00018548163" iyy="0.00018548163" izz="0.00028416296" ixy="0" ixz="0" iyz="0"/>
      <origin xyz="0 0 -0.016414865" rpy="0 0 0"/>
    </inertial>
  </link>
  <joint name="joint:dof_left_shoulder_yaw_02" type="revolute">
    <origin xyz="0 0 0.0035" rpy="0 0 0"/>
    <parent link="link:RS02_(6)"/>
    <child link="link:KC-C-202L_(1)"/>
    <limit effort="17" velocity="12.566" lower="-1.6580628" upper="1.6580628"/>
    <axis xyz="0 0 -1"/>
  </joint>
  <link name="link:KC-C-202L_(1)">
    <visual name="link:KC-C-202L_(1)_visual">
      <origin xyz="0 0 0" rpy="0 0 0"/>
      <geometry name="link:KC-C-202L_(1)_geometry">
        <mesh filename="meshes/KC-C-202L_(1).stl"/>
      </geometry>
      <material name="link:KC-C-202L_(1)_material">
        <color rgba="0.2627451 0.28235294 0.30196078 1"/>
      </material>
    </visual>
    <collision name="link:KC-C-202L_(1).collision">
      <origin xyz="0 0 0" rpy="0 0 0"/>
      <geometry name="link:KC-C-202L_(1)_collision_geometry">
        <mesh filename="meshes/KC-C-202L_(1).stl"/>
      </geometry>
    </collision>
    <inertial name="link:KC-C-202L_(1)_inertial">
      <mass value="0.10356787"/>
      <inertia ixx="0.00030674882" iyy="0.00024319194" izz="9.5782617e-05" ixy="0" ixz="-2.9668284e-06" iyz="9.0548966e-06"/>
      <origin xyz="-0.020968937 -0.0023585685 0.058962967" rpy="0 0 0"/>
    </inertial>
  </link>
  <joint name="joint:fix_left_yaw_hardstop_vis" type="fixed">
    <origin xyz="0 0 0" rpy="0 0 0"/>
    <parent link="link:RS02_(6)"/>
    <child link="link:KC-C-203X_(2)"/>
  </joint>
  <link name="link:KC-C-203X_(2)">
    <visual name="link:KC-C-203X_(2)_visual">
      <origin xyz="0 0 0" rpy="0 0 0"/>
      <geometry name="link:KC-C-203X_(2)_geometry">
        <mesh filename="meshes/KC-C-203X_(2).stl"/>
      </geometry>
      <material name="link:KC-C-203X_(2)_material">
        <color rgba="0.2627451 0.28235294 0.30196078 1"/>
      </material>
    </visual>
    <collision name="link:KC-C-203X_(2).collision">
      <origin xyz="0 0 0" rpy="0 0 0"/>
      <geometry name="link:KC-C-203X_(2)_collision_geometry">
        <mesh filename="meshes/KC-C-203X_(2).stl"/>
      </geometry>
    </collision>
    <inertial name="link:KC-C-203X_(2)_inertial">
      <mass value="0.0058708317"/>
      <inertia ixx="1e-06" iyy="1e-06" izz="1e-06" ixy="0" ixz="0" iyz="0"/>
      <origin xyz="0.034998395 0 0.006989243" rpy="0 0 0"/>
    </inertial>
  </link>
  <joint name="joint:dof_right_hip_yaw_03" type="revolute">
    <origin xyz="0 0 -0.0025" rpy="3.1415927 0 0"/>
    <parent link="link:RS03_(1)"/>
    <child link="link:KC-D-301R_R_Femur_Lower_Drive_(1)"/>
    <limit effort="60" velocity="6.283" lower="-1.5707963" upper="1.5707963"/>
    <axis xyz="0 0 -1"/>
  </joint>
  <link name="link:KC-D-301R_R_Femur_Lower_Drive_(1)">
    <visual name="link:KC-D-301R_R_Femur_Lower_Drive_(1)_visual">
      <origin xyz="0 0 0" rpy="0 0 0"/>
      <geometry name="link:KC-D-301R_R_Femur_Lower_Drive_(1)_geometry">
        <mesh filename="meshes/KC-D-301R_R_Femur_Lower_Drive_(1).stl"/>
      </geometry>
      <material name="link:KC-D-301R_R_Femur_Lower_Drive_(1)_material">
        <color rgba="0.2627451 0.28235294 0.30196078 1"/>
      </material>
    </visual>
    <collision name="link:KC-D-301R_R_Femur_Lower_Drive_(1).collision">
      <origin xyz="0 0 0" rpy="0 0 0"/>
      <geometry name="link:KC-D-301R_R_Femur_Lower_Drive_(1)_collision_geometry">
        <mesh filename="meshes/KC-D-301R_R_Femur_Lower_Drive_(1).stl"/>
      </geometry>
    </collision>
    <inertial name="link:KC-D-301R_R_Femur_Lower_Drive_(1)_inertial">
      <mass value="0.62243904"/>
      <inertia ixx="0.0040853777" iyy="0.0034437306" izz="0.0011275762" ixy="1.7119475e-05" ixz="1.7625293e-05" iyz="9.514952e-05"/>
      <origin xyz="0.022876644 0.0017241936 0.089140078" rpy="0 0 0"/>
    </inertial>
  </link>
  <joint name="joint:fix_right_hipyaw_hardstop_vis" type="fixed">
    <origin xyz="0 0 0" rpy="0 0 0"/>
    <parent link="link:RS03_(1)"/>
    <child link="link:KC-D-203R_Thigh_Roll_Hardstop_vis_(1)"/>
  </joint>
  <link name="link:KC-D-203R_Thigh_Roll_Hardstop_vis_(1)">
    <visual name="link:KC-D-203R_Thigh_Roll_Hardstop_vis_(1)_visual">
      <origin xyz="0 0 0" rpy="0 0 0"/>
      <geometry name="link:KC-D-203R_Thigh_Roll_Hardstop_vis_(1)_geometry">
        <mesh filename="meshes/KC-D-203R_Thigh_Roll_Hardstop_vis_(1).stl"/>
      </geometry>
      <material name="link:KC-D-203R_Thigh_Roll_Hardstop_vis_(1)_material">
        <color rgba="0.2627451 0.28235294 0.30196078 1"/>
      </material>
    </visual>
    <collision name="link:KC-D-203R_Thigh_Roll_Hardstop_vis_(1).collision">
      <origin xyz="0 0 0" rpy="0 0 0"/>
      <geometry name="link:KC-D-203R_Thigh_Roll_Hardstop_vis_(1)_collision_geometry">
        <mesh filename="meshes/KC-D-203R_Thigh_Roll_Hardstop_vis_(1).stl"/>
      </geometry>
    </collision>
    <inertial name="link:KC-D-203R_Thigh_Roll_Hardstop_vis_(1)_inertial">
      <mass value="0.0074288749"/>
      <inertia ixx="1.8985668e-06" iyy="1e-06" izz="1.9391138e-06" ixy="0" ixz="0" iyz="0"/>
      <origin xyz="-0.047374141 4.1279552e-05 -0.0051008514" rpy="0 0 0"/>
    </inertial>
  </link>
  <joint name="joint:dof_left_hip_yaw_03" type="revolute">
    <origin xyz="0 0 -0.0025" rpy="3.1415927 0 0"/>
    <parent link="link:RS03_(7)"/>
    <child link="link:KC-D-301L_L_Femur_Lower_Drive_(1)"/>
    <limit effort="60" velocity="6.283" lower="-1.5707963" upper="1.5707963"/>
    <axis xyz="0 0 -1"/>
  </joint>
  <link name="link:KC-D-301L_L_Femur_Lower_Drive_(1)">
    <visual name="link:KC-D-301L_L_Femur_Lower_Drive_(1)_visual">
      <origin xyz="0 0 0" rpy="0 0 0"/>
      <geometry name="link:KC-D-301L_L_Femur_Lower_Drive_(1)_geometry">
        <mesh filename="meshes/KC-D-301L_L_Femur_Lower_Drive_(1).stl"/>
      </geometry>
      <material name="link:KC-D-301L_L_Femur_Lower_Drive_(1)_material">
        <color rgba="0.2627451 0.28235294 0.30196078 1"/>
      </material>
    </visual>
    <collision name="link:KC-D-301L_L_Femur_Lower_Drive_(1).collision">
      <origin xyz="0 0 0" rpy="0 0 0"/>
      <geometry name="link:KC-D-301L_L_Femur_Lower_Drive_(1)_collision_geometry">
        <mesh filename="meshes/KC-D-301L_L_Femur_Lower_Drive_(1).stl"/>
      </geometry>
    </collision>
    <inertial name="link:KC-D-301L_L_Femur_Lower_Drive_(1)_inertial">
      <mass value="0.62246632"/>
      <inertia ixx="0.0040853496" iyy="0.0034437299" izz="0.0011275805" ixy="-1.7072162e-05" ixz="-1.7542024e-05" iyz="9.5139008e-05"/>
      <origin xyz="-0.022877715 0.001727793 0.089146883" rpy="0 0 0"/>
    </inertial>
  </link>
  <joint name="joint:fix_left_hipyaw_hardstop_vis" type="fixed">
    <origin xyz="0 0 0" rpy="0 0 0"/>
    <parent link="link:RS03_(7)"/>
    <child link="link:KC-D-203L_Thigh_Roll_Hardstop_vis_(1)"/>
  </joint>
  <link name="link:KC-D-203L_Thigh_Roll_Hardstop_vis_(1)">
    <visual name="link:KC-D-203L_Thigh_Roll_Hardstop_vis_(1)_visual">
      <origin xyz="0 0 0" rpy="0 0 0"/>
      <geometry name="link:KC-D-203L_Thigh_Roll_Hardstop_vis_(1)_geometry">
        <mesh filename="meshes/KC-D-203L_Thigh_Roll_Hardstop_vis_(1).stl"/>
      </geometry>
      <material name="link:KC-D-203L_Thigh_Roll_Hardstop_vis_(1)_material">
        <color rgba="0.2627451 0.28235294 0.30196078 1"/>
      </material>
    </visual>
    <collision name="link:KC-D-203L_Thigh_Roll_Hardstop_vis_(1).collision">
      <origin xyz="0 0 0" rpy="0 0 0"/>
      <geometry name="link:KC-D-203L_Thigh_Roll_Hardstop_vis_(1)_collision_geometry">
        <mesh filename="meshes/KC-D-203L_Thigh_Roll_Hardstop_vis_(1).stl"/>
      </geometry>
    </collision>
    <inertial name="link:KC-D-203L_Thigh_Roll_Hardstop_vis_(1)_inertial">
      <mass value="0.0074288749"/>
      <inertia ixx="1.8985668e-06" iyy="1e-06" izz="1.9391138e-06" ixy="0" ixz="0" iyz="0"/>
      <origin xyz="0.047374141 4.1279552e-05 -0.0051008514" rpy="0 0 0"/>
    </inertial>
  </link>
  <joint name="joint:dof_right_elbow_02" type="revolute">
    <origin xyz="0 0 0.0035" rpy="0 0 0"/>
    <parent link="link:RS02_(2)"/>
    <child link="link:KC-C-401R_R_UpForearmDrive_(1)"/>
    <limit effort="17" velocity="12.566" lower="0" upper="2.4783675"/>
    <axis xyz="0 0 -1"/>
  </joint>
  <link name="link:KC-C-401R_R_UpForearmDrive_(1)">
    <visual name="link:KC-C-401R_R_UpForearmDrive_(1)_visual">
      <origin xyz="0 0 0" rpy="0 0 0"/>
      <geometry name="link:KC-C-401R_R_UpForearmDrive_(1)_geometry">
        <mesh filename="meshes/KC-C-401R_R_UpForearmDrive_(1).stl"/>
      </geometry>
      <material name="link:KC-C-401R_R_UpForearmDrive_(1)_material">
        <color rgba="0.2627451 0.28235294 0.30196078 1"/>
      </material>
    </visual>
    <collision name="link:KC-C-401R_R_UpForearmDrive_(1).collision">
      <origin xyz="0 0 0" rpy="0 0 0"/>
      <geometry name="link:KC-C-401R_R_UpForearmDrive_(1)_collision_geometry">
        <mesh filename="meshes/KC-C-401R_R_UpForearmDrive_(1).stl"/>
      </geometry>
    </collision>
    <inertial name="link:KC-C-401R_R_UpForearmDrive_(1)_inertial">
      <mass value="0.22276655"/>
      <inertia ixx="0.00021042201" iyy="0.00052506238" izz="0.00062349526" ixy="-2.6958545e-05" ixz="7.9153432e-05" iyz="1.1684089e-05"/>
      <origin xyz="0.048275974 0.014047967 0.0038603079" rpy="0 0 0"/>
    </inertial>
  </link>
  <joint name="joint:dof_left_lowerbicep_idle" type="fixed">
    <origin xyz="0 -0.0345 0.02675" rpy="1.5707963 0 -1.5707963"/>
    <parent link="link:KC-C-202L_(1)"/>
    <child link="link:KC-C-201L_(2)"/>
  </joint>
  <link name="link:KC-C-201L_(2)">
    <visual name="link:KC-C-201L_(2)_visual">
      <origin xyz="0 0 0" rpy="0 0 0"/>
      <geometry name="link:KC-C-201L_(2)_geometry">
        <mesh filename="meshes/KC-C-201L_(2).stl"/>
      </geometry>
      <material name="link:KC-C-201L_(2)_material">
        <color rgba="0.2627451 0.28235294 0.30196078 1"/>
      </material>
    </visual>
    <collision name="link:KC-C-201L_(2).collision">
      <origin xyz="0 0 0" rpy="0 0 0"/>
      <geometry name="link:KC-C-201L_(2)_collision_geometry">
        <mesh filename="meshes/KC-C-201L_(2).stl"/>
      </geometry>
    </collision>
    <inertial name="link:KC-C-201L_(2)_inertial">
      <mass value="0.075691317"/>
      <inertia ixx="0.00014207921" iyy="8.1420643e-05" izz="0.00020010346" ixy="-1.3984141e-05" ixz="0" iyz="-9.0473773e-06"/>
      <origin xyz="-0.030873145 0.035856581 -0.023010732" rpy="0 0 0"/>
    </inertial>
  </link>
  <joint name="joint:dof_left_elbow02fix" type="fixed">
    <origin xyz="-0.014 0.01 0.137" rpy="3.1415927 1.5707963 0"/>
    <parent link="link:KC-C-202L_(1)"/>
    <child link="link:RS02_(5)"/>
  </joint>
  <link name="link:RS02_(5)">
    <visual name="link:RS02_(5)_visual">
      <origin xyz="0 0 0" rpy="0 0 0"/>
      <geometry name="link:RS02_(5)_geometry">
        <mesh filename="meshes/RS02_(5).stl"/>
      </geometry>
      <material name="link:RS02_(5)_material">
        <color rgba="0.2627451 0.28235294 0.30196078 1"/>
      </material>
    </visual>
    <collision name="link:RS02_(5).collision">
      <origin xyz="0 0 0" rpy="0 0 0"/>
      <geometry name="link:RS02_(5)_collision_geometry">
        <mesh filename="meshes/RS02_(5).stl"/>
      </geometry>
    </collision>
    <inertial name="link:RS02_(5)_inertial">
      <mass value="0.4"/>
      <inertia ixx="0.00018548163" iyy="0.00018548163" izz="0.00028416296" ixy="0" ixz="0" iyz="0"/>
      <origin xyz="0 0 -0.016414865" rpy="0 0 0"/>
    </inertial>
  </link>
  <joint name="joint:fixed_knee_idle_right" type="fixed">
    <origin xyz="0.0195 -0.021 0.212" rpy="1.5707963 0 -1.5707963"/>
    <parent link="link:KC-D-301R_R_Femur_Lower_Drive_(1)"/>
    <child link="link:RS04_(1)"/>
  </joint>
  <link name="link:RS04_(1)">
    <visual name="link:RS04_(1)_visual">
      <origin xyz="0 0 0" rpy="0 0 0"/>
      <geometry name="link:RS04_(1)_geometry">
        <mesh filename="meshes/RS04_(1).stl"/>
      </geometry>
      <material name="link:RS04_(1)_material">
        <color rgba="0.2627451 0.28235294 0.30196078 1"/>
      </material>
    </visual>
    <collision name="link:RS04_(1).collision">
      <origin xyz="0 0 0" rpy="0 0 0"/>
      <geometry name="link:RS04_(1)_collision_geometry">
        <mesh filename="meshes/RS04_(1).stl"/>
      </geometry>
    </collision>
    <inertial name="link:RS04_(1)_inertial">
      <mass value="1.42"/>
      <inertia ixx="0.001482289" iyy="0.001482289" izz="0.0023882984" ixy="0" ixz="0" iyz="0"/>
      <origin xyz="0 0 0.023914944" rpy="0 0 0"/>
    </inertial>
  </link>
  <joint name="joint:dof_lower_thigh_drive_left" type="fixed">
    <origin xyz="-0.0195 -0.021 0.212" rpy="-1.5707963 0 -1.5707963"/>
    <parent link="link:KC-D-301L_L_Femur_Lower_Drive_(1)"/>
    <child link="link:RS04_(3)"/>
  </joint>
  <link name="link:RS04_(3)">
    <visual name="link:RS04_(3)_visual">
      <origin xyz="0 0 0" rpy="0 0 0"/>
      <geometry name="link:RS04_(3)_geometry">
        <mesh filename="meshes/RS04_(3).stl"/>
      </geometry>
      <material name="link:RS04_(3)_material">
        <color rgba="0.2627451 0.28235294 0.30196078 1"/>
      </material>
    </visual>
    <collision name="link:RS04_(3).collision">
      <origin xyz="0 0 0" rpy="0 0 0"/>
      <geometry name="link:RS04_(3)_collision_geometry">
        <mesh filename="meshes/RS04_(3).stl"/>
      </geometry>
    </collision>
    <inertial name="link:RS04_(3)_inertial">
      <mass value="1.42"/>
      <inertia ixx="0.001482289" iyy="0.001482289" izz="0.0023882984" ixy="0" ixz="0" iyz="0"/>
      <origin xyz="0 0 0.023914944" rpy="0 0 0"/>
    </inertial>
  </link>
  <joint name="joint:dof_right_forearm_idle" type="fixed">
    <origin xyz="0.0525 -0.01565 -0.026" rpy="0 0 1.5707963"/>
    <parent link="link:KC-C-401R_R_UpForearmDrive_(1)"/>
    <child link="link:KC-C-402R_Forearm_Upper_Idle_(1)"/>
  </joint>
  <link name="link:KC-C-402R_Forearm_Upper_Idle_(1)">
    <visual name="link:KC-C-402R_Forearm_Upper_Idle_(1)_visual">
      <origin xyz="0 0 0" rpy="0 0 0"/>
      <geometry name="link:KC-C-402R_Forearm_Upper_Idle_(1)_geometry">
        <mesh filename="meshes/KC-C-402R_Forearm_Upper_Idle_(1).stl"/>
      </geometry>
      <material name="link:KC-C-402R_Forearm_Upper_Idle_(1)_material">
        <color rgba="0.2627451 0.28235294 0.30196078 1"/>
      </material>
    </visual>
    <collision name="link:KC-C-402R_Forearm_Upper_Idle_(1).collision">
      <origin xyz="0 0 0" rpy="0 0 0"/>
      <geometry name="link:KC-C-402R_Forearm_Upper_Idle_(1)_collision_geometry">
        <mesh filename="meshes/KC-C-402R_Forearm_Upper_Idle_(1).stl"/>
      </geometry>
    </collision>
    <inertial name="link:KC-C-402R_Forearm_Upper_Idle_(1)_inertial">
      <mass value="0.052437481"/>
      <inertia ixx="9.9585212e-05" iyy="4.609122e-05" izz="0.00013761069" ixy="6.8163621e-06" ixz="-2.2963821e-06" iyz="7.7297283e-06"/>
      <origin xyz="0.03048214 0.013147176 -0.022888666" rpy="0 0 0"/>
    </inertial>
  </link>
  <joint name="joint:dof_right_wrist00fix" type="fixed">
    <origin xyz="0.101 0.01735 -0.018" rpy="3.1415927 -1.5707963 0"/>
    <parent link="link:KC-C-401R_R_UpForearmDrive_(1)"/>
    <child link="link:RS00_(1)"/>
  </joint>
  <link name="link:RS00_(1)">
    <visual name="link:RS00_(1)_visual">
      <origin xyz="0 0 0" rpy="0 0 0"/>
      <geometry name="link:RS00_(1)_geometry">
        <mesh filename="meshes/RS00_(1).stl"/>
      </geometry>
      <material name="link:RS00_(1)_material">
        <color rgba="0.2627451 0.28235294 0.30196078 1"/>
      </material>
    </visual>
    <collision name="link:RS00_(1).collision">
      <origin xyz="0 0 0" rpy="0 0 0"/>
      <geometry name="link:RS00_(1)_collision_geometry">
        <mesh filename="meshes/RS00_(1).stl"/>
      </geometry>
    </collision>
    <inertial name="link:RS00_(1)_inertial">
      <mass value="0.31"/>
      <inertia ixx="0.00013088778" iyy="0.00013088778" izz="0.00012532318" ixy="0" ixz="0" iyz="0"/>
      <origin xyz="0 0 -0.025309195" rpy="0 0 0"/>
    </inertial>
  </link>
  <joint name="joint:dof_left_elbow_02" type="revolute">
    <origin xyz="0 0 0.0035" rpy="0 0 0"/>
    <parent link="link:RS02_(5)"/>
    <child link="link:KC-C-401L_L_UpForearmDrive_(1)"/>
    <limit effort="17" velocity="12.566" lower="-2.4783675" upper="0"/>
    <axis xyz="0 0 -1"/>
  </joint>
  <link name="link:KC-C-401L_L_UpForearmDrive_(1)">
    <visual name="link:KC-C-401L_L_UpForearmDrive_(1)_visual">
      <origin xyz="0 0 0" rpy="0 0 0"/>
      <geometry name="link:KC-C-401L_L_UpForearmDrive_(1)_geometry">
        <mesh filename="meshes/KC-C-401L_L_UpForearmDrive_(1).stl"/>
      </geometry>
      <material name="link:KC-C-401L_L_UpForearmDrive_(1)_material">
        <color rgba="0.2627451 0.28235294 0.30196078 1"/>
      </material>
    </visual>
    <collision name="link:KC-C-401L_L_UpForearmDrive_(1).collision">
      <origin xyz="0 0 0" rpy="0 0 0"/>
      <geometry name="link:KC-C-401L_L_UpForearmDrive_(1)_collision_geometry">
        <mesh filename="meshes/KC-C-401L_L_UpForearmDrive_(1).stl"/>
      </geometry>
    </collision>
    <inertial name="link:KC-C-401L_L_UpForearmDrive_(1)_inertial">
      <mass value="0.22278157"/>
      <inertia ixx="0.00021043513" iyy="0.00052508868" izz="0.00062353245" ixy="2.6975771e-05" ixz="-7.9155014e-05" iyz="1.1685136e-05"/>
      <origin xyz="-0.048275101 0.014047846 0.0038607081" rpy="0 0 0"/>
    </inertial>
  </link>
  <joint name="joint:dof_right_knee_04" type="revolute">
    <origin xyz="0 0 0" rpy="0 0 0"/>
    <parent link="link:RS04_(1)"/>
    <child link="link:KC-D-401R_R_Shin_Drive_(1)"/>
    <limit effort="120" velocity="6.283" lower="-2.7052603" upper="0"/>
    <axis xyz="0 0 1"/>
  </joint>
  <link name="link:KC-D-401R_R_Shin_Drive_(1)">
    <visual name="link:KC-D-401R_R_Shin_Drive_(1)_visual">
      <origin xyz="0 0 0" rpy="0 0 0"/>
      <geometry name="link:KC-D-401R_R_Shin_Drive_(1)_geometry">
        <mesh filename="meshes/KC-D-401R_R_Shin_Drive_(1).stl"/>
      </geometry>
      <material name="link:KC-D-401R_R_Shin_Drive_(1)_material">
        <color rgba="0.2627451 0.28235294 0.30196078 1"/>
      </material>
    </visual>
    <collision name="link:KC-D-401R_R_Shin_Drive_(1).collision">
      <origin xyz="0 0 0" rpy="0 0 0"/>
      <geometry name="link:KC-D-401R_R_Shin_Drive_(1)_collision_geometry">
        <mesh filename="meshes/KC-D-401R_R_Shin_Drive_(1).stl"/>
      </geometry>
    </collision>
    <inertial name="link:KC-D-401R_R_Shin_Drive_(1)_inertial">
      <mass value="0.55460769"/>
      <inertia ixx="0.0056690493" iyy="0.00062368976" izz="0.0061560222" ixy="0.00026601988" ixz="3.482373e-05" iyz="-0.00024965194"/>
      <origin xyz="-0.026421413 0.076046523 -0.015400551" rpy="0 0 0"/>
    </inertial>
  </link>
  <joint name="joint:dof_lower_thigh_drive_right" type="fixed">
    <origin xyz="0 0 0.039" rpy="3.1415927 0 0"/>
    <parent link="link:RS04_(1)"/>
    <child link="link:KC-D-302R_Femur_Lower_Idle_(1)"/>
  </joint>
  <link name="link:KC-D-302R_Femur_Lower_Idle_(1)">
    <visual name="link:KC-D-302R_Femur_Lower_Idle_(1)_visual">
      <origin xyz="0 0 0" rpy="0 0 0"/>
      <geometry name="link:KC-D-302R_Femur_Lower_Idle_(1)_geometry">
        <mesh filename="meshes/KC-D-302R_Femur_Lower_Idle_(1).stl"/>
      </geometry>
      <material name="link:KC-D-302R_Femur_Lower_Idle_(1)_material">
        <color rgba="0.2627451 0.28235294 0.30196078 1"/>
      </material>
    </visual>
    <collision name="link:KC-D-302R_Femur_Lower_Idle_(1).collision">
      <origin xyz="0 0 0" rpy="0 0 0"/>
      <geometry name="link:KC-D-302R_Femur_Lower_Idle_(1)_collision_geometry">
        <mesh filename="meshes/KC-D-302R_Femur_Lower_Idle_(1).stl"/>
      </geometry>
    </collision>
    <inertial name="link:KC-D-302R_Femur_Lower_Idle_(1)_inertial">
      <mass value="0.19499179"/>
      <inertia ixx="0.0012122912" iyy="0.00035053388" izz="0.0014983147" ixy="9.7545361e-05" ixz="-1.5324328e-05" iyz="0.00012495735"/>
      <origin xyz="-0.018288554 0.093785931 -0.015380242" rpy="0 0 0"/>
    </inertial>
  </link>
  <joint name="joint:dof_left_knee_04" type="revolute">
    <origin xyz="0 0 0" rpy="0 0 0"/>
    <parent link="link:RS04_(3)"/>
    <child link="link:KC-D-401L_L_Shin_Drive_(1)"/>
    <limit effort="120" velocity="6.283" lower="0" upper="2.7052603"/>
    <axis xyz="0 0 1"/>
  </joint>
  <link name="link:KC-D-401L_L_Shin_Drive_(1)">
    <visual name="link:KC-D-401L_L_Shin_Drive_(1)_visual">
      <origin xyz="0 0 0" rpy="0 0 0"/>
      <geometry name="link:KC-D-401L_L_Shin_Drive_(1)_geometry">
        <mesh filename="meshes/KC-D-401L_L_Shin_Drive_(1).stl"/>
      </geometry>
      <material name="link:KC-D-401L_L_Shin_Drive_(1)_material">
        <color rgba="0.2627451 0.28235294 0.30196078 1"/>
      </material>
    </visual>
    <collision name="link:KC-D-401L_L_Shin_Drive_(1).collision">
      <origin xyz="0 0 0" rpy="0 0 0"/>
      <geometry name="link:KC-D-401L_L_Shin_Drive_(1)_collision_geometry">
        <mesh filename="meshes/KC-D-401L_L_Shin_Drive_(1).stl"/>
      </geometry>
    </collision>
    <inertial name="link:KC-D-401L_L_Shin_Drive_(1)_inertial">
      <mass value="0.5545677"/>
      <inertia ixx="0.0056689659" iyy="0.00062361463" izz="0.0061558662" ixy="-0.00026597701" ixz="3.4818747e-05" iyz="0.00024965416"/>
      <origin xyz="-0.026423815 -0.076047627 -0.015400463" rpy="0 0 0"/>
    </inertial>
  </link>
  <joint name="joint:dof_lower_thigh_idle_left" type="fixed">
    <origin xyz="0 0 0.039" rpy="3.1415927 0 0"/>
    <parent link="link:RS04_(3)"/>
    <child link="link:KC-D-302L_L_Femur_Lower_Idle_(1)"/>
  </joint>
  <link name="link:KC-D-302L_L_Femur_Lower_Idle_(1)">
    <visual name="link:KC-D-302L_L_Femur_Lower_Idle_(1)_visual">
      <origin xyz="0 0 0" rpy="0 0 0"/>
      <geometry name="link:KC-D-302L_L_Femur_Lower_Idle_(1)_geometry">
        <mesh filename="meshes/KC-D-302L_L_Femur_Lower_Idle_(1).stl"/>
      </geometry>
      <material name="link:KC-D-302L_L_Femur_Lower_Idle_(1)_material">
        <color rgba="0.2627451 0.28235294 0.30196078 1"/>
      </material>
    </visual>
    <collision name="link:KC-D-302L_L_Femur_Lower_Idle_(1).collision">
      <origin xyz="0 0 0" rpy="0 0 0"/>
      <geometry name="link:KC-D-302L_L_Femur_Lower_Idle_(1)_collision_geometry">
        <mesh filename="meshes/KC-D-302L_L_Femur_Lower_Idle_(1).stl"/>
      </geometry>
    </collision>
    <inertial name="link:KC-D-302L_L_Femur_Lower_Idle_(1)_inertial">
      <mass value="0.19495904"/>
      <inertia ixx="0.0012122792" iyy="0.00035046993" izz="0.0014982429" ixy="-9.7580734e-05" ixz="-1.5334693e-05" iyz="-0.00012496846"/>
      <origin xyz="-0.018282455 -0.093788781 -0.015380124" rpy="0 0 0"/>
    </inertial>
  </link>
  <joint name="joint:dof_right_wrist_00" type="revolute">
    <origin xyz="0 0 0.001" rpy="3.1415927 0 0"/>
    <parent link="link:RS00_(1)"/>
    <child link="link:KB-C-501X_Right_Bayonet_Adapter_Hard_Stop_(1)"/>
    <limit effort="14" velocity="12.566" lower="-1.7453293" upper="1.7453293"/>
    <axis xyz="0 0 1"/>
  </joint>
  <link name="link:KB-C-501X_Right_Bayonet_Adapter_Hard_Stop_(1)">
    <visual name="link:KB-C-501X_Right_Bayonet_Adapter_Hard_Stop_(1)_visual">
      <origin xyz="0 0 0" rpy="0 0 0"/>
      <geometry name="link:KB-C-501X_Right_Bayonet_Adapter_Hard_Stop_(1)_geometry">
        <mesh filename="meshes/KB-C-501X_Right_Bayonet_Adapter_Hard_Stop_(1).stl"/>
      </geometry>
      <material name="link:KB-C-501X_Right_Bayonet_Adapter_Hard_Stop_(1)_material">
        <color rgba="0.2627451 0.28235294 0.30196078 1"/>
      </material>
    </visual>
    <collision name="link:KB-C-501X_Right_Bayonet_Adapter_Hard_Stop_(1).collision">
      <origin xyz="0 0 0" rpy="0 0 0"/>
      <geometry name="link:KB-C-501X_Right_Bayonet_Adapter_Hard_Stop_(1)_collision_geometry">
        <mesh filename="meshes/KB-C-501X_Right_Bayonet_Adapter_Hard_Stop_(1).stl"/>
      </geometry>
    </collision>
    <inertial name="link:KB-C-501X_Right_Bayonet_Adapter_Hard_Stop_(1)_inertial">
      <mass value="0.15219828"/>
      <inertia ixx="6.147539e-05" iyy="6.0523235e-05" izz="8.3857883e-05" ixy="0" ixz="0" iyz="0"/>
      <origin xyz="0.0041870181 6.7565325e-05 -0.01990547" rpy="0 0 0"/>
    </inertial>
  </link>
  <joint name="joint:dof_left_forearm_idle" type="fixed">
    <origin xyz="-0.0525 -0.01565 -0.026" rpy="0 0 1.5707963"/>
    <parent link="link:KC-C-401L_L_UpForearmDrive_(1)"/>
    <child link="link:KC-C-402L_Forearm_Upper_Idle_(2)"/>
  </joint>
  <link name="link:KC-C-402L_Forearm_Upper_Idle_(2)">
    <visual name="link:KC-C-402L_Forearm_Upper_Idle_(2)_visual">
      <origin xyz="0 0 0" rpy="0 0 0"/>
      <geometry name="link:KC-C-402L_Forearm_Upper_Idle_(2)_geometry">
        <mesh filename="meshes/KC-C-402L_Forearm_Upper_Idle_(2).stl"/>
      </geometry>
      <material name="link:KC-C-402L_Forearm_Upper_Idle_(2)_material">
        <color rgba="0.2627451 0.28235294 0.30196078 1"/>
      </material>
    </visual>
    <collision name="link:KC-C-402L_Forearm_Upper_Idle_(2).collision">
      <origin xyz="0 0 0" rpy="0 0 0"/>
      <geometry name="link:KC-C-402L_Forearm_Upper_Idle_(2)_collision_geometry">
        <mesh filename="meshes/KC-C-402L_Forearm_Upper_Idle_(2).stl"/>
      </geometry>
    </collision>
    <inertial name="link:KC-C-402L_Forearm_Upper_Idle_(2)_inertial">
      <mass value="0.052437909"/>
      <inertia ixx="9.9585809e-05" iyy="4.6093932e-05" izz="0.00013761395" ixy="-6.8208286e-06" ixz="-2.2965906e-06" iyz="-7.7297926e-06"/>
      <origin xyz="0.030480313 -0.01314614 -0.022888496" rpy="0 0 0"/>
    </inertial>
  </link>
  <joint name="joint:doft_left_wrist00fix" type="fixed">
    <origin xyz="-0.101 0.01735 -0.018" rpy="3.1415927 1.5707963 0"/>
    <parent link="link:KC-C-401L_L_UpForearmDrive_(1)"/>
    <child link="link:RS00_(2)"/>
  </joint>
  <link name="link:RS00_(2)">
    <visual name="link:RS00_(2)_visual">
      <origin xyz="0 0 0" rpy="0 0 0"/>
      <geometry name="link:RS00_(2)_geometry">
        <mesh filename="meshes/RS00_(2).stl"/>
      </geometry>
      <material name="link:RS00_(2)_material">
        <color rgba="0.2627451 0.28235294 0.30196078 1"/>
      </material>
    </visual>
    <collision name="link:RS00_(2).collision">
      <origin xyz="0 0 0" rpy="0 0 0"/>
      <geometry name="link:RS00_(2)_collision_geometry">
        <mesh filename="meshes/RS00_(2).stl"/>
      </geometry>
    </collision>
    <inertial name="link:RS00_(2)_inertial">
      <mass value="0.31"/>
      <inertia ixx="0.00013088778" iyy="0.00013088778" izz="0.00012532318" ixy="0" ixz="0" iyz="0"/>
      <origin xyz="0 0 -0.025309195" rpy="0 0 0"/>
    </inertial>
  </link>
  <joint name="joint:dof_shin_shells_right" type="fixed">
    <origin xyz="0.02440957 0.097730353 0.01075" rpy="3.1415927 0 0"/>
    <parent link="link:KC-D-401R_R_Shin_Drive_(1)"/>
    <child link="link:KC-D-402R_R_Shin_Idle_(1)"/>
  </joint>
  <link name="link:KC-D-402R_R_Shin_Idle_(1)">
    <visual name="link:KC-D-402R_R_Shin_Idle_(1)_visual">
      <origin xyz="0 0 0" rpy="0 0 0"/>
      <geometry name="link:KC-D-402R_R_Shin_Idle_(1)_geometry">
        <mesh filename="meshes/KC-D-402R_R_Shin_Idle_(1).stl"/>
      </geometry>
      <material name="link:KC-D-402R_R_Shin_Idle_(1)_material">
        <color rgba="0.2627451 0.28235294 0.30196078 1"/>
      </material>
    </visual>
    <collision name="link:KC-D-402R_R_Shin_Idle_(1).collision">
      <origin xyz="0 0 0" rpy="0 0 0"/>
      <geometry name="link:KC-D-402R_R_Shin_Idle_(1)_collision_geometry">
        <mesh filename="meshes/KC-D-402R_R_Shin_Idle_(1).stl"/>
      </geometry>
    </collision>
    <inertial name="link:KC-D-402R_R_Shin_Idle_(1)_inertial">
      <mass value="0.56360122"/>
      <inertia ixx="0.0056052922" iyy="0.000806669" izz="0.0060845871" ixy="8.574295e-05" ixz="6.191718e-05" iyz="0.00041975148"/>
      <origin xyz="-0.052930343 -0.017805202 -0.037704334" rpy="0 0 0"/>
    </inertial>
  </link>
  <joint name="joint:dof_lower_thigh_drive_left" type="fixed">
    <origin xyz="0.024061496 0.047223346 -0.005" rpy="0 0 0"/>
    <parent link="link:KC-D-302R_Femur_Lower_Idle_(1)"/>
    <child link="link:KC-D-403R_LEG-SHIN_COVER_vis_(1)"/>
  </joint>
  <link name="link:KC-D-403R_LEG-SHIN_COVER_vis_(1)">
    <visual name="link:KC-D-403R_LEG-SHIN_COVER_vis_(1)_visual">
      <origin xyz="0 0 0" rpy="0 0 0"/>
      <geometry name="link:KC-D-403R_LEG-SHIN_COVER_vis_(1)_geometry">
        <mesh filename="meshes/KC-D-403R_LEG-SHIN_COVER_vis_(1).stl"/>
      </geometry>
      <material name="link:KC-D-403R_LEG-SHIN_COVER_vis_(1)_material">
        <color rgba="0.91764706 0.91764706 0.91764706 1"/>
      </material>
    </visual>
    <collision name="link:KC-D-403R_LEG-SHIN_COVER_vis_(1).collision">
      <origin xyz="0 0 0" rpy="0 0 0"/>
      <geometry name="link:KC-D-403R_LEG-SHIN_COVER_vis_(1)_collision_geometry">
        <mesh filename="meshes/KC-D-403R_LEG-SHIN_COVER_vis_(1).stl"/>
      </geometry>
    </collision>
    <inertial name="link:KC-D-403R_LEG-SHIN_COVER_vis_(1)_inertial">
      <mass value="0.10620412"/>
      <inertia ixx="6.8457054e-05" iyy="9.7905826e-05" izz="0.0001630426" ixy="-2.0266378e-05" ixz="0" iyz="0"/>
      <origin xyz="-0.025304171 -0.044784459 -0.008884904" rpy="0 0 0"/>
    </inertial>
  </link>
  <joint name="joint:dof_shin_shells_left" type="fixed">
    <origin xyz="0.02440957 -0.097730353 0.01075" rpy="0 0 0"/>
    <parent link="link:KC-D-401L_L_Shin_Drive_(1)"/>
    <child link="link:KC-D-402L_L_Shin_Idle_(1)"/>
  </joint>
  <link name="link:KC-D-402L_L_Shin_Idle_(1)">
    <visual name="link:KC-D-402L_L_Shin_Idle_(1)_visual">
      <origin xyz="0 0 0" rpy="0 0 0"/>
      <geometry name="link:KC-D-402L_L_Shin_Idle_(1)_geometry">
        <mesh filename="meshes/KC-D-402L_L_Shin_Idle_(1).stl"/>
      </geometry>
      <material name="link:KC-D-402L_L_Shin_Idle_(1)_material">
        <color rgba="0.2627451 0.28235294 0.30196078 1"/>
      </material>
    </visual>
    <collision name="link:KC-D-402L_L_Shin_Idle_(1).collision">
      <origin xyz="0 0 0" rpy="0 0 0"/>
      <geometry name="link:KC-D-402L_L_Shin_Idle_(1)_collision_geometry">
        <mesh filename="meshes/KC-D-402L_L_Shin_Idle_(1).stl"/>
      </geometry>
    </collision>
    <inertial name="link:KC-D-402L_L_Shin_Idle_(1)_inertial">
      <mass value="0.56358397"/>
      <inertia ixx="0.0056050697" iyy="0.00080666169" izz="0.006084367" ixy="8.5714142e-05" ixz="-6.1921042e-05" iyz="-0.00041972397"/>
      <origin xyz="-0.052929329 -0.017808175 0.037703871" rpy="0 0 0"/>
    </inertial>
  </link>
  <joint name="joint:fixed_knee_idle_left" type="fixed">
    <origin xyz="0.024061496 -0.047223346 -0.005" rpy="0 0 0"/>
    <parent link="link:KC-D-302L_L_Femur_Lower_Idle_(1)"/>
    <child link="link:KC-D-403L_LEG-SHIN_COVER_vis_(1)"/>
  </joint>
  <link name="link:KC-D-403L_LEG-SHIN_COVER_vis_(1)">
    <visual name="link:KC-D-403L_LEG-SHIN_COVER_vis_(1)_visual">
      <origin xyz="0 0 0" rpy="0 0 0"/>
      <geometry name="link:KC-D-403L_LEG-SHIN_COVER_vis_(1)_geometry">
        <mesh filename="meshes/KC-D-403L_LEG-SHIN_COVER_vis_(1).stl"/>
      </geometry>
      <material name="link:KC-D-403L_LEG-SHIN_COVER_vis_(1)_material">
        <color rgba="0.91764706 0.91764706 0.91764706 1"/>
      </material>
    </visual>
    <collision name="link:KC-D-403L_LEG-SHIN_COVER_vis_(1).collision">
      <origin xyz="0 0 0" rpy="0 0 0"/>
      <geometry name="link:KC-D-403L_LEG-SHIN_COVER_vis_(1)_collision_geometry">
        <mesh filename="meshes/KC-D-403L_LEG-SHIN_COVER_vis_(1).stl"/>
      </geometry>
    </collision>
    <inertial name="link:KC-D-403L_LEG-SHIN_COVER_vis_(1)_inertial">
      <mass value="0.10620411"/>
      <inertia ixx="6.8457053e-05" iyy="9.7905826e-05" izz="0.0001630426" ixy="2.0266379e-05" ixz="0" iyz="0"/>
      <origin xyz="-0.025304172 0.044784458 -0.0088849038" rpy="0 0 0"/>
    </inertial>
  </link>
  <joint name="joint:dof_left_wrist_00" type="revolute">
    <origin xyz="0 0 0.001" rpy="0 0 0"/>
    <parent link="link:RS00_(2)"/>
    <child link="link:KB-C-501X_Left_Bayonet_Adapter_Hard_Stop_(1)"/>
    <limit effort="14" velocity="12.566" lower="-1.7453293" upper="1.7453293"/>
    <axis xyz="0 0 -1"/>
  </joint>
  <link name="link:KB-C-501X_Left_Bayonet_Adapter_Hard_Stop_(1)">
    <visual name="link:KB-C-501X_Left_Bayonet_Adapter_Hard_Stop_(1)_visual">
      <origin xyz="0 0 0" rpy="0 0 0"/>
      <geometry name="link:KB-C-501X_Left_Bayonet_Adapter_Hard_Stop_(1)_geometry">
        <mesh filename="meshes/KB-C-501X_Left_Bayonet_Adapter_Hard_Stop_(1).stl"/>
      </geometry>
      <material name="link:KB-C-501X_Left_Bayonet_Adapter_Hard_Stop_(1)_material">
        <color rgba="0.2627451 0.28235294 0.30196078 1"/>
      </material>
    </visual>
    <collision name="link:KB-C-501X_Left_Bayonet_Adapter_Hard_Stop_(1).collision">
      <origin xyz="0 0 0" rpy="0 0 0"/>
      <geometry name="link:KB-C-501X_Left_Bayonet_Adapter_Hard_Stop_(1)_collision_geometry">
        <mesh filename="meshes/KB-C-501X_Left_Bayonet_Adapter_Hard_Stop_(1).stl"/>
      </geometry>
    </collision>
    <inertial name="link:KB-C-501X_Left_Bayonet_Adapter_Hard_Stop_(1)_inertial">
      <mass value="0.15219821"/>
      <inertia ixx="6.1475317e-05" iyy="6.052323e-05" izz="8.3857809e-05" ixy="0" ixz="0" iyz="0"/>
      <origin xyz="-0.0041870225 -6.7530785e-05 0.019905469" rpy="0 0 0"/>
    </inertial>
  </link>
  <joint name="joint:dof_right_ankle_02" type="revolute">
    <origin xyz="-0.05440957 -0.19226965 -0.02535" rpy="3.1415927 0 0"/>
    <parent link="link:KC-D-402R_R_Shin_Idle_(1)"/>
    <child link="link:KB-D-501R_R_LEG-FOOT_(1)"/>
    <limit effort="17" velocity="12.566" lower="-0.29670597" upper="0.78539816"/>
    <axis xyz="0 0 1"/>
  </joint>
  <link name="link:KB-D-501R_R_LEG-FOOT_(1)">
    <visual name="link:KB-D-501R_R_LEG-FOOT_(1)_visual">
      <origin xyz="0 0 0" rpy="0 0 0"/>
      <geometry name="link:KB-D-501R_R_LEG-FOOT_(1)_geometry">
        <mesh filename="meshes/KB-D-501R_R_LEG-FOOT_(1).stl"/>
      </geometry>
      <material name="link:KB-D-501R_R_LEG-FOOT_(1)_material">
        <color rgba="0.2627451 0.28235294 0.30196078 1"/>
      </material>
    </visual>
    <collision name="link:KB-D-501R_R_LEG-FOOT_(1).collision">
      <origin xyz="0 0 0" rpy="0 0 0"/>
      <geometry name="link:KB-D-501R_R_LEG-FOOT_(1)_collision_geometry">
        <mesh filename="meshes/KB-D-501R_R_LEG-FOOT_(1).stl"/>
      </geometry>
    </collision>
    <inertial name="link:KB-D-501R_R_LEG-FOOT_(1)_inertial">
      <mass value="0.36488575"/>
      <inertia ixx="0.00018230305" iyy="0.0010668841" izz="0.00099128996" ixy="5.4278994e-05" ixz="2.4376413e-05" iyz="-1.3174892e-05"/>
      <origin xyz="-0.011200095 0.022318669 -0.016654577" rpy="0 0 0"/>
    </inertial>
  </link>
  <joint name="joint:fix_ankle_bolt_right" type="fixed">
    <origin xyz="-0.05440957 -0.19226965 -0.03275" rpy="3.1415927 0 0"/>
    <parent link="link:KC-D-402R_R_Shin_Idle_(1)"/>
    <child link="link:KB-D-504X_BOLT_ANKLE_R_vis_(1)"/>
  </joint>
  <link name="link:KB-D-504X_BOLT_ANKLE_R_vis_(1)">
    <visual name="link:KB-D-504X_BOLT_ANKLE_R_vis_(1)_visual">
      <origin xyz="0 0 0" rpy="0 0 0"/>
      <geometry name="link:KB-D-504X_BOLT_ANKLE_R_vis_(1)_geometry">
        <mesh filename="meshes/KB-D-504X_BOLT_ANKLE_R_vis_(1).stl"/>
      </geometry>
      <material name="link:KB-D-504X_BOLT_ANKLE_R_vis_(1)_material">
        <color rgba="0.2627451 0.28235294 0.30196078 1"/>
      </material>
    </visual>
    <collision name="link:KB-D-504X_BOLT_ANKLE_R_vis_(1).collision">
      <origin xyz="0 0 0" rpy="0 0 0"/>
      <geometry name="link:KB-D-504X_BOLT_ANKLE_R_vis_(1)_collision_geometry">
        <mesh filename="meshes/KB-D-504X_BOLT_ANKLE_R_vis_(1).stl"/>
      </geometry>
    </collision>
    <inertial name="link:KB-D-504X_BOLT_ANKLE_R_vis_(1)_inertial">
      <mass value="0.028063921"/>
      <inertia ixx="8.3444869e-06" iyy="8.2733002e-06" izz="1e-06" ixy="0" ixz="0" iyz="0"/>
      <origin xyz="0 0 -0.02289859" rpy="0 0 0"/>
    </inertial>
  </link>
  <joint name="joint:dof_right_anklemotor" type="fixed">
    <origin xyz="-0.04440957 -0.0072696472 -0.02825" rpy="3.1415927 0 -1.5707963"/>
    <parent link="link:KC-D-402R_R_Shin_Idle_(1)"/>
    <child link="link:RS02_(1)"/>
  </joint>
  <link name="link:RS02_(1)">
    <visual name="link:RS02_(1)_visual">
      <origin xyz="0 0 0" rpy="0 0 0"/>
      <geometry name="link:RS02_(1)_geometry">
        <mesh filename="meshes/RS02_(1).stl"/>
      </geometry>
      <material name="link:RS02_(1)_material">
        <color rgba="0.2627451 0.28235294 0.30196078 1"/>
      </material>
    </visual>
    <collision name="link:RS02_(1).collision">
      <origin xyz="0 0 0" rpy="0 0 0"/>
      <geometry name="link:RS02_(1)_collision_geometry">
        <mesh filename="meshes/RS02_(1).stl"/>
      </geometry>
    </collision>
    <inertial name="link:RS02_(1)_inertial">
      <mass value="0.4"/>
      <inertia ixx="0.00018548163" iyy="0.00018548163" izz="0.00028416296" ixy="0" ixz="0" iyz="0"/>
      <origin xyz="0 0 -0.011585135" rpy="0 0 0"/>
    </inertial>
  </link>
  <joint name="joint:dof_left_ankle_02" type="revolute">
    <origin xyz="-0.05440957 -0.19226965 0.02535" rpy="3.1415927 0 0"/>
    <parent link="link:KC-D-402L_L_Shin_Idle_(1)"/>
    <child link="link:KB-D-501L_L_LEG-FOOT_(1)"/>
    <limit effort="17" velocity="12.566" lower="-0.78539816" upper="0.29670597"/>
    <axis xyz="0 0 -1"/>
  </joint>
  <link name="link:KB-D-501L_L_LEG-FOOT_(1)">
    <visual name="link:KB-D-501L_L_LEG-FOOT_(1)_visual">
      <origin xyz="0 0 0" rpy="0 0 0"/>
      <geometry name="link:KB-D-501L_L_LEG-FOOT_(1)_geometry">
        <mesh filename="meshes/KB-D-501L_L_LEG-FOOT_(1).stl"/>
      </geometry>
      <material name="link:KB-D-501L_L_LEG-FOOT_(1)_material">
        <color rgba="0.2627451 0.28235294 0.30196078 1"/>
      </material>
    </visual>
    <collision name="link:KB-D-501L_L_LEG-FOOT_(1).collision">
      <origin xyz="0 0 0" rpy="0 0 0"/>
      <geometry name="link:KB-D-501L_L_LEG-FOOT_(1)_collision_geometry">
        <mesh filename="meshes/KB-D-501L_L_LEG-FOOT_(1).stl"/>
      </geometry>
    </collision>
    <inertial name="link:KB-D-501L_L_LEG-FOOT_(1)_inertial">
      <mass value="0.36488621"/>
      <inertia ixx="0.00018230309" iyy="0.0010668847" izz="0.00099129045" ixy="5.4278812e-05" ixz="-2.4376368e-05" iyz="1.317475e-05"/>
      <origin xyz="-0.011200082 0.022318659 0.016654652" rpy="0 0 0"/>
    </inertial>
  </link>
  <joint name="joint:fix_ankle_bolt_left" type="fixed">
    <origin xyz="-0.05440957 -0.19226965 0.03275" rpy="3.1415927 0 0"/>
    <parent link="link:KC-D-402L_L_Shin_Idle_(1)"/>
    <child link="link:KB-D-504X_BOLT_ANKLE_L_vis_(1)"/>
  </joint>
  <link name="link:KB-D-504X_BOLT_ANKLE_L_vis_(1)">
    <visual name="link:KB-D-504X_BOLT_ANKLE_L_vis_(1)_visual">
      <origin xyz="0 0 0" rpy="0 0 0"/>
      <geometry name="link:KB-D-504X_BOLT_ANKLE_L_vis_(1)_geometry">
        <mesh filename="meshes/KB-D-504X_BOLT_ANKLE_L_vis_(1).stl"/>
      </geometry>
      <material name="link:KB-D-504X_BOLT_ANKLE_L_vis_(1)_material">
        <color rgba="0.2627451 0.28235294 0.30196078 1"/>
      </material>
    </visual>
    <collision name="link:KB-D-504X_BOLT_ANKLE_L_vis_(1).collision">
      <origin xyz="0 0 0" rpy="0 0 0"/>
      <geometry name="link:KB-D-504X_BOLT_ANKLE_L_vis_(1)_collision_geometry">
        <mesh filename="meshes/KB-D-504X_BOLT_ANKLE_L_vis_(1).stl"/>
      </geometry>
    </collision>
    <inertial name="link:KB-D-504X_BOLT_ANKLE_L_vis_(1)_inertial">
      <mass value="0.028063921"/>
      <inertia ixx="8.3444869e-06" iyy="8.2733002e-06" izz="1e-06" ixy="0" ixz="0" iyz="0"/>
      <origin xyz="0 0 0.02289859" rpy="0 0 0"/>
    </inertial>
  </link>
  <joint name="joint:dof_left_anklemotor" type="fixed">
    <origin xyz="-0.04440957 -0.0072696472 0.02825" rpy="3.1415927 0 0"/>
    <parent link="link:KC-D-402L_L_Shin_Idle_(1)"/>
    <child link="link:RS02_(4)"/>
  </joint>
  <link name="link:RS02_(4)">
    <visual name="link:RS02_(4)_visual">
      <origin xyz="0 0 0" rpy="0 0 0"/>
      <geometry name="link:RS02_(4)_geometry">
        <mesh filename="meshes/RS02_(4).stl"/>
      </geometry>
      <material name="link:RS02_(4)_material">
        <color rgba="0.2627451 0.28235294 0.30196078 1"/>
      </material>
    </visual>
    <collision name="link:RS02_(4).collision">
      <origin xyz="0 0 0" rpy="0 0 0"/>
      <geometry name="link:RS02_(4)_collision_geometry">
        <mesh filename="meshes/RS02_(4).stl"/>
      </geometry>
    </collision>
    <inertial name="link:RS02_(4)_inertial">
      <mass value="0.4"/>
      <inertia ixx="0.00018548163" iyy="0.00018548163" izz="0.00028416296" ixy="0" ixz="0" iyz="0"/>
      <origin xyz="0 0 0.011585135" rpy="0 0 0"/>
    </inertial>
  </link>
  <joint name="joint:dof_feet_pad_right" type="fixed">
    <origin xyz="-0.1133243 0.038 -0.034" rpy="1.5707963 1.5707963 0"/>
    <parent link="link:KB-D-501R_R_LEG-FOOT_(1)"/>
    <child link="link:Flat_Foot_Pad_Right_(1)"/>
  </joint>
  <link name="link:Flat_Foot_Pad_Right_(1)">
    <visual name="link:Flat_Foot_Pad_Right_(1)_visual">
      <origin xyz="0 0 0" rpy="0 0 0"/>
      <geometry name="link:Flat_Foot_Pad_Right_(1)_geometry">
        <mesh filename="meshes/Flat_Foot_Pad_Right_(1).stl"/>
      </geometry>
      <material name="link:Flat_Foot_Pad_Right_(1)_material">
        <color rgba="0.2627451 0.28235294 0.30196078 1"/>
      </material>
    </visual>
    <collision name="link:Flat_Foot_Pad_Right_(1).collision">
      <origin xyz="0 0 0" rpy="0 0 0"/>
      <geometry name="link:Flat_Foot_Pad_Right_(1)_collision_geometry">
        <mesh filename="meshes/Flat_Foot_Pad_Right_(1).stl"/>
      </geometry>
    </collision>
    <inertial name="link:Flat_Foot_Pad_Right_(1)_inertial">
      <mass value="0.1189719"/>
      <inertia ixx="0.00041226643" iyy="5.0964102e-05" izz="0.00046197187" ixy="4.9197431e-06" ixz="0" iyz="0"/>
      <origin xyz="-0.019580813 0.08731067 -0.0039224686" rpy="0 0 0"/>
    </inertial>
  </link>
  <joint name="joint:fix_ankle_motor2" type="fixed">
    <origin xyz="0 0 -0.0315" rpy="3.1415927 0 0"/>
    <parent link="link:RS02_(1)"/>
    <child link="link:KB-D-502R_ANKLE-SHAFT_vis_(1)"/>
  </joint>
  <link name="link:KB-D-502R_ANKLE-SHAFT_vis_(1)">
    <visual name="link:KB-D-502R_ANKLE-SHAFT_vis_(1)_visual">
      <origin xyz="0 0 0" rpy="0 0 0"/>
      <geometry name="link:KB-D-502R_ANKLE-SHAFT_vis_(1)_geometry">
        <mesh filename="meshes/KB-D-502R_ANKLE-SHAFT_vis_(1).stl"/>
      </geometry>
      <material name="link:KB-D-502R_ANKLE-SHAFT_vis_(1)_material">
        <color rgba="0.2627451 0.28235294 0.30196078 1"/>
      </material>
    </visual>
    <collision name="link:KB-D-502R_ANKLE-SHAFT_vis_(1).collision">
      <origin xyz="0 0 0" rpy="0 0 0"/>
      <geometry name="link:KB-D-502R_ANKLE-SHAFT_vis_(1)_collision_geometry">
        <mesh filename="meshes/KB-D-502R_ANKLE-SHAFT_vis_(1).stl"/>
      </geometry>
    </collision>
    <inertial name="link:KB-D-502R_ANKLE-SHAFT_vis_(1)_inertial">
      <mass value="0.063549526"/>
      <inertia ixx="1.3605452e-05" iyy="1.1742686e-05" izz="2.1808786e-05" ixy="2.851718e-06" ixz="0" iyz="-1.1103707e-06"/>
      <origin xyz="-0.0034958494 0.0039179227 0.0075410399" rpy="0 0 0"/>
    </inertial>
  </link>
  <joint name="joint:fix_ankle_motor3" type="fixed">
    <origin xyz="0 0 -0.028" rpy="0 0 -1.5707963"/>
    <parent link="link:RS02_(1)"/>
    <child link="link:KC-D-506R_EndStop_80deg_vis_(1)"/>
  </joint>
  <link name="link:KC-D-506R_EndStop_80deg_vis_(1)">
    <visual name="link:KC-D-506R_EndStop_80deg_vis_(1)_visual">
      <origin xyz="0 0 0" rpy="0 0 0"/>
      <geometry name="link:KC-D-506R_EndStop_80deg_vis_(1)_geometry">
        <mesh filename="meshes/KC-D-506R_EndStop_80deg_vis_(1).stl"/>
      </geometry>
      <material name="link:KC-D-506R_EndStop_80deg_vis_(1)_material">
        <color rgba="0.2627451 0.28235294 0.30196078 1"/>
      </material>
    </visual>
    <collision name="link:KC-D-506R_EndStop_80deg_vis_(1).collision">
      <origin xyz="0 0 0" rpy="0 0 0"/>
      <geometry name="link:KC-D-506R_EndStop_80deg_vis_(1)_collision_geometry">
        <mesh filename="meshes/KC-D-506R_EndStop_80deg_vis_(1).stl"/>
      </geometry>
    </collision>
    <inertial name="link:KC-D-506R_EndStop_80deg_vis_(1)_inertial">
      <mass value="0.015244989"/>
      <inertia ixx="7.1070955e-06" iyy="1.7792102e-06" izz="8.7258664e-06" ixy="0" ixz="0" iyz="0"/>
      <origin xyz="-0.0211358 -0.001498874 -0.00098372138" rpy="0 0 0"/>
    </inertial>
  </link>
  <joint name="joint:dof_feet_pad_left" type="fixed">
    <origin xyz="-0.1133243 0.038 0.034" rpy="1.5707963 1.5707963 0"/>
    <parent link="link:KB-D-501L_L_LEG-FOOT_(1)"/>
    <child link="link:Flat_Foot_Pad_Left_(1)"/>
  </joint>
  <link name="link:Flat_Foot_Pad_Left_(1)">
    <visual name="link:Flat_Foot_Pad_Left_(1)_visual">
      <origin xyz="0 0 0" rpy="0 0 0"/>
      <geometry name="link:Flat_Foot_Pad_Left_(1)_geometry">
        <mesh filename="meshes/Flat_Foot_Pad_Left_(1).stl"/>
      </geometry>
      <material name="link:Flat_Foot_Pad_Left_(1)_material">
        <color rgba="0.2627451 0.28235294 0.30196078 1"/>
      </material>
    </visual>
    <collision name="link:Flat_Foot_Pad_Left_(1).collision">
      <origin xyz="0 0 0" rpy="0 0 0"/>
      <geometry name="link:Flat_Foot_Pad_Left_(1)_collision_geometry">
        <mesh filename="meshes/Flat_Foot_Pad_Left_(1).stl"/>
      </geometry>
    </collision>
    <inertial name="link:Flat_Foot_Pad_Left_(1)_inertial">
      <mass value="0.1189719"/>
      <inertia ixx="0.00041226643" iyy="5.0964102e-05" izz="0.00046197187" ixy="-4.9197431e-06" ixz="0" iyz="0"/>
      <origin xyz="0.019580813 0.08731067 -0.0039224686" rpy="0 0 0"/>
    </inertial>
  </link>
  <joint name="joint:fix_ankle_motor2" type="fixed">
    <origin xyz="0 0 0.0315" rpy="0 0 -1.5707963"/>
    <parent link="link:RS02_(4)"/>
    <child link="link:KB-D-502L_ANKLE-SHAFT_vis_(1)"/>
  </joint>
  <link name="link:KB-D-502L_ANKLE-SHAFT_vis_(1)">
    <visual name="link:KB-D-502L_ANKLE-SHAFT_vis_(1)_visual">
      <origin xyz="0 0 0" rpy="0 0 0"/>
      <geometry name="link:KB-D-502L_ANKLE-SHAFT_vis_(1)_geometry">
        <mesh filename="meshes/KB-D-502L_ANKLE-SHAFT_vis_(1).stl"/>
      </geometry>
      <material name="link:KB-D-502L_ANKLE-SHAFT_vis_(1)_material">
        <color rgba="0.2627451 0.28235294 0.30196078 1"/>
      </material>
    </visual>
    <collision name="link:KB-D-502L_ANKLE-SHAFT_vis_(1).collision">
      <origin xyz="0 0 0" rpy="0 0 0"/>
      <geometry name="link:KB-D-502L_ANKLE-SHAFT_vis_(1)_collision_geometry">
        <mesh filename="meshes/KB-D-502L_ANKLE-SHAFT_vis_(1).stl"/>
      </geometry>
    </collision>
    <inertial name="link:KB-D-502L_ANKLE-SHAFT_vis_(1)_inertial">
      <mass value="0.063549526"/>
      <inertia ixx="1.360556e-05" iyy="1.1742556e-05" izz="2.1808764e-05" ixy="-2.8516078e-06" ixz="0" iyz="-1.1103842e-06"/>
      <origin xyz="0.0034959308 0.0039178903 0.00754104" rpy="0 0 0"/>
    </inertial>
  </link>
  <joint name="joint:fix_ankle_motor3" type="fixed">
    <origin xyz="0 0 0.028" rpy="3.1415927 0 0"/>
    <parent link="link:RS02_(4)"/>
    <child link="link:KC-D-506L_EndStop_80deg_vis_(1)"/>
  </joint>
  <link name="link:KC-D-506L_EndStop_80deg_vis_(1)">
    <visual name="link:KC-D-506L_EndStop_80deg_vis_(1)_visual">
      <origin xyz="0 0 0" rpy="0 0 0"/>
      <geometry name="link:KC-D-506L_EndStop_80deg_vis_(1)_geometry">
        <mesh filename="meshes/KC-D-506L_EndStop_80deg_vis_(1).stl"/>
      </geometry>
      <material name="link:KC-D-506L_EndStop_80deg_vis_(1)_material">
        <color rgba="0.2627451 0.28235294 0.30196078 1"/>
      </material>
    </visual>
    <collision name="link:KC-D-506L_EndStop_80deg_vis_(1).collision">
      <origin xyz="0 0 0" rpy="0 0 0"/>
      <geometry name="link:KC-D-506L_EndStop_80deg_vis_(1)_collision_geometry">
        <mesh filename="meshes/KC-D-506L_EndStop_80deg_vis_(1).stl"/>
      </geometry>
    </collision>
    <inertial name="link:KC-D-506L_EndStop_80deg_vis_(1)_inertial">
      <mass value="0.015245117"/>
      <inertia ixx="7.107162e-06" iyy="1.7792153e-06" izz="8.7259341e-06" ixy="0" ixz="0" iyz="0"/>
      <origin xyz="-0.021135759 0.0014990275 -0.00098374408" rpy="0 0 0"/>
    </inertial>
  </link>
  <joint name="joint:fix_ankle_motor" type="fixed">
    <origin xyz="-0.011238198 0.027815516 0.0134" rpy="3.1415927 0 1.5707963"/>
    <parent link="link:KB-D-502R_ANKLE-SHAFT_vis_(1)"/>
    <child link="link:KB-D-503X_ANKLE_LINK-S-RIGHT_vis_(1)"/>
  </joint>
  <link name="link:KB-D-503X_ANKLE_LINK-S-RIGHT_vis_(1)">
    <visual name="link:KB-D-503X_ANKLE_LINK-S-RIGHT_vis_(1)_visual">
      <origin xyz="0 0 0" rpy="0 0 0"/>
      <geometry name="link:KB-D-503X_ANKLE_LINK-S-RIGHT_vis_(1)_geometry">
        <mesh filename="meshes/KB-D-503X_ANKLE_LINK-S-RIGHT_vis_(1).stl"/>
      </geometry>
      <material name="link:KB-D-503X_ANKLE_LINK-S-RIGHT_vis_(1)_material">
        <color rgba="0.2627451 0.28235294 0.30196078 1"/>
      </material>
    </visual>
    <collision name="link:KB-D-503X_ANKLE_LINK-S-RIGHT_vis_(1).collision">
      <origin xyz="0 0 0" rpy="0 0 0"/>
      <geometry name="link:KB-D-503X_ANKLE_LINK-S-RIGHT_vis_(1)_collision_geometry">
        <mesh filename="meshes/KB-D-503X_ANKLE_LINK-S-RIGHT_vis_(1).stl"/>
      </geometry>
    </collision>
    <inertial name="link:KB-D-503X_ANKLE_LINK-S-RIGHT_vis_(1)_inertial">
      <mass value="0.045524578"/>
      <inertia ixx="0.00017086846" iyy="1.0280965e-06" izz="0.00017143364" ixy="5.9381976e-06" ixz="0" iyz="0"/>
      <origin xyz="-0.0032735728 0.09374286 0.004" rpy="0 0 0"/>
    </inertial>
  </link>
  <joint name="joint:fix_ankle_motor" type="fixed">
    <origin xyz="0.011238198 0.027815516 0.0134" rpy="3.1415927 0 1.5707963"/>
    <parent link="link:KB-D-502L_ANKLE-SHAFT_vis_(1)"/>
    <child link="link:KB-D-503X_ANKLE_LINK-S-LEFT_vis_(1)"/>
  </joint>
  <link name="link:KB-D-503X_ANKLE_LINK-S-LEFT_vis_(1)">
    <visual name="link:KB-D-503X_ANKLE_LINK-S-LEFT_vis_(1)_visual">
      <origin xyz="0 0 0" rpy="0 0 0"/>
      <geometry name="link:KB-D-503X_ANKLE_LINK-S-LEFT_vis_(1)_geometry">
        <mesh filename="meshes/KB-D-503X_ANKLE_LINK-S-LEFT_vis_(1).stl"/>
      </geometry>
      <material name="link:KB-D-503X_ANKLE_LINK-S-LEFT_vis_(1)_material">
        <color rgba="0.2627451 0.28235294 0.30196078 1"/>
      </material>
    </visual>
    <collision name="link:KB-D-503X_ANKLE_LINK-S-LEFT_vis_(1).collision">
      <origin xyz="0 0 0" rpy="0 0 0"/>
      <geometry name="link:KB-D-503X_ANKLE_LINK-S-LEFT_vis_(1)_collision_geometry">
        <mesh filename="meshes/KB-D-503X_ANKLE_LINK-S-LEFT_vis_(1).stl"/>
      </geometry>
    </collision>
    <inertial name="link:KB-D-503X_ANKLE_LINK-S-LEFT_vis_(1)_inertial">
      <mass value="0.045524578"/>
      <inertia ixx="0.00017086846" iyy="1.0280965e-06" izz="0.00017143364" ixy="-5.9381976e-06" ixz="0" iyz="0"/>
      <origin xyz="-0.0032735728 -0.09374286 0.004" rpy="0 0 0"/>
    </inertial>
  </link>
</robot>
