<?xml version="1.0" ?>
<robot name="top_level_assy_[urdf]">
  <link name="floating_base_link">
    <visual name="floating_base_link_visual">
      <geometry name="floating_base_link_geometry">
        <sphere radius="0.01"/>
      </geometry>
      <material name="floating_base_link_material">
        <color rgba="1 0 0 1"/>
      </material>
      <origin xyz="0 0 0" rpy="0.00 0.00 1.57"/>
    </visual>
    <inertial name="floating_base_link_inertial">
      <mass value="0.001"/>
      <inertia ixx="0.000001" iyy="0.000001" izz="0.000002" ixy="0" ixz="0" iyz="0"/>
      <origin xyz="0 0 0" rpy="0.00 0.00 1.57"/>
    </inertial>
  </link>
  <joint name="floating_base_joint" type="fixed">
    <parent link="floating_base_link"/>
    <child link="Z_BOT2_MASTER_BODY_SKELETON"/>
    <origin xyz="0 0 0" rpy="0.00 0.00 1.57"/>
  </joint>
  <joint name="imu" type="fixed">
    <origin xyz="0.042470 0.026490 -0.025518" rpy="1.570796 0 1.570796"/>
    <parent link="Z_BOT2_MASTER_BODY_SKELETON"/>
    <child link="IMU"/>
  </joint>
  <joint name="right_shoulder_yaw" type="revolute">
    <origin xyz="-0.055995 -0.010610 -0.009528" rpy="-1.570796 0 0"/>
    <parent link="Z_BOT2_MASTER_BODY_SKELETON"/>
    <child link="Z_BOT2_MASTER_SHOULDER2"/>
    <limit effort="2" velocity="2" lower="-0.174533" upper="1.221731"/>
    <axis xyz="0 0 1"/>
  </joint>
  <joint name="left_shoulder_yaw" type="revolute">
    <origin xyz="0.055995 -0.010610 -0.009528" rpy="1.570796 0 0"/>
    <parent link="Z_BOT2_MASTER_BODY_SKELETON"/>
    <child link="Z_BOT2_MASTER_SHOULDER2_1"/>
    <limit effort="2" velocity="2" lower="-1.221731" upper="0.174533"/>
    <axis xyz="0 0 -1"/>
  </joint>
  <joint name="left_hip_yaw" type="revolute">
    <origin xyz="0.042868 -0.002265 -0.123018" rpy="-3.141593 0 0"/>
    <parent link="Z_BOT2_MASTER_BODY_SKELETON"/>
    <child link="Hip_Bracket"/>
    <limit effort="2" velocity="2" lower="-1.570796" upper="1.570796"/>
    <axis xyz="0 0 -1"/>
  </joint>
  <joint name="right_shoulder_pitch" type="revolute">
    <origin xyz="-0.020845 0.004900 0.018800" rpy="3.141593 -1.570796 0"/>
    <parent link="Z_BOT2_MASTER_SHOULDER2"/>
    <child link="FK_AP_019_25T_11"/>
    <limit effort="2" velocity="2" lower="-3.141593" upper="3.141593"/>
    <axis xyz="0 0 1"/>
  </joint>
  <joint name="left_shoulder_pitch" type="revolute">
    <origin xyz="0.020845 -0.004900 -0.018800" rpy="3.141593 1.570796 0"/>
    <parent link="Z_BOT2_MASTER_SHOULDER2_1"/>
    <child link="FK_AP_019_25T_11_1"/>
    <limit effort="2" velocity="2" lower="-3.141593" upper="3.141593"/>
    <axis xyz="0 0 1"/>
  </joint>
  <joint name="left_hip_roll" type="revolute">
    <origin xyz="0.000087 -0.019650 0.024075" rpy="1.570796 0 0"/>
    <parent link="Hip_Bracket"/>
    <child link="ST15_4"/>
    <limit effort="2" velocity="2" lower="-0.610865" upper="0.610865"/>
    <axis xyz="0 0 -1"/>
  </joint>
  <joint name="right_hip_yaw" type="revolute">
    <origin xyz="-0.042868 -0.002265 -0.123018" rpy="-3.141593 0 0"/>
    <parent link="Z_BOT2_MASTER_BODY_SKELETON"/>
    <child link="Hip_Bracket_2"/>
    <limit effort="2" velocity="2" lower="-1.570796" upper="1.570796"/>
    <axis xyz="0 0 -1"/>
  </joint>
  <joint name="right_hip_roll" type="revolute">
    <origin xyz="-0.000087 -0.019650 0.024075" rpy="1.570796 0 0"/>
    <parent link="Hip_Bracket_2"/>
    <child link="ST15_7"/>
    <limit effort="2" velocity="2" lower="-0.610865" upper="0.610865"/>
    <axis xyz="0 0 -1"/>
  </joint>
  <joint name="right_elbow_yaw" type="revolute">
    <origin xyz="-0.019800 -0.092984 -0.018600" rpy="-3.141593 -1.570796 0"/>
    <parent link="FK_AP_019_25T_11"/>
    <child link="L_ARM_MIRROR_1"/>
    <limit effort="2" velocity="2" lower="-1.570796" upper="0.872665"/>
    <axis xyz="0 0 1"/>
  </joint>
  <joint name="left_elbow_yaw" type="revolute">
    <origin xyz="-0.019800 0.092984 -0.018600" rpy="0 1.570796 0"/>
    <parent link="FK_AP_019_25T_11_1"/>
    <child link="R_ARM_MIRROR_1"/>
    <limit effort="2" velocity="2" lower="-0.872665" upper="1.570796"/>
    <axis xyz="0 0 1"/>
  </joint>
  <joint name="left_hip_pitch" type="revolute">
    <origin xyz="-0.019800 0 -0.016150" rpy="-3.141593 -1.570796 0"/>
    <parent link="ST15_4"/>
    <child link="Upper_Leg"/>
    <limit effort="2" velocity="2" lower="-1.570796" upper="0.872665"/>
    <axis xyz="0 0 1"/>
  </joint>
  <joint name="left_knee_pitch" type="revolute">
    <origin xyz="0 -0.100000 0.001260" rpy="3.141593 0 0"/>
    <parent link="Upper_Leg"/>
    <child link="ST15_12"/>
    <limit effort="2" velocity="2" lower="-1.396263" upper="1.396263"/>
    <axis xyz="0 0 1"/>
  </joint>
  <joint name="right_gripper" type="revolute">
    <origin xyz="-0.011778 0.066206 -0.001260" rpy="-3.141593 0 0"/>
    <parent link="L_ARM_MIRROR_1"/>
    <child link="FINGER_1"/>
    <limit effort="2" velocity="2" lower="-0.523599" upper="0.523599"/>
    <axis xyz="0 0 -1"/>
  </joint>
  <joint name="left_gripper" type="revolute">
    <origin xyz="0.011778 0.066206 -0.001260" rpy="-3.141593 0 0"/>
    <parent link="R_ARM_MIRROR_1"/>
    <child link="FINGER_1_1"/>
    <limit effort="2" velocity="2" lower="-0.523599" upper="0.523599"/>
    <axis xyz="0 0 -1"/>
  </joint>
  <joint name="right_hip_pitch" type="revolute">
    <origin xyz="0.018800 0 -0.016150" rpy="-3.141593 -1.570796 0"/>
    <parent link="ST15_7"/>
    <child link="Upper_Leg_2"/>
    <limit effort="2" velocity="2" lower="-1.570796" upper="0.872665"/>
    <axis xyz="0 0 -1"/>
  </joint>
  <joint name="right_knee_pitch" type="revolute">
    <origin xyz="0 -0.100000 -0.036399" rpy="3.141593 0 0"/>
    <parent link="Upper_Leg_2"/>
    <child link="ST15_13"/>
    <limit effort="2" velocity="2" lower="-1.396263" upper="1.396263"/>
    <axis xyz="0 0 1"/>
  </joint>
  <joint name="left_ankle_pitch" type="revolute">
    <origin xyz="0 0.100000 -0.036340" rpy="-3.141593 0 0"/>
    <parent link="ST15_12"/>
    <child link="ST15_14"/>
    <limit effort="2" velocity="2" lower="-1.396263" upper="0.698132"/>
    <axis xyz="0 0 1"/>
  </joint>
  <joint name="right_ankle_pitch" type="revolute">
    <origin xyz="0 0.100000 -0.036340" rpy="-3.141593 0 0"/>
    <parent link="ST15_13"/>
    <child link="ST15_15"/>
    <limit effort="2" velocity="2" lower="-1.396263" upper="0.698132"/>
    <axis xyz="0 0 1"/>
  </joint>
  <joint name="left_ankle_roll" type="revolute">
    <origin xyz="0.015150 0 -0.018800" rpy="-3.141593 -1.570796 0"/>
    <parent link="ST15_14"/>
    <child link="Left_Foot"/>
    <limit effort="2" velocity="2" lower="-1.047198" upper="1.047198"/>
    <axis xyz="0 0 1"/>
  </joint>
  <joint name="right_ankle_roll" type="revolute">
    <origin xyz="0.015150 0 -0.018800" rpy="-3.141593 -1.570796 0"/>
    <parent link="ST15_15"/>
    <child link="Right_Foot"/>
    <limit effort="2" velocity="2" lower="-1.047198" upper="1.047198"/>
    <axis xyz="0 0 1"/>
  </joint>
  <link name="Z_BOT2_MASTER_BODY_SKELETON">
    <visual name="Z_BOT2_MASTER_BODY_SKELETON_visual">
      <origin xyz="0 0 0" rpy="0 0 0"/>
      <geometry name="Z_BOT2_MASTER_BODY_SKELETON_geometry">
        <mesh filename="meshes/Z_BOT2_MASTER_BODY_SKELETON.stl"/>
      </geometry>
      <material name="Z_BOT2_MASTER_BODY_SKELETON_material">
        <color rgba="0.494118 0.623529 0.749020 1"/>
      </material>
    </visual>
    <inertial name="Z_BOT2_MASTER_BODY_SKELETON_inertial">
      <mass value="1.209796"/>
      <inertia ixx="0.003041" iyy="0.003682" izz="0.001756" ixy="0.000010" ixz="0.000008" iyz="-0.000158"/>
      <origin xyz="-0.000316 0.007954 -0.043762" rpy="0 0 0"/>
    </inertial>
  </link>
  <link name="IMU">
    <visual name="IMU_visual">
      <origin xyz="0 0 0" rpy="0 0 0"/>
      <geometry name="IMU_geometry">
        <mesh filename="meshes/IMU.stl"/>
      </geometry>
      <material name="IMU_material">
        <color rgba="0 1 0 1"/>
      </material>
    </visual>
    <inertial name="IMU_inertial">
      <mass value="0.001887"/>
      <inertia ixx="0.000001" iyy="0.000001" izz="0.000001" ixy="0" ixz="0" iyz="0"/>
      <origin xyz="-0.010000 -0.007500 0.001235" rpy="0 0 0"/>
    </inertial>
  </link>
  <link name="Z_BOT2_MASTER_SHOULDER2">
    <visual name="Z_BOT2_MASTER_SHOULDER2_visual">
      <origin xyz="0 0 0" rpy="0 0 0"/>
      <geometry name="Z_BOT2_MASTER_SHOULDER2_geometry">
        <mesh filename="meshes/Z_BOT2_MASTER_SHOULDER2.stl"/>
      </geometry>
      <material name="Z_BOT2_MASTER_SHOULDER2_material">
        <color rgba="0.364706 0.360784 0.749020 1"/>
      </material>
    </visual>
    <inertial name="Z_BOT2_MASTER_SHOULDER2_inertial">
      <mass value="0.008227"/>
      <inertia ixx="0.000003" iyy="0.000003" izz="0.000001" ixy="0" ixz="0" iyz="0"/>
      <origin xyz="-0.012788 -0.001374 0.018800" rpy="0 0 0"/>
    </inertial>
  </link>
  <link name="Z_BOT2_MASTER_SHOULDER2_1">
    <visual name="Z_BOT2_MASTER_SHOULDER2_1_visual">
      <origin xyz="0 0 0" rpy="0 0 0"/>
      <geometry name="Z_BOT2_MASTER_SHOULDER2_1_geometry">
        <mesh filename="meshes/Z_BOT2_MASTER_SHOULDER2_1.stl"/>
      </geometry>
      <material name="Z_BOT2_MASTER_SHOULDER2_1_material">
        <color rgba="0.364706 0.360784 0.749020 1"/>
      </material>
    </visual>
    <inertial name="Z_BOT2_MASTER_SHOULDER2_1_inertial">
      <mass value="0.008227"/>
      <inertia ixx="0.000003" iyy="0.000003" izz="0.000001" ixy="0" ixz="0" iyz="0"/>
      <origin xyz="0.012788 0.001374 -0.018800" rpy="0 0 0"/>
    </inertial>
  </link>
  <link name="Hip_Bracket">
    <visual name="Hip_Bracket_visual">
      <origin xyz="0 0 0" rpy="0 0 0"/>
      <geometry name="Hip_Bracket_geometry">
        <mesh filename="meshes/Hip_Bracket.stl"/>
      </geometry>
      <material name="Hip_Bracket_material">
        <color rgba="0.231373 0.380392 0.705882 1"/>
      </material>
    </visual>
    <inertial name="Hip_Bracket_inertial">
      <mass value="0.019861"/>
      <inertia ixx="0.000012" iyy="0.000011" izz="0.000005" ixy="0" ixz="0.000002" iyz="0"/>
      <origin xyz="0.006897 0 -0.006184" rpy="0 0 0"/>
    </inertial>
  </link>
  <link name="FK_AP_019_25T_11">
    <visual name="FK_AP_019_25T_11_visual">
      <origin xyz="0 0 0" rpy="0 0 0"/>
      <geometry name="FK_AP_019_25T_11_geometry">
        <mesh filename="meshes/FK_AP_019_25T_11.stl"/>
      </geometry>
      <material name="FK_AP_019_25T_11_material">
        <color rgba="0.749020 0.498039 0.725490 1"/>
      </material>
    </visual>
    <inertial name="FK_AP_019_25T_11_inertial">
      <mass value="0.222405"/>
      <inertia ixx="0.000326" iyy="0.000053" izz="0.000328" ixy="-0.000005" ixz="0" iyz="-0.000007"/>
      <origin xyz="-0.000729 -0.043819 -0.018153" rpy="0 0 0"/>
    </inertial>
  </link>
  <link name="FK_AP_019_25T_11_1">
    <visual name="FK_AP_019_25T_11_1_visual">
      <origin xyz="0 0 0" rpy="0 0 0"/>
      <geometry name="FK_AP_019_25T_11_1_geometry">
        <mesh filename="meshes/FK_AP_019_25T_11_1.stl"/>
      </geometry>
      <material name="FK_AP_019_25T_11_1_material">
        <color rgba="0.749020 0.498039 0.725490 1"/>
      </material>
    </visual>
    <inertial name="FK_AP_019_25T_11_1_inertial">
      <mass value="0.222405"/>
      <inertia ixx="0.000326" iyy="0.000052" izz="0.000328" ixy="0.000005" ixz="0" iyz="0.000007"/>
      <origin xyz="-0.000741 0.043819 -0.018142" rpy="0 0 0"/>
    </inertial>
  </link>
  <link name="ST15_4">
    <visual name="ST15_visual_4">
      <origin xyz="0 0 0" rpy="0 0 0"/>
      <geometry name="ST15_geometry_4">
        <mesh filename="meshes/ST15_4.stl"/>
      </geometry>
      <material name="ST15_material_4">
        <color rgba="1 0 0 1"/>
      </material>
    </visual>
    <inertial name="ST15_inertial_4">
      <mass value="0.217273"/>
      <inertia ixx="0.000131" iyy="0.000113" izz="0.000072" ixy="0" ixz="-0.000003" iyz="0.000002"/>
      <origin xyz="-0.000781 0.013065 0.000178" rpy="0 0 0"/>
    </inertial>
  </link>
  <link name="Hip_Bracket_2">
    <visual name="Hip_Bracket_visual_2">
      <origin xyz="0 0 0" rpy="0 0 0"/>
      <geometry name="Hip_Bracket_geometry_2">
        <mesh filename="meshes/Hip_Bracket_2.stl"/>
      </geometry>
      <material name="Hip_Bracket_material_2">
        <color rgba="0.231373 0.380392 0.705882 1"/>
      </material>
    </visual>
    <inertial name="Hip_Bracket_inertial_2">
      <mass value="0.019861"/>
      <inertia ixx="0.000012" iyy="0.000011" izz="0.000005" ixy="0" ixz="-0.000002" iyz="0"/>
      <origin xyz="-0.006897 0 -0.006184" rpy="0 0 0"/>
    </inertial>
  </link>
  <link name="ST15_7">
    <visual name="ST15_visual_7">
      <origin xyz="0 0 0" rpy="0 0 0"/>
      <geometry name="ST15_geometry_7">
        <mesh filename="meshes/ST15_7.stl"/>
      </geometry>
      <material name="ST15_material_7">
        <color rgba="1 0 0 1"/>
      </material>
    </visual>
    <inertial name="ST15_inertial_7">
      <mass value="0.217273"/>
      <inertia ixx="0.000131" iyy="0.000113" izz="0.000072" ixy="0" ixz="-0.000003" iyz="0.000002"/>
      <origin xyz="-0.000781 0.013065 0.000178" rpy="0 0 0"/>
    </inertial>
  </link>
  <link name="L_ARM_MIRROR_1">
    <visual name="L_ARM_MIRROR_1_visual">
      <origin xyz="0 0 0" rpy="0 0 0"/>
      <geometry name="L_ARM_MIRROR_1_geometry">
        <mesh filename="meshes/L_ARM_MIRROR_1.stl"/>
      </geometry>
      <material name="L_ARM_MIRROR_1_material">
        <color rgba="0.627451 0.627451 0.627451 1"/>
      </material>
    </visual>
    <inertial name="L_ARM_MIRROR_1_inertial">
      <mass value="0.153130"/>
      <inertia ixx="0.000126" iyy="0.000044" izz="0.000118" ixy="-0.000006" ixz="0" iyz="-0.000001"/>
      <origin xyz="-0.003295 0.055921 0.017302" rpy="0 0 0"/>
    </inertial>
  </link>
  <link name="R_ARM_MIRROR_1">
    <visual name="R_ARM_MIRROR_1_visual">
      <origin xyz="0 0 0" rpy="0 0 0"/>
      <geometry name="R_ARM_MIRROR_1_geometry">
        <mesh filename="meshes/R_ARM_MIRROR_1.stl"/>
      </geometry>
      <material name="R_ARM_MIRROR_1_material">
        <color rgba="0.647059 0.647059 0.647059 1"/>
      </material>
    </visual>
    <inertial name="R_ARM_MIRROR_1_inertial">
      <mass value="0.153130"/>
      <inertia ixx="0.000126" iyy="0.000044" izz="0.000118" ixy="0.000006" ixz="0" iyz="-0.000001"/>
      <origin xyz="0.003280 0.055927 0.017306" rpy="0 0 0"/>
    </inertial>
  </link>
  <link name="Upper_Leg">
    <visual name="Upper_Leg_visual">
      <origin xyz="0 0 0" rpy="0 0 0"/>
      <geometry name="Upper_Leg_geometry">
        <mesh filename="meshes/Upper_Leg.stl"/>
      </geometry>
      <material name="Upper_Leg_material">
        <color rgba="0.498039 0.498039 0.498039 1"/>
      </material>
    </visual>
    <collision name="Upper_Leg.collision">
      <origin xyz="0 0 0" rpy="0 0 0"/>
      <geometry name="Upper_Leg_collision_geometry">
        <mesh filename="meshes/Upper_Leg.collision.stl"/>
      </geometry>
    </collision>
    <inertial name="Upper_Leg_inertial">
      <mass value="0.030705"/>
      <inertia ixx="0.000038" iyy="0.000013" izz="0.000029" ixy="-0.000002" ixz="0" iyz="0"/>
      <origin xyz="-0.004004 -0.054562 0.018602" rpy="0 0 0"/>
    </inertial>
  </link>
  <link name="ST15_12">
    <visual name="ST15_visual_12">
      <origin xyz="0 0 0" rpy="0 0 0"/>
      <geometry name="ST15_geometry_12">
        <mesh filename="meshes/ST15_12.stl"/>
      </geometry>
      <material name="ST15_material_12">
        <color rgba="1 0 0 1"/>
      </material>
    </visual>
    <inertial name="ST15_inertial_12">
      <mass value="0.133647"/>
      <inertia ixx="0.000117" iyy="0.000036" izz="0.000102" ixy="0.000002" ixz="0" iyz="0"/>
      <origin xyz="-0.000874 0.024183 -0.017593" rpy="0 0 0"/>
    </inertial>
  </link>
  <link name="FINGER_1">
    <visual name="FINGER_1_visual">
      <origin xyz="0 0 0" rpy="0 0 0"/>
      <geometry name="FINGER_1_geometry">
        <mesh filename="meshes/FINGER_1.stl"/>
      </geometry>
      <material name="FINGER_1_material">
        <color rgba="0.627451 0.627451 0.627451 1"/>
      </material>
    </visual>
    <inertial name="FINGER_1_inertial">
      <mass value="0.022322"/>
      <inertia ixx="0.000009" iyy="0.000006" izz="0.000007" ixy="-0.000003" ixz="0" iyz="0"/>
      <origin xyz="-0.021523 -0.027779 -0.018800" rpy="0 0 0"/>
    </inertial>
  </link>
  <link name="FINGER_1_1">
    <visual name="FINGER_1_1_visual">
      <origin xyz="0 0 0" rpy="0 0 0"/>
      <geometry name="FINGER_1_1_geometry">
        <mesh filename="meshes/FINGER_1_1.stl"/>
      </geometry>
      <material name="FINGER_1_1_material">
        <color rgba="0.627451 0.627451 0.627451 1"/>
      </material>
    </visual>
    <inertial name="FINGER_1_1_inertial">
      <mass value="0.022322"/>
      <inertia ixx="0.000009" iyy="0.000006" izz="0.000007" ixy="0.000003" ixz="0" iyz="0"/>
      <origin xyz="0.021523 -0.027779 -0.018800" rpy="0 0 0"/>
    </inertial>
  </link>
  <link name="Upper_Leg_2">
    <visual name="Upper_Leg_visual_2">
      <origin xyz="0 0 0" rpy="0 0 0"/>
      <geometry name="Upper_Leg_geometry_2">
        <mesh filename="meshes/Upper_Leg_2.stl"/>
      </geometry>
      <material name="Upper_Leg_material_2">
        <color rgba="0.498039 0.498039 0.498039 1"/>
      </material>
    </visual>
    <collision name="Upper_Leg.collision_2">
      <origin xyz="0 0 0" rpy="0 0 0"/>
      <geometry name="Upper_Leg_collision_geometry_2">
        <mesh filename="meshes/Upper_Leg_2.collision.stl"/>
      </geometry>
    </collision>
    <inertial name="Upper_Leg_inertial_2">
      <mass value="0.030705"/>
      <inertia ixx="0.000038" iyy="0.000013" izz="0.000029" ixy="-0.000002" ixz="0" iyz="0"/>
      <origin xyz="-0.004004 -0.054562 -0.019057" rpy="0 0 0"/>
    </inertial>
  </link>
  <link name="ST15_13">
    <visual name="ST15_visual_13">
      <origin xyz="0 0 0" rpy="0 0 0"/>
      <geometry name="ST15_geometry_13">
        <mesh filename="meshes/ST15_13.stl"/>
      </geometry>
      <material name="ST15_material_13">
        <color rgba="1 0 0 1"/>
      </material>
    </visual>
    <inertial name="ST15_inertial_13">
      <mass value="0.133647"/>
      <inertia ixx="0.000117" iyy="0.000036" izz="0.000102" ixy="0.000002" ixz="0" iyz="0"/>
      <origin xyz="-0.000874 0.024183 -0.017593" rpy="0 0 0"/>
    </inertial>
  </link>
  <link name="ST15_14">
    <visual name="ST15_visual_14">
      <origin xyz="0 0 0" rpy="0 0 0"/>
      <geometry name="ST15_geometry_14">
        <mesh filename="meshes/ST15_14.stl"/>
      </geometry>
      <material name="ST15_material_14">
        <color rgba="1 0 0 1"/>
      </material>
    </visual>
    <inertial name="ST15_inertial_14">
      <mass value="0.217273"/>
      <inertia ixx="0.000072" iyy="0.000113" izz="0.000131" ixy="0.000002" ixz="0.000003" iyz="0"/>
      <origin xyz="0.016328 0.013065 -0.018019" rpy="0 0 0"/>
    </inertial>
  </link>
  <link name="ST15_15">
    <visual name="ST15_visual_15">
      <origin xyz="0 0 0" rpy="0 0 0"/>
      <geometry name="ST15_geometry_15">
        <mesh filename="meshes/ST15_15.stl"/>
      </geometry>
      <material name="ST15_material_15">
        <color rgba="1 0 0 1"/>
      </material>
    </visual>
    <inertial name="ST15_inertial_15">
      <mass value="0.217273"/>
      <inertia ixx="0.000072" iyy="0.000113" izz="0.000131" ixy="0.000002" ixz="0.000003" iyz="0"/>
      <origin xyz="0.016328 0.013065 -0.018019" rpy="0 0 0"/>
    </inertial>
  </link>
  <link name="Left_Foot">
    <visual name="Left_Foot_visual">
      <origin xyz="0 0 0" rpy="0 0 0"/>
      <geometry name="Left_Foot_geometry">
        <mesh filename="meshes/Left_Foot.stl"/>
      </geometry>
      <material name="Left_Foot_material">
        <color rgba="0.498039 0.498039 0.498039 1"/>
      </material>
    </visual>
    <collision name="Left_Foot.collision">
      <origin xyz="0 0 0" rpy="0 0 0"/>
      <geometry name="Left_Foot_collision_geometry">
        <mesh filename="meshes/Left_Foot.collision.stl"/>
      </geometry>
    </collision>
    <inertial name="Left_Foot_inertial">
      <mass value="0.096554"/>
      <inertia ixx="0.000090" iyy="0.000131" izz="0.000047" ixy="0" ixz="0.000002" iyz="0.000003"/>
      <origin xyz="0.006981 0.025970 -0.010887" rpy="0 0 0"/>
    </inertial>
  </link>
  <link name="Right_Foot">
    <visual name="Right_Foot_visual">
      <origin xyz="0 0 0" rpy="0 0 0"/>
      <geometry name="Right_Foot_geometry">
        <mesh filename="meshes/Right_Foot.stl"/>
      </geometry>
      <material name="Right_Foot_material">
        <color rgba="0.498039 0.498039 0.498039 1"/>
      </material>
    </visual>
    <collision name="Right_Foot.collision">
      <origin xyz="0 0 0" rpy="0 0 0"/>
      <geometry name="Right_Foot_collision_geometry">
        <mesh filename="meshes/Right_Foot.collision.stl"/>
      </geometry>
    </collision>
    <inertial name="Right_Foot_inertial">
      <mass value="0.096554"/>
      <inertia ixx="0.000090" iyy="0.000131" izz="0.000047" ixy="0" ixz="-0.000002" iyz="0.000003"/>
      <origin xyz="-0.006981 0.025970 -0.010887" rpy="0 0 0"/>
    </inertial>
  </link>
</robot>
